Workbook
Name رصيد_افتتاحي: 'الإعدادات'!$B$4
Name قائمة_شركات_الشحن: 'الإعدادات'!$D$4:$D$203
Name قائمة_التوكيلات: 'الإعدادات'!$E$4:$E$203
Name قائمة_الموانئ: 'الإعدادات'!$F$4:$F$203
Name قائمة_الشركات: 'الإعدادات'!$H$4:$H$203
Name قائمة_الجهات: 'الإعدادات'!$I$4:$I$203
Name قائمة_الملاك: 'الإعدادات'!$J$4:$J$203

Sheet تقفيل اليوم
A1: شركة المتوكل — تقفيل يومية العمل
A2: اكتب التاريخ في الخانة الصفراء ← يظهر تقفيل اليوم كامل جاهز للطباعة
B4: =TODAY() | D4: التاريخ
B5: =IFERROR(INDEX('سجل اليومية'!$C$4:$C$503,MATCH($B$4,'سجل اليومية'!$B$4:$B$503,0)),0) | D5: باقي عهدة سابق
B6: =IFERROR(INDEX('سجل اليومية'!$D$4:$D$503,MATCH($B$4,'سجل اليومية'!$B$4:$B$503,0)),0) | D6: العهدة المستلمة اليوم
B7: =IFERROR(INDEX('سجل اليومية'!$E$4:$E$503,MATCH($B$4,'سجل اليومية'!$B$4:$B$503,0)),0) | D7: إجمالي العهدة المتاحة
A9: عُهد ورحلات اليوم
A10: م | B10: عدد الحاويات | C10: شركة الشحن | D10: اسم الشركة | E10: الجهة | F10: توكيل | G10: الميناء | H10: مالك السيارة | I10: العهد
A11: =IF($K11="","",1) | B11: =IF($K11="","",INDEX('العهد والرحلات'!$A$1:$J$2003,$K11,3)) | C11: =IF($K11="","",INDEX('العهد والرحلات'!$A$1:$J$2003,$K11,4)) | D11: =IF($K11="","",INDEX('العهد والرحلات'!$A$1:$J$2003,$K11,5)) | E11: =IF($K11="","",INDEX('العهد والرحلات'!$A$1:$J$2003,$K11,6)) | F11: =IF($K11="","",INDEX('العهد والرحلات'!$A$1:$J$2003,$K11,7)) | G11: =IF($K11="","",INDEX('العهد والرحلات'!$A$1:$J$2003,$K11,8)) | H11: =IF($K11="","",INDEX('العهد والرحلات'!$A$1:$J$2003,$K11,9)) | I11: =IF($K11="","",INDEX('العهد والرحلات'!$A$1:$J$2003,$K11,10)) | K11: {=IFERROR(SMALL(IF('العهد والرحلات'!$B$4:$B$2003=$B$4,ROW('العهد والرحلات'!$B$4:$B$2003)),1),"")}
A12: =IF($K12="","",2) | B12: =IF($K12="","",INDEX('العهد والرحلات'!$A$1:$J$2003,$K12,3)) | C12: =IF($K12="","",INDEX('العهد والرحلات'!$A$1:$J$2003,$K12,4)) | D12: =IF($K12="","",INDEX('العهد والرحلات'!$A$1:$J$2003,$K12,5)) | E12: =IF($K12="","",INDEX('العهد والرحلات'!$A$1:$J$2003,$K12,6)) | F12: =IF($K12="","",INDEX('العهد والرحلات'!$A$1:$J$2003,$K12,7)) | G12: =IF($K12="","",INDEX('العهد والرحلات'!$A$1:$J$2003,$K12,8)) | H12: =IF($K12="","",INDEX('العهد والرحلات'!$A$1:$J$2003,$K12,9)) | I12: =IF($K12="","",INDEX('العهد والرحلات'!$A$1:$J$2003,$K12,10)) | K12: {=IFERROR(SMALL(IF('العهد والرحلات'!$B$4:$B$2003=$B$4,ROW('العهد والرحلات'!$B$4:$B$2003)),2),"")}
A13: =IF($K13="","",3) | B13: =IF($K13="","",INDEX('العهد والرحلات'!$A$1:$J$2003,$K13,3)) | C13: =IF($K13="","",INDEX('العهد والرحلات'!$A$1:$J$2003,$K13,4)) | D13: =IF($K13="","",INDEX('العهد والرحلات'!$A$1:$J$2003,$K13,5)) | E13: =IF($K13="","",INDEX('العهد والرحلات'!$A$1:$J$2003,$K13,6)) | F13: =IF($K13="","",INDEX('العهد والرحلات'!$A$1:$J$2003,$K13,7)) | G13: =IF($K13="","",INDEX('العهد والرحلات'!$A$1:$J$2003,$K13,8)) | H13: =IF($K13="","",INDEX('العهد والرحلات'!$A$1:$J$2003,$K13,9)) | I13: =IF($K13="","",INDEX('العهد والرحلات'!$A$1:$J$2003,$K13,10)) | K13: {=IFERROR(SMALL(IF('العهد والرحلات'!$B$4:$B$2003=$B$4,ROW('العهد والرحلات'!$B$4:$B$2003)),3),"")}
A14: =IF($K14="","",4) | B14: =IF($K14="","",INDEX('العهد والرحلات'!$A$1:$J$2003,$K14,3)) | C14: =IF($K14="","",INDEX('العهد والرحلات'!$A$1:$J$2003,$K14,4)) | D14: =IF($K14="","",INDEX('العهد والرحلات'!$A$1:$J$2003,$K14,5)) | E14: =IF($K14="","",INDEX('العهد والرحلات'!$A$1:$J$2003,$K14,6)) | F14: =IF($K14="","",INDEX('العهد والرحلات'!$A$1:$J$2003,$K14,7)) | G14: =IF($K14="","",INDEX('العهد والرحلات'!$A$1:$J$2003,$K14,8)) | H14: =IF($K14="","",INDEX('العهد والرحلات'!$A$1:$J$2003,$K14,9)) | I14: =IF($K14="","",INDEX('العهد والرحلات'!$A$1:$J$2003,$K14,10)) | K14: {=IFERROR(SMALL(IF('العهد والرحلات'!$B$4:$B$2003=$B$4,ROW('العهد والرحلات'!$B$4:$B$2003)),4),"")}
A15: =IF($K15="","",5) | B15: =IF($K15="","",INDEX('العهد والرحلات'!$A$1:$J$2003,$K15,3)) | C15: =IF($K15="","",INDEX('العهد والرحلات'!$A$1:$J$2003,$K15,4)) | D15: =IF($K15="","",INDEX('العهد والرحلات'!$A$1:$J$2003,$K15,5)) | E15: =IF($K15="","",INDEX('العهد والرحلات'!$A$1:$J$2003,$K15,6)) | F15: =IF($K15="","",INDEX('العهد والرحلات'!$A$1:$J$2003,$K15,7)) | G15: =IF($K15="","",INDEX('العهد والرحلات'!$A$1:$J$2003,$K15,8)) | H15: =IF($K15="","",INDEX('العهد والرحلات'!$A$1:$J$2003,$K15,9)) | I15: =IF($K15="","",INDEX('العهد والرحلات'!$A$1:$J$2003,$K15,10)) | K15: {=IFERROR(SMALL(IF('العهد والرحلات'!$B$4:$B$2003=$B$4,ROW('العهد والرحلات'!$B$4:$B$2003)),5),"")}
A16: =IF($K16="","",6) | B16: =IF($K16="","",INDEX('العهد والرحلات'!$A$1:$J$2003,$K16,3)) | C16: =IF($K16="","",INDEX('العهد والرحلات'!$A$1:$J$2003,$K16,4)) | D16: =IF($K16="","",INDEX('العهد والرحلات'!$A$1:$J$2003,$K16,5)) | E16: =IF($K16="","",INDEX('العهد والرحلات'!$A$1:$J$2003,$K16,6)) | F16: =IF($K16="","",INDEX('العهد والرحلات'!$A$1:$J$2003,$K16,7)) | G16: =IF($K16="","",INDEX('العهد والرحلات'!$A$1:$J$2003,$K16,8)) | H16: =IF($K16="","",INDEX('العهد والرحلات'!$A$1:$J$2003,$K16,9)) | I16: =IF($K16="","",INDEX('العهد والرحلات'!$A$1:$J$2003,$K16,10)) | K16: {=IFERROR(SMALL(IF('العهد والرحلات'!$B$4:$B$2003=$B$4,ROW('العهد والرحلات'!$B$4:$B$2003)),6),"")}
A17: =IF($K17="","",7) | B17: =IF($K17="","",INDEX('العهد والرحلات'!$A$1:$J$2003,$K17,3)) | C17: =IF($K17="","",INDEX('العهد والرحلات'!$A$1:$J$2003,$K17,4)) | D17: =IF($K17="","",INDEX('العهد والرحلات'!$A$1:$J$2003,$K17,5)) | E17: =IF($K17="","",INDEX('العهد والرحلات'!$A$1:$J$2003,$K17,6)) | F17: =IF($K17="","",INDEX('العهد والرحلات'!$A$1:$J$2003,$K17,7)) | G17: =IF($K17="","",INDEX('العهد والرحلات'!$A$1:$J$2003,$K17,8)) | H17: =IF($K17="","",INDEX('العهد والرحلات'!$A$1:$J$2003,$K17,9)) | I17: =IF($K17="","",INDEX('العهد والرحلات'!$A$1:$J$2003,$K17,10)) | K17: {=IFERROR(SMALL(IF('العهد والرحلات'!$B$4:$B$2003=$B$4,ROW('العهد والرحلات'!$B$4:$B$2003)),7),"")}
A18: =IF($K18="","",8) | B18: =IF($K18="","",INDEX('العهد والرحلات'!$A$1:$J$2003,$K18,3)) | C18: =IF($K18="","",INDEX('العهد والرحلات'!$A$1:$J$2003,$K18,4)) | D18: =IF($K18="","",INDEX('العهد والرحلات'!$A$1:$J$2003,$K18,5)) | E18: =IF($K18="","",INDEX('العهد والرحلات'!$A$1:$J$2003,$K18,6)) | F18: =IF($K18="","",INDEX('العهد والرحلات'!$A$1:$J$2003,$K18,7)) | G18: =IF($K18="","",INDEX('العهد والرحلات'!$A$1:$J$2003,$K18,8)) | H18: =IF($K18="","",INDEX('العهد والرحلات'!$A$1:$J$2003,$K18,9)) | I18: =IF($K18="","",INDEX('العهد والرحلات'!$A$1:$J$2003,$K18,10)) | K18: {=IFERROR(SMALL(IF('العهد والرحلات'!$B$4:$B$2003=$B$4,ROW('العهد والرحلات'!$B$4:$B$2003)),8),"")}
A19: =IF($K19="","",9) | B19: =IF($K19="","",INDEX('العهد والرحلات'!$A$1:$J$2003,$K19,3)) | C19: =IF($K19="","",INDEX('العهد والرحلات'!$A$1:$J$2003,$K19,4)) | D19: =IF($K19="","",INDEX('العهد والرحلات'!$A$1:$J$2003,$K19,5)) | E19: =IF($K19="","",INDEX('العهد والرحلات'!$A$1:$J$2003,$K19,6)) | F19: =IF($K19="","",INDEX('العهد والرحلات'!$A$1:$J$2003,$K19,7)) | G19: =IF($K19="","",INDEX('العهد والرحلات'!$A$1:$J$2003,$K19,8)) | H19: =IF($K19="","",INDEX('العهد والرحلات'!$A$1:$J$2003,$K19,9)) | I19: =IF($K19="","",INDEX('العهد والرحلات'!$A$1:$J$2003,$K19,10)) | K19: {=IFERROR(SMALL(IF('العهد والرحلات'!$B$4:$B$2003=$B$4,ROW('العهد والرحلات'!$B$4:$B$2003)),9),"")}
A20: =IF($K20="","",10) | B20: =IF($K20="","",INDEX('العهد والرحلات'!$A$1:$J$2003,$K20,3)) | C20: =IF($K20="","",INDEX('العهد والرحلات'!$A$1:$J$2003,$K20,4)) | D20: =IF($K20="","",INDEX('العهد والرحلات'!$A$1:$J$2003,$K20,5)) | E20: =IF($K20="","",INDEX('العهد والرحلات'!$A$1:$J$2003,$K20,6)) | F20: =IF($K20="","",INDEX('العهد والرحلات'!$A$1:$J$2003,$K20,7)) | G20: =IF($K20="","",INDEX('العهد والرحلات'!$A$1:$J$2003,$K20,8)) | H20: =IF($K20="","",INDEX('العهد والرحلات'!$A$1:$J$2003,$K20,9)) | I20: =IF($K20="","",INDEX('العهد والرحلات'!$A$1:$J$2003,$K20,10)) | K20: {=IFERROR(SMALL(IF('العهد والرحلات'!$B$4:$B$2003=$B$4,ROW('العهد والرحلات'!$B$4:$B$2003)),10),"")}
A21: =IF($K21="","",11) | B21: =IF($K21="","",INDEX('العهد والرحلات'!$A$1:$J$2003,$K21,3)) | C21: =IF($K21="","",INDEX('العهد والرحلات'!$A$1:$J$2003,$K21,4)) | D21: =IF($K21="","",INDEX('العهد والرحلات'!$A$1:$J$2003,$K21,5)) | E21: =IF($K21="","",INDEX('العهد والرحلات'!$A$1:$J$2003,$K21,6)) | F21: =IF($K21="","",INDEX('العهد والرحلات'!$A$1:$J$2003,$K21,7)) | G21: =IF($K21="","",INDEX('العهد والرحلات'!$A$1:$J$2003,$K21,8)) | H21: =IF($K21="","",INDEX('العهد والرحلات'!$A$1:$J$2003,$K21,9)) | I21: =IF($K21="","",INDEX('العهد والرحلات'!$A$1:$J$2003,$K21,10)) | K21: {=IFERROR(SMALL(IF('العهد والرحلات'!$B$4:$B$2003=$B$4,ROW('العهد والرحلات'!$B$4:$B$2003)),11),"")}
A22: =IF($K22="","",12) | B22: =IF($K22="","",INDEX('العهد والرحلات'!$A$1:$J$2003,$K22,3)) | C22: =IF($K22="","",INDEX('العهد والرحلات'!$A$1:$J$2003,$K22,4)) | D22: =IF($K22="","",INDEX('العهد والرحلات'!$A$1:$J$2003,$K22,5)) | E22: =IF($K22="","",INDEX('العهد والرحلات'!$A$1:$J$2003,$K22,6)) | F22: =IF($K22="","",INDEX('العهد والرحلات'!$A$1:$J$2003,$K22,7)) | G22: =IF($K22="","",INDEX('العهد والرحلات'!$A$1:$J$2003,$K22,8)) | H22: =IF($K22="","",INDEX('العهد والرحلات'!$A$1:$J$2003,$K22,9)) | I22: =IF($K22="","",INDEX('العهد والرحلات'!$A$1:$J$2003,$K22,10)) | K22: {=IFERROR(SMALL(IF('العهد والرحلات'!$B$4:$B$2003=$B$4,ROW('العهد والرحلات'!$B$4:$B$2003)),12),"")}
A23: =IF($K23="","",13) | B23: =IF($K23="","",INDEX('العهد والرحلات'!$A$1:$J$2003,$K23,3)) | C23: =IF($K23="","",INDEX('العهد والرحلات'!$A$1:$J$2003,$K23,4)) | D23: =IF($K23="","",INDEX('العهد والرحلات'!$A$1:$J$2003,$K23,5)) | E23: =IF($K23="","",INDEX('العهد والرحلات'!$A$1:$J$2003,$K23,6)) | F23: =IF($K23="","",INDEX('العهد والرحلات'!$A$1:$J$2003,$K23,7)) | G23: =IF($K23="","",INDEX('العهد والرحلات'!$A$1:$J$2003,$K23,8)) | H23: =IF($K23="","",INDEX('العهد والرحلات'!$A$1:$J$2003,$K23,9)) | I23: =IF($K23="","",INDEX('العهد والرحلات'!$A$1:$J$2003,$K23,10)) | K23: {=IFERROR(SMALL(IF('العهد والرحلات'!$B$4:$B$2003=$B$4,ROW('العهد والرحلات'!$B$4:$B$2003)),13),"")}
A24: =IF($K24="","",14) | B24: =IF($K24="","",INDEX('العهد والرحلات'!$A$1:$J$2003,$K24,3)) | C24: =IF($K24="","",INDEX('العهد والرحلات'!$A$1:$J$2003,$K24,4)) | D24: =IF($K24="","",INDEX('العهد والرحلات'!$A$1:$J$2003,$K24,5)) | E24: =IF($K24="","",INDEX('العهد والرحلات'!$A$1:$J$2003,$K24,6)) | F24: =IF($K24="","",INDEX('العهد والرحلات'!$A$1:$J$2003,$K24,7)) | G24: =IF($K24="","",INDEX('العهد والرحلات'!$A$1:$J$2003,$K24,8)) | H24: =IF($K24="","",INDEX('العهد والرحلات'!$A$1:$J$2003,$K24,9)) | I24: =IF($K24="","",INDEX('العهد والرحلات'!$A$1:$J$2003,$K24,10)) | K24: {=IFERROR(SMALL(IF('العهد والرحلات'!$B$4:$B$2003=$B$4,ROW('العهد والرحلات'!$B$4:$B$2003)),14),"")}
A25: =IF($K25="","",15) | B25: =IF($K25="","",INDEX('العهد والرحلات'!$A$1:$J$2003,$K25,3)) | C25: =IF($K25="","",INDEX('العهد والرحلات'!$A$1:$J$2003,$K25,4)) | D25: =IF($K25="","",INDEX('العهد والرحلات'!$A$1:$J$2003,$K25,5)) | E25: =IF($K25="","",INDEX('العهد والرحلات'!$A$1:$J$2003,$K25,6)) | F25: =IF($K25="","",INDEX('العهد والرحلات'!$A$1:$J$2003,$K25,7)) | G25: =IF($K25="","",INDEX('العهد والرحلات'!$A$1:$J$2003,$K25,8)) | H25: =IF($K25="","",INDEX('العهد والرحلات'!$A$1:$J$2003,$K25,9)) | I25: =IF($K25="","",INDEX('العهد والرحلات'!$A$1:$J$2003,$K25,10)) | K25: {=IFERROR(SMALL(IF('العهد والرحلات'!$B$4:$B$2003=$B$4,ROW('العهد والرحلات'!$B$4:$B$2003)),15),"")}
A26: =IF($K26="","",16) | B26: =IF($K26="","",INDEX('العهد والرحلات'!$A$1:$J$2003,$K26,3)) | C26: =IF($K26="","",INDEX('العهد والرحلات'!$A$1:$J$2003,$K26,4)) | D26: =IF($K26="","",INDEX('العهد والرحلات'!$A$1:$J$2003,$K26,5)) | E26: =IF($K26="","",INDEX('العهد والرحلات'!$A$1:$J$2003,$K26,6)) | F26: =IF($K26="","",INDEX('العهد والرحلات'!$A$1:$J$2003,$K26,7)) | G26: =IF($K26="","",INDEX('العهد والرحلات'!$A$1:$J$2003,$K26,8)) | H26: =IF($K26="","",INDEX('العهد والرحلات'!$A$1:$J$2003,$K26,9)) | I26: =IF($K26="","",INDEX('العهد والرحلات'!$A$1:$J$2003,$K26,10)) | K26: {=IFERROR(SMALL(IF('العهد والرحلات'!$B$4:$B$2003=$B$4,ROW('العهد والرحلات'!$B$4:$B$2003)),16),"")}
A27: =IF($K27="","",17) | B27: =IF($K27="","",INDEX('العهد والرحلات'!$A$1:$J$2003,$K27,3)) | C27: =IF($K27="","",INDEX('العهد والرحلات'!$A$1:$J$2003,$K27,4)) | D27: =IF($K27="","",INDEX('العهد والرحلات'!$A$1:$J$2003,$K27,5)) | E27: =IF($K27="","",INDEX('العهد والرحلات'!$A$1:$J$2003,$K27,6)) | F27: =IF($K27="","",INDEX('العهد والرحلات'!$A$1:$J$2003,$K27,7)) | G27: =IF($K27="","",INDEX('العهد والرحلات'!$A$1:$J$2003,$K27,8)) | H27: =IF($K27="","",INDEX('العهد والرحلات'!$A$1:$J$2003,$K27,9)) | I27: =IF($K27="","",INDEX('العهد والرحلات'!$A$1:$J$2003,$K27,10)) | K27: {=IFERROR(SMALL(IF('العهد والرحلات'!$B$4:$B$2003=$B$4,ROW('العهد والرحلات'!$B$4:$B$2003)),17),"")}
A28: =IF($K28="","",18) | B28: =IF($K28="","",INDEX('العهد والرحلات'!$A$1:$J$2003,$K28,3)) | C28: =IF($K28="","",INDEX('العهد والرحلات'!$A$1:$J$2003,$K28,4)) | D28: =IF($K28="","",INDEX('العهد والرحلات'!$A$1:$J$2003,$K28,5)) | E28: =IF($K28="","",INDEX('العهد والرحلات'!$A$1:$J$2003,$K28,6)) | F28: =IF($K28="","",INDEX('العهد والرحلات'!$A$1:$J$2003,$K28,7)) | G28: =IF($K28="","",INDEX('العهد والرحلات'!$A$1:$J$2003,$K28,8)) | H28: =IF($K28="","",INDEX('العهد والرحلات'!$A$1:$J$2003,$K28,9)) | I28: =IF($K28="","",INDEX('العهد والرحلات'!$A$1:$J$2003,$K28,10)) | K28: {=IFERROR(SMALL(IF('العهد والرحلات'!$B$4:$B$2003=$B$4,ROW('العهد والرحلات'!$B$4:$B$2003)),18),"")}
A29: =IF($K29="","",19) | B29: =IF($K29="","",INDEX('العهد والرحلات'!$A$1:$J$2003,$K29,3)) | C29: =IF($K29="","",INDEX('العهد والرحلات'!$A$1:$J$2003,$K29,4)) | D29: =IF($K29="","",INDEX('العهد والرحلات'!$A$1:$J$2003,$K29,5)) | E29: =IF($K29="","",INDEX('العهد والرحلات'!$A$1:$J$2003,$K29,6)) | F29: =IF($K29="","",INDEX('العهد والرحلات'!$A$1:$J$2003,$K29,7)) | G29: =IF($K29="","",INDEX('العهد والرحلات'!$A$1:$J$2003,$K29,8)) | H29: =IF($K29="","",INDEX('العهد والرحلات'!$A$1:$J$2003,$K29,9)) | I29: =IF($K29="","",INDEX('العهد والرحلات'!$A$1:$J$2003,$K29,10)) | K29: {=IFERROR(SMALL(IF('العهد والرحلات'!$B$4:$B$2003=$B$4,ROW('العهد والرحلات'!$B$4:$B$2003)),19),"")}
A30: =IF($K30="","",20) | B30: =IF($K30="","",INDEX('العهد والرحلات'!$A$1:$J$2003,$K30,3)) | C30: =IF($K30="","",INDEX('العهد والرحلات'!$A$1:$J$2003,$K30,4)) | D30: =IF($K30="","",INDEX('العهد والرحلات'!$A$1:$J$2003,$K30,5)) | E30: =IF($K30="","",INDEX('العهد والرحلات'!$A$1:$J$2003,$K30,6)) | F30: =IF($K30="","",INDEX('العهد والرحلات'!$A$1:$J$2003,$K30,7)) | G30: =IF($K30="","",INDEX('العهد والرحلات'!$A$1:$J$2003,$K30,8)) | H30: =IF($K30="","",INDEX('العهد والرحلات'!$A$1:$J$2003,$K30,9)) | I30: =IF($K30="","",INDEX('العهد والرحلات'!$A$1:$J$2003,$K30,10)) | K30: {=IFERROR(SMALL(IF('العهد والرحلات'!$B$4:$B$2003=$B$4,ROW('العهد والرحلات'!$B$4:$B$2003)),20),"")}
A31: =IF($K31="","",21) | B31: =IF($K31="","",INDEX('العهد والرحلات'!$A$1:$J$2003,$K31,3)) | C31: =IF($K31="","",INDEX('العهد والرحلات'!$A$1:$J$2003,$K31,4)) | D31: =IF($K31="","",INDEX('العهد والرحلات'!$A$1:$J$2003,$K31,5)) | E31: =IF($K31="","",INDEX('العهد والرحلات'!$A$1:$J$2003,$K31,6)) | F31: =IF($K31="","",INDEX('العهد والرحلات'!$A$1:$J$2003,$K31,7)) | G31: =IF($K31="","",INDEX('العهد والرحلات'!$A$1:$J$2003,$K31,8)) | H31: =IF($K31="","",INDEX('العهد والرحلات'!$A$1:$J$2003,$K31,9)) | I31: =IF($K31="","",INDEX('العهد والرحلات'!$A$1:$J$2003,$K31,10)) | K31: {=IFERROR(SMALL(IF('العهد والرحلات'!$B$4:$B$2003=$B$4,ROW('العهد والرحلات'!$B$4:$B$2003)),21),"")}
A32: =IF($K32="","",22) | B32: =IF($K32="","",INDEX('العهد والرحلات'!$A$1:$J$2003,$K32,3)) | C32: =IF($K32="","",INDEX('العهد والرحلات'!$A$1:$J$2003,$K32,4)) | D32: =IF($K32="","",INDEX('العهد والرحلات'!$A$1:$J$2003,$K32,5)) | E32: =IF($K32="","",INDEX('العهد والرحلات'!$A$1:$J$2003,$K32,6)) | F32: =IF($K32="","",INDEX('العهد والرحلات'!$A$1:$J$2003,$K32,7)) | G32: =IF($K32="","",INDEX('العهد والرحلات'!$A$1:$J$2003,$K32,8)) | H32: =IF($K32="","",INDEX('العهد والرحلات'!$A$1:$J$2003,$K32,9)) | I32: =IF($K32="","",INDEX('العهد والرحلات'!$A$1:$J$2003,$K32,10)) | K32: {=IFERROR(SMALL(IF('العهد والرحلات'!$B$4:$B$2003=$B$4,ROW('العهد والرحلات'!$B$4:$B$2003)),22),"")}
A33: =IF($K33="","",23) | B33: =IF($K33="","",INDEX('العهد والرحلات'!$A$1:$J$2003,$K33,3)) | C33: =IF($K33="","",INDEX('العهد والرحلات'!$A$1:$J$2003,$K33,4)) | D33: =IF($K33="","",INDEX('العهد والرحلات'!$A$1:$J$2003,$K33,5)) | E33: =IF($K33="","",INDEX('العهد والرحلات'!$A$1:$J$2003,$K33,6)) | F33: =IF($K33="","",INDEX('العهد والرحلات'!$A$1:$J$2003,$K33,7)) | G33: =IF($K33="","",INDEX('العهد والرحلات'!$A$1:$J$2003,$K33,8)) | H33: =IF($K33="","",INDEX('العهد والرحلات'!$A$1:$J$2003,$K33,9)) | I33: =IF($K33="","",INDEX('العهد والرحلات'!$A$1:$J$2003,$K33,10)) | K33: {=IFERROR(SMALL(IF('العهد والرحلات'!$B$4:$B$2003=$B$4,ROW('العهد والرحلات'!$B$4:$B$2003)),23),"")}
A34: =IF($K34="","",24) | B34: =IF($K34="","",INDEX('العهد والرحلات'!$A$1:$J$2003,$K34,3)) | C34: =IF($K34="","",INDEX('العهد والرحلات'!$A$1:$J$2003,$K34,4)) | D34: =IF($K34="","",INDEX('العهد والرحلات'!$A$1:$J$2003,$K34,5)) | E34: =IF($K34="","",INDEX('العهد والرحلات'!$A$1:$J$2003,$K34,6)) | F34: =IF($K34="","",INDEX('العهد والرحلات'!$A$1:$J$2003,$K34,7)) | G34: =IF($K34="","",INDEX('العهد والرحلات'!$A$1:$J$2003,$K34,8)) | H34: =IF($K34="","",INDEX('العهد والرحلات'!$A$1:$J$2003,$K34,9)) | I34: =IF($K34="","",INDEX('العهد والرحلات'!$A$1:$J$2003,$K34,10)) | K34: {=IFERROR(SMALL(IF('العهد والرحلات'!$B$4:$B$2003=$B$4,ROW('العهد والرحلات'!$B$4:$B$2003)),24),"")}
A35: =IF($K35="","",25) | B35: =IF($K35="","",INDEX('العهد والرحلات'!$A$1:$J$2003,$K35,3)) | C35: =IF($K35="","",INDEX('العهد والرحلات'!$A$1:$J$2003,$K35,4)) | D35: =IF($K35="","",INDEX('العهد والرحلات'!$A$1:$J$2003,$K35,5)) | E35: =IF($K35="","",INDEX('العهد والرحلات'!$A$1:$J$2003,$K35,6)) | F35: =IF($K35="","",INDEX('العهد والرحلات'!$A$1:$J$2003,$K35,7)) | G35: =IF($K35="","",INDEX('العهد والرحلات'!$A$1:$J$2003,$K35,8)) | H35: =IF($K35="","",INDEX('العهد والرحلات'!$A$1:$J$2003,$K35,9)) | I35: =IF($K35="","",INDEX('العهد والرحلات'!$A$1:$J$2003,$K35,10)) | K35: {=IFERROR(SMALL(IF('العهد والرحلات'!$B$4:$B$2003=$B$4,ROW('العهد والرحلات'!$B$4:$B$2003)),25),"")}
A36: =IF($K36="","",26) | B36: =IF($K36="","",INDEX('العهد والرحلات'!$A$1:$J$2003,$K36,3)) | C36: =IF($K36="","",INDEX('العهد والرحلات'!$A$1:$J$2003,$K36,4)) | D36: =IF($K36="","",INDEX('العهد والرحلات'!$A$1:$J$2003,$K36,5)) | E36: =IF($K36="","",INDEX('العهد والرحلات'!$A$1:$J$2003,$K36,6)) | F36: =IF($K36="","",INDEX('العهد والرحلات'!$A$1:$J$2003,$K36,7)) | G36: =IF($K36="","",INDEX('العهد والرحلات'!$A$1:$J$2003,$K36,8)) | H36: =IF($K36="","",INDEX('العهد والرحلات'!$A$1:$J$2003,$K36,9)) | I36: =IF($K36="","",INDEX('العهد والرحلات'!$A$1:$J$2003,$K36,10)) | K36: {=IFERROR(SMALL(IF('العهد والرحلات'!$B$4:$B$2003=$B$4,ROW('العهد والرحلات'!$B$4:$B$2003)),26),"")}
A37: =IF($K37="","",27) | B37: =IF($K37="","",INDEX('العهد والرحلات'!$A$1:$J$2003,$K37,3)) | C37: =IF($K37="","",INDEX('العهد والرحلات'!$A$1:$J$2003,$K37,4)) | D37: =IF($K37="","",INDEX('العهد والرحلات'!$A$1:$J$2003,$K37,5)) | E37: =IF($K37="","",INDEX('العهد والرحلات'!$A$1:$J$2003,$K37,6)) | F37: =IF($K37="","",INDEX('العهد والرحلات'!$A$1:$J$2003,$K37,7)) | G37: =IF($K37="","",INDEX('العهد والرحلات'!$A$1:$J$2003,$K37,8)) | H37: =IF($K37="","",INDEX('العهد والرحلات'!$A$1:$J$2003,$K37,9)) | I37: =IF($K37="","",INDEX('العهد والرحلات'!$A$1:$J$2003,$K37,10)) | K37: {=IFERROR(SMALL(IF('العهد والرحلات'!$B$4:$B$2003=$B$4,ROW('العهد والرحلات'!$B$4:$B$2003)),27),"")}
A38: =IF($K38="","",28) | B38: =IF($K38="","",INDEX('العهد والرحلات'!$A$1:$J$2003,$K38,3)) | C38: =IF($K38="","",INDEX('العهد والرحلات'!$A$1:$J$2003,$K38,4)) | D38: =IF($K38="","",INDEX('العهد والرحلات'!$A$1:$J$2003,$K38,5)) | E38: =IF($K38="","",INDEX('العهد والرحلات'!$A$1:$J$2003,$K38,6)) | F38: =IF($K38="","",INDEX('العهد والرحلات'!$A$1:$J$2003,$K38,7)) | G38: =IF($K38="","",INDEX('العهد والرحلات'!$A$1:$J$2003,$K38,8)) | H38: =IF($K38="","",INDEX('العهد والرحلات'!$A$1:$J$2003,$K38,9)) | I38: =IF($K38="","",INDEX('العهد والرحلات'!$A$1:$J$2003,$K38,10)) | K38: {=IFERROR(SMALL(IF('العهد والرحلات'!$B$4:$B$2003=$B$4,ROW('العهد والرحلات'!$B$4:$B$2003)),28),"")}
A39: =IF($K39="","",29) | B39: =IF($K39="","",INDEX('العهد والرحلات'!$A$1:$J$2003,$K39,3)) | C39: =IF($K39="","",INDEX('العهد والرحلات'!$A$1:$J$2003,$K39,4)) | D39: =IF($K39="","",INDEX('العهد والرحلات'!$A$1:$J$2003,$K39,5)) | E39: =IF($K39="","",INDEX('العهد والرحلات'!$A$1:$J$2003,$K39,6)) | F39: =IF($K39="","",INDEX('العهد والرحلات'!$A$1:$J$2003,$K39,7)) | G39: =IF($K39="","",INDEX('العهد والرحلات'!$A$1:$J$2003,$K39,8)) | H39: =IF($K39="","",INDEX('العهد والرحلات'!$A$1:$J$2003,$K39,9)) | I39: =IF($K39="","",INDEX('العهد والرحلات'!$A$1:$J$2003,$K39,10)) | K39: {=IFERROR(SMALL(IF('العهد والرحلات'!$B$4:$B$2003=$B$4,ROW('العهد والرحلات'!$B$4:$B$2003)),29),"")}
A40: =IF($K40="","",30) | B40: =IF($K40="","",INDEX('العهد والرحلات'!$A$1:$J$2003,$K40,3)) | C40: =IF($K40="","",INDEX('العهد والرحلات'!$A$1:$J$2003,$K40,4)) | D40: =IF($K40="","",INDEX('العهد والرحلات'!$A$1:$J$2003,$K40,5)) | E40: =IF($K40="","",INDEX('العهد والرحلات'!$A$1:$J$2003,$K40,6)) | F40: =IF($K40="","",INDEX('العهد والرحلات'!$A$1:$J$2003,$K40,7)) | G40: =IF($K40="","",INDEX('العهد والرحلات'!$A$1:$J$2003,$K40,8)) | H40: =IF($K40="","",INDEX('العهد والرحلات'!$A$1:$J$2003,$K40,9)) | I40: =IF($K40="","",INDEX('العهد والرحلات'!$A$1:$J$2003,$K40,10)) | K40: {=IFERROR(SMALL(IF('العهد والرحلات'!$B$4:$B$2003=$B$4,ROW('العهد والرحلات'!$B$4:$B$2003)),30),"")}
B41: إجمالي عُهد اليوم | I41: =SUM($I11:$I40)
A43: إيصالات اليوم
...

Sheet سجل اليومية
A1: شركة المتوكل — سجل اليومية
A2: تقفيل كل يوم في صف — الرصيد يترحّل تلقائياً لليوم التالي
A3: م | B3: التاريخ | C3: باقي عهدة سابق | D3: العهدة المستلمة | E3: إجمالي العهدة المتاحة | F3: إجمالي العهد (الرحلات) | G3: إجمالي الإيصالات | H3: مصروفات أخرى | I3: إجمالي المصروف | J3: رصيد عهد مُرحَّل لليوم التالي
A4: =IF($B4="","",COUNTA($B$4:$B4)) | C4: =IF($B4="","",رصيد_افتتاحي) | E4: =IF($B4="","",N($C4)+N($D4)) | F4: =IF($B4="","",SUMIFS('العهد والرحلات'!$J$4:$J$2003,'العهد والرحلات'!$B$4:$B$2003,$B4)) | G4: =IF($B4="","",SUMIFS('الإيصالات'!$C$4:$C$2003,'الإيصالات'!$B$4:$B$2003,$B4)) | I4: =IF($B4="","",N($F4)+N($G4)+N($H4)) | J4: =IF($B4="","",N($E4)-N($I4))
A5: =IF($B5="","",COUNTA($B$4:$B5)) | C5: =IF($B5="","",N($J4)) | E5: =IF($B5="","",N($C5)+N($D5)) | F5: =IF($B5="","",SUMIFS('العهد والرحلات'!$J$4:$J$2003,'العهد والرحلات'!$B$4:$B$2003,$B5)) | G5: =IF($B5="","",SUMIFS('الإيصالات'!$C$4:$C$2003,'الإيصالات'!$B$4:$B$2003,$B5)) | I5: =IF($B5="","",N($F5)+N($G5)+N($H5)) | J5: =IF($B5="","",N($E5)-N($I5))
A6: =IF($B6="","",COUNTA($B$4:$B6)) | C6: =IF($B6="","",N($J5)) | E6: =IF($B6="","",N($C6)+N($D6)) | F6: =IF($B6="","",SUMIFS('العهد والرحلات'!$J$4:$J$2003,'العهد والرحلات'!$B$4:$B$2003,$B6)) | G6: =IF($B6="","",SUMIFS('الإيصالات'!$C$4:$C$2003,'الإيصالات'!$B$4:$B$2003,$B6)) | I6: =IF($B6="","",N($F6)+N($G6)+N($H6)) | J6: =IF($B6="","",N($E6)-N($I6))
A7: =IF($B7="","",COUNTA($B$4:$B7)) | C7: =IF($B7="","",N($J6)) | E7: =IF($B7="","",N($C7)+N($D7)) | F7: =IF($B7="","",SUMIFS('العهد والرحلات'!$J$4:$J$2003,'العهد والرحلات'!$B$4:$B$2003,$B7)) | G7: =IF($B7="","",SUMIFS('الإيصالات'!$C$4:$C$2003,'الإيصالات'!$B$4:$B$2003,$B7)) | I7: =IF($B7="","",N($F7)+N($G7)+N($H7)) | J7: =IF($B7="","",N($E7)-N($I7))
A8: =IF($B8="","",COUNTA($B$4:$B8)) | C8: =IF($B8="","",N($J7)) | E8: =IF($B8="","",N($C8)+N($D8)) | F8: =IF($B8="","",SUMIFS('العهد والرحلات'!$J$4:$J$2003,'العهد والرحلات'!$B$4:$B$2003,$B8)) | G8: =IF($B8="","",SUMIFS('الإيصالات'!$C$4:$C$2003,'الإيصالات'!$B$4:$B$2003,$B8)) | I8: =IF($B8="","",N($F8)+N($G8)+N($H8)) | J8: =IF($B8="","",N($E8)-N($I8))
A9: =IF($B9="","",COUNTA($B$4:$B9)) | C9: =IF($B9="","",N($J8)) | E9: =IF($B9="","",N($C9)+N($D9)) | F9: =IF($B9="","",SUMIFS('العهد والرحلات'!$J$4:$J$2003,'العهد والرحلات'!$B$4:$B$2003,$B9)) | G9: =IF($B9="","",SUMIFS('الإيصالات'!$C$4:$C$2003,'الإيصالات'!$B$4:$B$2003,$B9)) | I9: =IF($B9="","",N($F9)+N($G9)+N($H9)) | J9: =IF($B9="","",N($E9)-N($I9))
A10: =IF($B10="","",COUNTA($B$4:$B10)) | C10: =IF($B10="","",N($J9)) | E10: =IF($B10="","",N($C10)+N($D10)) | F10: =IF($B10="","",SUMIFS('العهد والرحلات'!$J$4:$J$2003,'العهد والرحلات'!$B$4:$B$2003,$B10)) | G10: =IF($B10="","",SUMIFS('الإيصالات'!$C$4:$C$2003,'الإيصالات'!$B$4:$B$2003,$B10)) | I10: =IF($B10="","",N($F10)+N($G10)+N($H10)) | J10: =IF($B10="","",N($E10)-N($I10))
A11: =IF($B11="","",COUNTA($B$4:$B11)) | C11: =IF($B11="","",N($J10)) | E11: =IF($B11="","",N($C11)+N($D11)) | F11: =IF($B11="","",SUMIFS('العهد والرحلات'!$J$4:$J$2003,'العهد والرحلات'!$B$4:$B$2003,$B11)) | G11: =IF($B11="","",SUMIFS('الإيصالات'!$C$4:$C$2003,'الإيصالات'!$B$4:$B$2003,$B11)) | I11: =IF($B11="","",N($F11)+N($G11)+N($H11)) | J11: =IF($B11="","",N($E11)-N($I11))
A12: =IF($B12="","",COUNTA($B$4:$B12)) | C12: =IF($B12="","",N($J11)) | E12: =IF($B12="","",N($C12)+N($D12)) | F12: =IF($B12="","",SUMIFS('العهد والرحلات'!$J$4:$J$2003,'العهد والرحلات'!$B$4:$B$2003,$B12)) | G12: =IF($B12="","",SUMIFS('الإيصالات'!$C$4:$C$2003,'الإيصالات'!$B$4:$B$2003,$B12)) | I12: =IF($B12="","",N($F12)+N($G12)+N($H12)) | J12: =IF($B12="","",N($E12)-N($I12))
A13: =IF($B13="","",COUNTA($B$4:$B13)) | C13: =IF($B13="","",N($J12)) | E13: =IF($B13="","",N($C13)+N($D13)) | F13: =IF($B13="","",SUMIFS('العهد والرحلات'!$J$4:$J$2003,'العهد والرحلات'!$B$4:$B$2003,$B13)) | G13: =IF($B13="","",SUMIFS('الإيصالات'!$C$4:$C$2003,'الإيصالات'!$B$4:$B$2003,$B13)) | I13: =IF($B13="","",N($F13)+N($G13)+N($H13)) | J13: =IF($B13="","",N($E13)-N($I13))
A14: =IF($B14="","",COUNTA($B$4:$B14)) | C14: =IF($B14="","",N($J13)) | E14: =IF($B14="","",N($C14)+N($D14)) | F14: =IF($B14="","",SUMIFS('العهد والرحلات'!$J$4:$J$2003,'العهد والرحلات'!$B$4:$B$2003,$B14)) | G14: =IF($B14="","",SUMIFS('الإيصالات'!$C$4:$C$2003,'الإيصالات'!$B$4:$B$2003,$B14)) | I14: =IF($B14="","",N($F14)+N($G14)+N($H14)) | J14: =IF($B14="","",N($E14)-N($I14))
A15: =IF($B15="","",COUNTA($B$4:$B15)) | C15: =IF($B15="","",N($J14)) | E15: =IF($B15="","",N($C15)+N($D15)) | F15: =IF($B15="","",SUMIFS('العهد والرحلات'!$J$4:$J$2003,'العهد والرحلات'!$B$4:$B$2003,$B15)) | G15: =IF($B15="","",SUMIFS('الإيصالات'!$C$4:$C$2003,'الإيصالات'!$B$4:$B$2003,$B15)) | I15: =IF($B15="","",N($F15)+N($G15)+N($H15)) | J15: =IF($B15="","",N($E15)-N($I15))
A16: =IF($B16="","",COUNTA($B$4:$B16)) | C16: =IF($B16="","",N($J15)) | E16: =IF($B16="","",N($C16)+N($D16)) | F16: =IF($B16="","",SUMIFS('العهد والرحلات'!$J$4:$J$2003,'العهد والرحلات'!$B$4:$B$2003,$B16)) | G16: =IF($B16="","",SUMIFS('الإيصالات'!$C$4:$C$2003,'الإيصالات'!$B$4:$B$2003,$B16)) | I16: =IF($B16="","",N($F16)+N($G16)+N($H16)) | J16: =IF($B16="","",N($E16)-N($I16))
... A503: =IF($B503="","",COUNTA($B$4:$B503)) | C503: =IF($B503="","",N($J502)) | E503: =IF($B503="","",N($C503)+N($D503)) | F503: =IF($B503="","",SUMIFS('العهد والرحلات'!$J$4:$J$2003,'العهد والرحلات'!$B$4:$B$2003,$B503)) | G503: =IF($B503="","",SUMIFS('الإيصالات'!$C$4:$C$2003,'الإيصالات'!$B$4:$B$2003,$B503)) | I503: =IF($B503="","",N($F503)+N($G503)+N($H503)) | J503: =IF($B503="","",N($E503)-N($I503))
B504: الإجماليات | D504: =SUM($D$4:$D$503) | F504: =SUM($F$4:$F$503) | G504: =SUM($G$4:$G$503) | H504: =SUM($H$4:$H$503) | I504: =SUM($I$4:$I$503)

Sheet العهد والرحلات
A1: شركة المتوكل — العهد والرحلات
A2: سجل مستمر لكل الرحلات والعُهد — يوماً بعد يوم
A3: م | B3: التاريخ | C3: عدد الحاويات | D3: شركة الشحن | E3: اسم الشركة | F3: الجهة | G3: توكيل | H3: الميناء | I3: مالك السيارة | J3: العهد
A4: =IF($B4="","",COUNTA($B$4:$B4))
A5: =IF($B5="","",COUNTA($B$4:$B5))
A6: =IF($B6="","",COUNTA($B$4:$B6))
A7: =IF($B7="","",COUNTA($B$4:$B7))
A8: =IF($B8="","",COUNTA($B$4:$B8))
A9: =IF($B9="","",COUNTA($B$4:$B9))
A10: =IF($B10="","",COUNTA($B$4:$B10))
A11: =IF($B11="","",COUNTA($B$4:$B11))
A12: =IF($B12="","",COUNTA($B$4:$B12))
A13: =IF($B13="","",COUNTA($B$4:$B13))
A14: =IF($B14="","",COUNTA($B$4:$B14))
A15: =IF($B15="","",COUNTA($B$4:$B15))
... A2003: =IF($B2003="","",COUNTA($B$4:$B2003))
B2004: الإجماليات | C2004: =SUM($C$4:$C$2003) | J2004: =SUM($J$4:$J$2003)

Sheet الإيصالات
A1: شركة المتوكل — الإيصالات
A2: سجل مستمر لكل الإيصالات — يوماً بعد يوم
A3: م | B3: التاريخ | C3: المبلغ | D3: البيان / الجهة
A4: =IF($B4="","",COUNTA($B$4:$B4))
A5: =IF($B5="","",COUNTA($B$4:$B5))
A6: =IF($B6="","",COUNTA($B$4:$B6))
A7: =IF($B7="","",COUNTA($B$4:$B7))
A8: =IF($B8="","",COUNTA($B$4:$B8))
A9: =IF($B9="","",COUNTA($B$4:$B9))
A10: =IF($B10="","",COUNTA($B$4:$B10))
A11: =IF($B11="","",COUNTA($B$4:$B11))
A12: =IF($B12="","",COUNTA($B$4:$B12))
A13: =IF($B13="","",COUNTA($B$4:$B13))
A14: =IF($B14="","",COUNTA($B$4:$B14))
A15: =IF($B15="","",COUNTA($B$4:$B15))
... A2003: =IF($B2003="","",COUNTA($B$4:$B2003))
B2004: الإجماليات | C2004: =SUM($C$4:$C$2003)

Sheet الإعدادات
A1: شركة المتوكل — الإعدادات والقوائم
A2: قوائم محلية + نسخة محدَّثة من قوائم الملف الأساسي (تُزامَن بسكربت المزامنة)
A3: الإعداد | B3: القيمة | D3: شركة الشحن | E3: توكيل | F3: الميناء | H3: الشركات (من الأساسي) | I3: الجهات (من الأساسي) | J3: ملاك السيارات (من الأساسي)
A4: رصيد عهدة افتتاحي (أول يوم) | B4: 0 | D4: ميرسك | F4: الإسكندرية | H4: l g | I4: أكتوبر | J4: ا/ماجد
D5: MSC | F5: الدخيلة | H5: ابيك | I5: ابو حماد | J5: ابراهيم ابو طالب
D6: CMA CGM | F6: دمياط | H6: اتش ام ام | I6: ابو رواش | J6: ابراهيم الشندويلى
D7: هاباج لويد | F7: بورسعيد | H7: اتش بى فلور | I7: ابو غالب | J7: ابراهيم الصعيدى
D8: ONE | F8: غرب بورسعيد | H8: اتش بى فولر | I8: ابوحماد الشرقيه | J8: ابراهيم العمدة
D9: إيفرغرين | F9: شرق بورسعيد | H9: اتش تى ام | I9: ابورواش | J9: ابراهيم القها
D10: كوسكو | F10: السخنة | H10: اتش دى | I10: ابيس | J10: ابراهيم انور
D11: يانغ مينغ | F11: سفاجا | H11: اجرو جرين | I11: اشاص / ج العبور | J11: ابراهيم عفيفى
D12: هيونداي | F12: نويبع | H12: اجرو لاند | I12: اكبوبر | J12: ابراهيم كامل
D13: زيم | F13: العريش | H13: اجروفود | I13: اكتوبر | J13: ابراهيم يسرى
D14: OOCL | F14: 6 أكتوبر الجاف | H14: اجريفود | I14: الاسماعيليه | J14: ابراهيم يونس
D15: سيلاند | F15: القاهرة الجاف | H15: ادفاليو | I15: الاقصر | J15: ابرهيم غزال
D16: الوطنية | H16: ارستون | I16: البدرشين | J16: ابو ادم
H17: اركانا | I17: البراوى | J17: ابو رحاب
H18: اروماتك | I18: البرج | J18: ابو طالب
H19: اروماتيك | I19: التجمع | J19: ابو كارما
H20: استيل لاند | I20: التجمع 5 | J20: ابو مينا
H21: اسطنبول | I21: التجمع الاول | J21: ابو هبش
H22: اكما | I22: التوفيقية | J22: ابو يحى
H23: ال موندو | I23: الجيزة | J23: ابوادم
H24: الاسراء | I24: الحسينية | J24: احمد
H25: الاكرامى | I25: الحوامدية | J25: احمد ابراهيم
H26: الامراء | I26: الخطاطبة | J26: احمد البو
H27: الامل | I27: الزاوية الحمراء | J27: احمد السويفى
H28: الانارة العامة | I28: السادات | J28: احمد الشريف
... H127: انترواكو | I127: وادى النطرون | J127: حسين
H128: انجنيرنج | J128: حماة الكحكى
H129: انرجى فيجن | J129: حمادة الصعيدى
H130: انرجيا | J130: حمادة الطوخى
H131: انرجين فيجن | J131: حمادة ذكى
H132: او ان تى | J132: حمادة مصطفى
H133: اوبال شعراوى | J133: حماده خليف
H134: اورجانيك | J134: حمدى
H135: اورجنيك | J135: حمدى البيضة
H136: اوركيد | J136: حمو البيبى
H137: اورماتيك | J137: حمو مرزوق
H138: اورينات | J138: حميدو شكير
...

Sheet الدليل
A1: شركة المتوكل — دليل ملف التقفيل اليومي
A2: اقرأ قبل الاستخدام
B3: طريقة العمل اليومية
B4: ١) العهد والرحلات | C4: سجّل كل رحلة في صفحة (العهد والرحلات): التاريخ + عدد الحاويات + شركة الشحن + الشركة + الجهة + التوكيل + الميناء + مالك السيارة + مبلغ العهدة.
B5: ٢) الإيصالات | C5: سجّل كل إيصال في صفحة (الإيصالات): التاريخ + المبلغ + البيان/الجهة.
B6: ٣) سجل اليومية | C6: أضِف صفاً واحداً لكل يوم: اكتب (التاريخ) و(العهدة المستلمة) و(مصروفات أخرى إن وجدت). الباقي يُحسب تلقائياً ويترحّل الرصيد لليوم التالي.
B7: ٤) تقفيل اليوم | C7: افتح صفحة (تقفيل اليوم)، اكتب التاريخ في الخانة الصفراء، فيظهر تقفيل اليوم كامل جاهز للطباعة.
B9: معادلة التقفيل
B10: باقي عهدة سابق | C10: رصيد أمس المُرحَّل (وأول يوم = الرصيد الافتتاحي في صفحة الإعدادات).
B11: إجمالي العهدة المتاحة | C11: باقي عهدة سابق + العهدة المستلمة اليوم.
B12: إجمالي المصروف | C12: عهد الرحلات + الإيصالات + مصروفات أخرى.
B13: رصيد مُرحَّل لليوم التالي | C13: إجمالي العهدة المتاحة ناقص إجمالي المصروف (لو ظهر أحمر يبقى فيه عجز عهدة).
B15: القوائم والربط بالأساسي
B16: قوائم من الأساسي | C16: الشركات + الجهات + ملاك السيارات نسخة محدَّثة من الملف الأساسي، مدمجة داخل هذا الملف — تظهر فوراً بدون أي روابط.
B17: تحديث القوائم | C17: لما تضيف أسماء جديدة في الأساسي، شغّل سكربت المزامنة (sync_lists.py) فيحدّث القوائم هنا بدون ما يلمس بياناتك.
B18: قوائم محلية | C18: شركة الشحن + التوكيل + الميناء قوائم خاصة بهذا الملف — عدّلها مباشرة في صفحة (الإعدادات).
B19: الكتابة اليدوية | C19: القوائم للتسهيل فقط ولا تمنع الكتابة — تقدر تكتب أي اسم مش موجود في القائمة عادي.
B20: ملاحظة | C20: ما فيش أي ارتباط بملف خارجي، فالملف يفتح لوحده من غير رسائل تحديث روابط.
