Workbook
Name نسبة_القيمة_المضافة: 'الإعدادات'!$B$5
Name سنة_التقارير: 'الإعدادات'!$B$6
Name قائمة_التصنيفات: 'الإعدادات'!$D$4:$D$203
Name قائمة_الشركات: 'الإعدادات'!$E$4:$E$203
Name قائمة_الجهات: 'الإعدادات'!$F$4:$F$203
Name قائمة_السائقين: 'الإعدادات'!$G$4:$G$203
Name قائمة_أصحاب_السيارات: 'الإعدادات'!$H$4:$H$203
Name قائمة_العملاء: 'الإعدادات'!$I$4:$I$203

Sheet لوحة التحكم
A1: شركة المتوكل — لوحة التحكم والمؤشرات
A2: نظرة شاملة على أداء الشركة — تُحدَّث تلقائياً مع إدخال البيانات
A4: إجمالي الإيرادات | E4: إجمالي المصروفات | I4: صافي الأرباح
A5: =SUM('البوالص'!$L$4:$L$2203)+SUM('شامل'!$O$4:$O$2203)+SUM('التخليص'!$G$4:$G$2203)+SUM('مولدات ايجي كول'!$G$4:$G$2203)+SUM('مولدات الشجيع'!$G$4:$G$2203) | E5: =SUM('البوالص'!$AF$4:$AF$2203)+SUM('شامل'!$T$4:$T$2203)+SUM('التخليص'!$F$4:$F$2203) | I5: =SUM('شامل'!$U$4:$U$2203)+SUM('شامل'!$V$4:$V$2203)+SUM('البوالص'!$AH$4:$AH$2203)
A7: إجمالي المتحصّلات | E7: المتبقي على العملاء | I7: إجمالي النولون
A8: =SUM('البوالص'!$Q$4:$Q$2203)+SUM('شامل'!$P$4:$P$2203)+SUM('التخليص'!$H$4:$H$2203)+SUM('مولدات ايجي كول'!$H$4:$H$2203)+SUM('مولدات الشجيع'!$H$4:$H$2203) | E8: =SUM('البوالص'!$R$4:$R$2203)+SUM('شامل'!$Q$4:$Q$2203)+SUM('التخليص'!$I$4:$I$2203)+SUM('مولدات ايجي كول'!$I$4:$I$2203)+SUM('مولدات الشجيع'!$I$4:$I$2203) | I8: =SUM('البوالص'!$L$4:$L$2203)+SUM('شامل'!$J$4:$J$2203)+SUM('مولدات ايجي كول'!$G$4:$G$2203)+SUM('مولدات الشجيع'!$G$4:$G$2203)
A10: عدد البوالص | C10: عدد الفواتير | E10: عدد الحاويات | G10: عدد المولدات | I10: شهادات التخليص
A11: =COUNT('البوالص'!$B$4:$B$2203) | C11: =COUNT('شامل'!$B$4:$B$2203) | E11: =SUM('شامل'!$I$4:$I$2203)+SUMPRODUCT(--('البوالص'!$H$4:$H$2203<>"")) | G11: =SUM('مولدات ايجي كول'!$F$4:$F$2203)+SUM('مولدات الشجيع'!$F$4:$F$2203) | I11: =COUNT('التخليص'!$B$4:$B$2203)
A13: التحليلات البيانية

Sheet البوالص
A1: شركة المتوكل — البوالص
A2: سجل بوالص الشحن ومحاسبة رحلات السيارات
A3: م | B3: التاريخ | C3: رقم البوليصة | D3: صاحب البيان | E3: التصنيف | F3: اسم الشركة | G3: الجهة | H3: رقم الحاوية | I3: رقم السيارة | J3: اسم السائق | K3: صاحب السيارة | L3: نولون | M3: عهدة | N3: تحويلة | O3: خصم | P3: بياتة (تحصيل) | Q3: دفعة | R3: باقي | S3: إجمالي التحصيل | T3: دور سواق | U3: دور تبّاع | V3: بياتة (مصروف) | W3: مصروف | X3: كرتات | Y3: تحيا مصر | Z3: ثبتان | AA3: ظ كاوتش | AB3: تصاريح | AC3: كاوتش | AD3: م أخرى | AE3: جاز | AF3: إجمالي المصروف | AG3: الباقي من العهدة | AH3: صافي السيارة | AI3: ربح/خسارة %
A4: =IF($B4="","",COUNTA($B$4:$B4)) | B4: 46023 | C4: 1974 | E4: كساحة ملاكى | G4: التجمع | H4: سيارة ملاكى | I4: 4373 س د و | J4: رامى سمير | K4: الدلوعة | L4: 4500 | M4: 3000 | Q4: 1500 | R4: =IF($B4="","",N($S4)-N($Q4)) | S4: =IF($B4="","",N($L4)+N($N4)+N($P4)) | AF4: =IF($B4="","",SUM($T4:$AE4)) | AG4: =IF($B4="","",N($M4)-N($AF4)) | AH4: =IF($B4="","",N($L4)-N($AF4)) | AI4: =IF($B4="","",IF(N($L4)=0,"",(N($L4)-N($AF4))/N($L4)))
A5: =IF($B5="","",COUNTA($B$4:$B5)) | B5: 46023 | C5: 1975 | E5: كساحة ملاكى | F5: محمد جميل | G5: اكتوبر | H5: سيارة ملاكى | I5: س م ب 7843 | J5: محمود محمد | K5: الدلوعة | L5: 4200 | M5: 3000 | Q5: 1200 | R5: =IF($B5="","",N($S5)-N($Q5)) | S5: =IF($B5="","",N($L5)+N($N5)+N($P5)) | AF5: =IF($B5="","",SUM($T5:$AE5)) | AG5: =IF($B5="","",N($M5)-N($AF5)) | AH5: =IF($B5="","",N($L5)-N($AF5)) | AI5: =IF($B5="","",IF(N($L5)=0,"",(N($L5)-N($AF5))/N($L5)))
A6: =IF($B6="","",COUNTA($B$4:$B6)) | B6: 46023 | C6: 1550 | D6: حمو مرزوق | E6: 1*40 | G6: السادات | H6: 067381/4 | I6: س ر ا 6671 | J6: السيد بدوى | K6: حمو مرزوق | L6: 11700 | M6: 7100 | O6: 200 | Q6: 4400 | R6: =IF($B6="","",N($S6)-N($Q6)) | S6: =IF($B6="","",N($L6)+N($N6)+N($P6)) | AF6: =IF($B6="","",SUM($T6:$AE6)) | AG6: =IF($B6="","",N($M6)-N($AF6)) | AH6: =IF($B6="","",N($L6)-N($AF6)) | AI6: =IF($B6="","",IF(N($L6)=0,"",(N($L6)-N($AF6))/N($L6)))
A7: =IF($B7="","",COUNTA($B$4:$B7)) | B7: 46023 | C7: 1549 | D7: حاتم البحر ق | E7: 1*40 | F7: ريجينا | G7: السادات | H7: 625009/2 | I7: س م ى 3925 | J7: عادل علام | K7: ايمن الزقزق | L7: 11700 | M7: 7100 | O7: 200 | Q7: 4400 | R7: =IF($B7="","",N($S7)-N($Q7)) | S7: =IF($B7="","",N($L7)+N($N7)+N($P7)) | AF7: =IF($B7="","",SUM($T7:$AE7)) | AG7: =IF($B7="","",N($M7)-N($AF7)) | AH7: =IF($B7="","",N($L7)-N($AF7)) | AI7: =IF($B7="","",IF(N($L7)=0,"",(N($L7)-N($AF7))/N($L7)))
A8: =IF($B8="","",COUNTA($B$4:$B8)) | B8: 46023 | C8: 1608 | D8: المكتب | E8: 2*20 | F8: ريجينا | G8: السادات | H8: 286911/9-137074/2 | I8: س ع م 8737 | J8: محمود بكر | K8: المكتب | L8: 15500 | M8: 6000 | Q8: 9500 | R8: =IF($B8="","",N($S8)-N($Q8)) | S8: =IF($B8="","",N($L8)+N($N8)+N($P8)) | T8: 1600 | U8: 600 | W8: 200 | X8: 60 | Y8: 60 | AC8: 50 | AE8: 2690 | AF8: =IF($B8="","",SUM($T8:$AE8)) | AG8: =IF($B8="","",N($M8)-N($AF8)) | AH8: =IF($B8="","",N($L8)-N($AF8)) | AI8: =IF($B8="","",IF(N($L8)=0,"",(N($L8)-N($AF8))/N($L8)))
A9: =IF($B9="","",COUNTA($B$4:$B9)) | B9: 46025 | C9: 1567 | D9: حاتم البحر ق | E9: 1*40 ث | F9: جرين لاند | G9: ك الدوار | H9: 862577/6 | I9: س م ب 3925 | J9: عادل محمد | K9: علاء علام | L9: 9000 | M9: 5100 | O9: 200 | Q9: 3700 | R9: =IF($B9="","",N($S9)-N($Q9)) | S9: =IF($B9="","",N($L9)+N($N9)+N($P9)) | AF9: =IF($B9="","",SUM($T9:$AE9)) | AG9: =IF($B9="","",N($M9)-N($AF9)) | AH9: =IF($B9="","",N($L9)-N($AF9)) | AI9: =IF($B9="","",IF(N($L9)=0,"",(N($L9)-N($AF9))/N($L9)))
A10: =IF($B10="","",COUNTA($B$4:$B10)) | B10: 46025 | C10: 1568 | D10: علاء علام | E10: 1*40 ث | F10: جرين لاند | G10: ك الدوار | H10: 508450/0 | I10: س ل ب 5917 | J10: احمد محمود فرج | K10: علاء علام | L10: 9000 | M10: 5100 | O10: 200 | Q10: 3700 | R10: =IF($B10="","",N($S10)-N($Q10)) | S10: =IF($B10="","",N($L10)+N($N10)+N($P10)) | AF10: =IF($B10="","",SUM($T10:$AE10)) | AG10: =IF($B10="","",N($M10)-N($AF10)) | AH10: =IF($B10="","",N($L10)-N($AF10)) | AI10: =IF($B10="","",IF(N($L10)=0,"",(N($L10)-N($AF10))/N($L10)))
A11: =IF($B11="","",COUNTA($B$4:$B11)) | B11: 46025 | C11: 1569 | D11: ابو مينا | E11: 1*40 ث | F11: جرين لاند | G11: ك الدوار | H11: 554623/3 | I11: س ع ف 5194 | J11: محمد حسان | K11: ابو مينا | L11: 9000 | M11: 5100 | O11: 200 | Q11: 3700 | R11: =IF($B11="","",N($S11)-N($Q11)) | S11: =IF($B11="","",N($L11)+N($N11)+N($P11)) | AF11: =IF($B11="","",SUM($T11:$AE11)) | AG11: =IF($B11="","",N($M11)-N($AF11)) | AH11: =IF($B11="","",N($L11)-N($AF11)) | AI11: =IF($B11="","",IF(N($L11)=0,"",(N($L11)-N($AF11))/N($L11)))
A12: =IF($B12="","",COUNTA($B$4:$B12)) | B12: 46025 | C12: 1570 | D12: حمو مرزوق | E12: 1*40 ث | F12: جرين لاند | G12: ك الدوار | H12: 158456/3 | I12: س ر ا 6671 | J12: السيد بدوى | K12: حمو مرزوق | L12: 9500 | M12: 5100 | O12: 200 | Q12: 4200 | R12: =IF($B12="","",N($S12)-N($Q12)) | S12: =IF($B12="","",N($L12)+N($N12)+N($P12)) | AF12: =IF($B12="","",SUM($T12:$AE12)) | AG12: =IF($B12="","",N($M12)-N($AF12)) | AH12: =IF($B12="","",N($L12)-N($AF12)) | AI12: =IF($B12="","",IF(N($L12)=0,"",(N($L12)-N($AF12))/N($L12)))
A13: =IF($B13="","",COUNTA($B$4:$B13)) | B13: 46025 | C13: 1571 | D13: صعيدى 1خ | E13: 1*40 ث | F13: جرين لاند | G13: ك الدوار | H13: 509384/2 | I13: س ر ا 9611 | J13: ياسر محمد | K13: محمد الصعيدى | L13: 9000 | M13: 5100 | O13: 200 | Q13: 3700 | R13: =IF($B13="","",N($S13)-N($Q13)) | S13: =IF($B13="","",N($L13)+N($N13)+N($P13)) | AF13: =IF($B13="","",SUM($T13:$AE13)) | AG13: =IF($B13="","",N($M13)-N($AF13)) | AH13: =IF($B13="","",N($L13)-N($AF13)) | AI13: =IF($B13="","",IF(N($L13)=0,"",(N($L13)-N($AF13))/N($L13)))
A14: =IF($B14="","",COUNTA($B$4:$B14)) | B14: 46025 | C14: 1610 | D14: ايوب خ | E14: 1*20 | F14: حلوانى اخوان | G14: العاشر | H14: 089103/0 | I14: ب ا ج 7235 | J14: حسام محمد | K14: ايوب | L14: 13000 | M14: 8100 | O14: 200 | Q14: 4700 | R14: =IF($B14="","",N($S14)-N($Q14)) | S14: =IF($B14="","",N($L14)+N($N14)+N($P14)) | AF14: =IF($B14="","",SUM($T14:$AE14)) | AG14: =IF($B14="","",N($M14)-N($AF14)) | AH14: =IF($B14="","",N($L14)-N($AF14)) | AI14: =IF($B14="","",IF(N($L14)=0,"",(N($L14)-N($AF14))/N($L14)))
A15: =IF($B15="","",COUNTA($B$4:$B15)) | B15: 46025 | C15: 1611 | D15: المكتب | E15: 2*20 | F15: حلوانى اخوان | G15: العاشر | H15: 093991/5-177254/4 | I15: س ع م 8737 | J15: محمود بكر | K15: المكتب | L15: 19000 | M15: 5000 | Q15: 14000 | R15: =IF($B15="","",N($S15)-N($Q15)) | S15: =IF($B15="","",N($L15)+N($N15)+N($P15)) | T15: 1700 | U15: 700 | W15: 200 | X15: 130 | Y15: 60 | AB15: 250 | AC15: 120 | AE15: 3940 | AF15: =IF($B15="","",SUM($T15:$AE15)) | AG15: =IF($B15="","",N($M15)-N($AF15)) | AH15: =IF($B15="","",N($L15)-N($AF15)) | AI15: =IF($B15="","",IF(N($L15)=0,"",(N($L15)-N($AF15))/N($L15)))
A16: =IF($B16="","",COUNTA($B$4:$B16)) | B16: 46025 | C16: 1609 | D16: عتريس مخيمر خ | E16: 1*40 | F16: يونايتد باك | G16: اكتوبر | H16: 422287/2 | I16: ب ص ا 2574 | J16: محمد البحيرى | K16: احمد خليف | L16: 12700 | M16: 7100 | O16: 200 | Q16: 5400 | R16: =IF($B16="","",N($S16)-N($Q16)) | S16: =IF($B16="","",N($L16)+N($N16)+N($P16)) | AF16: =IF($B16="","",SUM($T16:$AE16)) | AG16: =IF($B16="","",N($M16)-N($AF16)) | AH16: =IF($B16="","",N($L16)-N($AF16)) | AI16: =IF($B16="","",IF(N($L16)=0,"",(N($L16)-N($AF16))/N($L16)))
A17: =IF($B17="","",COUNTA($B$4:$B17)) | B17: 46026 | C17: 1614 | D17: سعد منير | E17: 1*40 | F17: الريعى | G17: ابو حماد | H17: 504109/8 | I17: ب ن و 6487 | J17: احمد رياض | K17: استوريا | L17: 16000 | M17: 8100 | O17: 200 | Q17: 7700 | R17: =IF($B17="","",N($S17)-N($Q17)) | S17: =IF($B17="","",N($L17)+N($N17)+N($P17)) | AF17: =IF($B17="","",SUM($T17:$AE17)) | AG17: =IF($B17="","",N($M17)-N($AF17)) | AH17: =IF($B17="","",N($L17)-N($AF17)) | AI17: =IF($B17="","",IF(N($L17)=0,"",(N($L17)-N($AF17))/N($L17)))
A18: =IF($B18="","",COUNTA($B$4:$B18)) | B18: 46026 | C18: 1615 | D18: عتريس مخيمر خ | E18: 1*40 | F18: الريعى | G18: ابو حماد | H18: 519205/3 | I18: ب ص ا 2574 | J18: محمد البحيرى | K18: احمد خليف | L18: 15000 | M18: 8100 | O18: 200 | Q18: 6700 | R18: =IF($B18="","",N($S18)-N($Q18)) | S18: =IF($B18="","",N($L18)+N($N18)+N($P18)) | AF18: =IF($B18="","",SUM($T18:$AE18)) | AG18: =IF($B18="","",N($M18)-N($AF18)) | AH18: =IF($B18="","",N($L18)-N($AF18)) | AI18: =IF($B18="","",IF(N($L18)=0,"",(N($L18)-N($AF18))/N($L18)))
A19: =IF($B19="","",COUNTA($B$4:$B19)) | B19: 46026 | C19: 1613 | D19: المكتب | E19: 1*40 | F19: يونايتد باك | G19: العاشر | H19: 483811/9 | I19: س ع م 8737 | J19: محمود بكر | K19: المكتب | L19: 14500 | M19: 5500 | Q19: 9000 | R19: =IF($B19="","",N($S19)-N($Q19)) | S19: =IF($B19="","",N($L19)+N($N19)+N($P19)) | T19: 1500 | U19: 600 | W19: 150 | X19: 130 | Y19: 60 | AC19: 250 | AE19: 3450 | AF19: =IF($B19="","",SUM($T19:$AE19)) | AG19: =IF($B19="","",N($M19)-N($AF19)) | AH19: =IF($B19="","",N($L19)-N($AF19)) | AI19: =IF($B19="","",IF(N($L19)=0,"",(N($L19)-N($AF19))/N($L19)))
A20: =IF($B20="","",COUNTA($B$4:$B20)) | B20: 46026 | C20: 1612 | D20: احمد محسن | E20: 1*40 | F20: مصر اسبانيا | G20: السادات | H20: 590982/1 | I20: س ه ف 1387 | J20: محمد خميس | K20: احمد محسن | L20: 11700 | M20: 6100 | O20: 200 | Q20: 5400 | R20: =IF($B20="","",N($S20)-N($Q20)) | S20: =IF($B20="","",N($L20)+N($N20)+N($P20)) | AF20: =IF($B20="","",SUM($T20:$AE20)) | AG20: =IF($B20="","",N($M20)-N($AF20)) | AH20: =IF($B20="","",N($L20)-N($AF20)) | AI20: =IF($B20="","",IF(N($L20)=0,"",(N($L20)-N($AF20))/N($L20)))
A21: =IF($B21="","",COUNTA($B$4:$B21)) | B21: 46026 | C21: 1616 | D21: احمد عبدو خ | E21: 1*40 | F21: سمارت فود | G21: الخطاطبة | H21: 890001/0 | I21: س ا ه 8198 | J21: ياسر عويضة | K21: علاء علام | L21: 11700 | M21: 7100 | O21: 200 | Q21: 4400 | R21: =IF($B21="","",N($S21)-N($Q21)) | S21: =IF($B21="","",N($L21)+N($N21)+N($P21)) | AF21: =IF($B21="","",SUM($T21:$AE21)) | AG21: =IF($B21="","",N($M21)-N($AF21)) | AH21: =IF($B21="","",N($L21)-N($AF21)) | AI21: =IF($B21="","",IF(N($L21)=0,"",(N($L21)-N($AF21))/N($L21)))
A22: =IF($B22="","",COUNTA($B$4:$B22)) | B22: 46026 | C22: 1617 | D22: احمد عبدو خ | E22: 1*40 | F22: سمارت فود | G22: الخطاطبة | H22: 846234/7 | I22: س ل ب 5917 | J22: محمود احمد | K22: علاء علام | L22: 11700 | M22: 7100 | O22: 200 | Q22: 4400 | R22: =IF($B22="","",N($S22)-N($Q22)) | S22: =IF($B22="","",N($L22)+N($N22)+N($P22)) | AF22: =IF($B22="","",SUM($T22:$AE22)) | AG22: =IF($B22="","",N($M22)-N($AF22)) | AH22: =IF($B22="","",N($L22)-N($AF22)) | AI22: =IF($B22="","",IF(N($L22)=0,"",(N($L22)-N($AF22))/N($L22)))
A23: =IF($B23="","",COUNTA($B$4:$B23)) | B23: 46026 | C23: 1572 | D23: حمو مرزوق | E23: 2*20 | F23: الدولية للفحم | G23: البرج | H23: 308570/4-096658/1 | I23: س ر ا 6671 | J23: السيد بدوى | K23: حمو مرزوق | L23: 10000 | M23: 5000 | Q23: 5000 | R23: =IF($B23="","",N($S23)-N($Q23)) | S23: =IF($B23="","",N($L23)+N($N23)+N($P23)) | AF23: =IF($B23="","",SUM($T23:$AE23)) | AG23: =IF($B23="","",N($M23)-N($AF23)) | AH23: =IF($B23="","",N($L23)-N($AF23)) | AI23: =IF($B23="","",IF(N($L23)=0,"",(N($L23)-N($AF23))/N($L23)))
A24: =IF($B24="","",COUNTA($B$4:$B24)) | B24: 46027 | C24: 1575 | D24: بدوى صلاح | E24: 1*20 | F24: مصر اسبانيا | G24: السادات | H24: 224206/5 | I24: ط ف ر 4847 | J24: محمد عبدالله | K24: عصفور | L24: 9000 | M24: 6100 | O24: 200 | Q24: 2700 | R24: =IF($B24="","",N($S24)-N($Q24)) | S24: =IF($B24="","",N($L24)+N($N24)+N($P24)) | AF24: =IF($B24="","",SUM($T24:$AE24)) | AG24: =IF($B24="","",N($M24)-N($AF24)) | AH24: =IF($B24="","",N($L24)-N($AF24)) | AI24: =IF($B24="","",IF(N($L24)=0,"",(N($L24)-N($AF24))/N($L24)))
A25: =IF($B25="","",COUNTA($B$4:$B25)) | B25: 46027 | C25: 1573 | D25: ايوب خ | E25: 1*20 | F25: الحناوي | G25: السادات | H25: 276863/3 | I25: ب د ن 5863 | J25: احمد السعيد | K25: ايوب | L25: 11500 | M25: 2600 | O25: 200 | Q25: 8700 | R25: =IF($B25="","",N($S25)-N($Q25)) | S25: =IF($B25="","",N($L25)+N($N25)+N($P25)) | AF25: =IF($B25="","",SUM($T25:$AE25)) | AG25: =IF($B25="","",N($M25)-N($AF25)) | AH25: =IF($B25="","",N($L25)-N($AF25)) | AI25: =IF($B25="","",IF(N($L25)=0,"",(N($L25)-N($AF25))/N($L25)))
A26: =IF($B26="","",COUNTA($B$4:$B26)) | B26: 46027 | C26: 1574 | D26: سعد منير | E26: 1*40 | F26: فابريك | G26: العاشر | H26: 786743/2 | I26: ب ج ط 9147 | J26: رضا محمد | K26: استوريا | L26: 14500 | M26: 8100 | O26: 200 | Q26: 6200 | R26: =IF($B26="","",N($S26)-N($Q26)) | S26: =IF($B26="","",N($L26)+N($N26)+N($P26)) | AF26: =IF($B26="","",SUM($T26:$AE26)) | AG26: =IF($B26="","",N($M26)-N($AF26)) | AH26: =IF($B26="","",N($L26)-N($AF26)) | AI26: =IF($B26="","",IF(N($L26)=0,"",(N($L26)-N($AF26))/N($L26)))
A27: =IF($B27="","",COUNTA($B$4:$B27)) | B27: 46027 | C27: 1651 | D27: ابو مينا | E27: 1*40 | F27: وادي الرياض | G27: الاسماعيليه | H27: 713234/4 | I27: ي ر ع 7945 | J27: علي جاد | K27: ابو مينا | L27: 17000 | M27: 9100 | O27: 200 | Q27: 7700 | R27: =IF($B27="","",N($S27)-N($Q27)) | S27: =IF($B27="","",N($L27)+N($N27)+N($P27)) | AF27: =IF($B27="","",SUM($T27:$AE27)) | AG27: =IF($B27="","",N($M27)-N($AF27)) | AH27: =IF($B27="","",N($L27)-N($AF27)) | AI27: =IF($B27="","",IF(N($L27)=0,"",(N($L27)-N($AF27))/N($L27)))
A28: =IF($B28="","",COUNTA($B$4:$B28)) | B28: 46027 | C28: 1576 | D28: الشريف خ | E28: 1*40 | F28: الريعي | G28: ابوحماد الشرقيه | H28: 761414/4 | I28: ب د ف 5419 | J28: سمير نوفل | K28: الليبر | L28: 15000 | M28: 8100 | O28: 200 | Q28: 6700 | R28: =IF($B28="","",N($S28)-N($Q28)) | S28: =IF($B28="","",N($L28)+N($N28)+N($P28)) | AF28: =IF($B28="","",SUM($T28:$AE28)) | AG28: =IF($B28="","",N($M28)-N($AF28)) | AH28: =IF($B28="","",N($L28)-N($AF28)) | AI28: =IF($B28="","",IF(N($L28)=0,"",(N($L28)-N($AF28))/N($L28)))
A29: =IF($B29="","",COUNTA($B$4:$B29)) | B29: 46027 | C29: 1577 | D29: حمو مرزوق | E29: 1*40 | F29: الريعي | G29: ابوحماد الشرقيه | H29: 797675/2 | I29: س ر ا 6671 | J29: السيد مرسي | K29: حمو مرزوق | L29: 15500 | M29: 8100 | O29: 200 | Q29: 7200 | R29: =IF($B29="","",N($S29)-N($Q29)) | S29: =IF($B29="","",N($L29)+N($N29)+N($P29)) | AF29: =IF($B29="","",SUM($T29:$AE29)) | AG29: =IF($B29="","",N($M29)-N($AF29)) | AH29: =IF($B29="","",N($L29)-N($AF29)) | AI29: =IF($B29="","",IF(N($L29)=0,"",(N($L29)-N($AF29))/N($L29)))
A30: =IF($B30="","",COUNTA($B$4:$B30)) | B30: 46028 | C30: 1288 | D30: ايوب خ | E30: 1*20 | F30: ايه كيه اتشى | G30: الهرم سقاره | H30: 101173/2 | I30: ب ع ا 5839 | J30: هاني شريف | K30: ايوب | L30: 10000 | M30: 7100 | O30: 200 | Q30: 2700 | R30: =IF($B30="","",N($S30)-N($Q30)) | S30: =IF($B30="","",N($L30)+N($N30)+N($P30)) | AF30: =IF($B30="","",SUM($T30:$AE30)) | AG30: =IF($B30="","",N($M30)-N($AF30)) | AH30: =IF($B30="","",N($L30)-N($AF30)) | AI30: =IF($B30="","",IF(N($L30)=0,"",(N($L30)-N($AF30))/N($L30)))
A31: =IF($B31="","",COUNTA($B$4:$B31)) | B31: 46028 | C31: 1578 | D31: عتريس مخيمر خ | E31: 1*40 | F31: الدوليه انترناشونال | G31: العاشر | H31: 46723/0 | I31: ب ص ا 2574 | J31: حمدي البحيري | K31: البحيري | L31: 14000 | M31: 8100 | O31: 200 | Q31: 5700 | R31: =IF($B31="","",N($S31)-N($Q31)) | S31: =IF($B31="","",N($L31)+N($N31)+N($P31)) | AF31: =IF($B31="","",SUM($T31:$AE31)) | AG31: =IF($B31="","",N($M31)-N($AF31)) | AH31: =IF($B31="","",N($L31)-N($AF31)) | AI31: =IF($B31="","",IF(N($L31)=0,"",(N($L31)-N($AF31))/N($L31)))
A32: =IF($B32="","",COUNTA($B$4:$B32)) | B32: 46028 | C32: 1579 | D32: المكتب | E32: 1*40 | F32: الدوليه | G32: العاشر | H32: 659169/8 | I32: س ع م 8737 | J32: محمود بكر | K32: المكتب | L32: 14000 | M32: 6000 | Q32: 8000 | R32: =IF($B32="","",N($S32)-N($Q32)) | S32: =IF($B32="","",N($L32)+N($N32)+N($P32)) | T32: 1500 | U32: 600 | W32: 150 | X32: 130 | Y32: 120 | AC32: 100 | AE32: 3630 | AF32: =IF($B32="","",SUM($T32:$AE32)) | AG32: =IF($B32="","",N($M32)-N($AF32)) | AH32: =IF($B32="","",N($L32)-N($AF32)) | AI32: =IF($B32="","",IF(N($L32)=0,"",(N($L32)-N($AF32))/N($L32)))
A33: =IF($B33="","",COUNTA($B$4:$B33)) | B33: 46029 | C33: 1618 | D33: حمو مرزوق | E33: 1*40 | F33: اجرو جرين | G33: جمصه | H33: 500718/5 | I33: س ر ا 6671 | J33: السيد بدوي | K33: حمو مرزوق | L33: 13500 | M33: 7100 | O33: 200 | Q33: 6200 | R33: =IF($B33="","",N($S33)-N($Q33)) | S33: =IF($B33="","",N($L33)+N($N33)+N($P33)) | AF33: =IF($B33="","",SUM($T33:$AE33)) | AG33: =IF($B33="","",N($M33)-N($AF33)) | AH33: =IF($B33="","",N($L33)-N($AF33)) | AI33: =IF($B33="","",IF(N($L33)=0,"",(N($L33)-N($AF33))/N($L33)))
A34: =IF($B34="","",COUNTA($B$4:$B34)) | B34: 46030 | C34: 1584 | D34: حمو مرزوق | E34: 1*40 | F34: محمود مسعود | G34: الكيلو59 | H34: 828127/9 | I34: س ر ا 6671 | J34: السيد مرسي | K34: حمو مرزوق | L34: 10000 | M34: 7100 | O34: 200 | Q34: 2700 | R34: =IF($B34="","",N($S34)-N($Q34)) | S34: =IF($B34="","",N($L34)+N($N34)+N($P34)) | AF34: =IF($B34="","",SUM($T34:$AE34)) | AG34: =IF($B34="","",N($M34)-N($AF34)) | AH34: =IF($B34="","",N($L34)-N($AF34)) | AI34: =IF($B34="","",IF(N($L34)=0,"",(N($L34)-N($AF34))/N($L34)))
A35: =IF($B35="","",COUNTA($B$4:$B35)) | B35: 46030 | C35: 1585 | D35: استوريا خ | E35: 1*40 | F35: محمود مسعود | G35: الكيلو59 | H35: 560074/1 | I35: س ن ب 1649 | J35: محمد عاطف | K35: محمد صابر | L35: 10000 | M35: 5100 | O35: 200 | Q35: 4700 | R35: =IF($B35="","",N($S35)-N($Q35)) | S35: =IF($B35="","",N($L35)+N($N35)+N($P35)) | AF35: =IF($B35="","",SUM($T35:$AE35)) | AG35: =IF($B35="","",N($M35)-N($AF35)) | AH35: =IF($B35="","",N($L35)-N($AF35)) | AI35: =IF($B35="","",IF(N($L35)=0,"",(N($L35)-N($AF35))/N($L35)))
A36: =IF($B36="","",COUNTA($B$4:$B36)) | B36: 46030 | C36: 1580 | D36: احمد عبدو خ | E36: 1*40 | F36: المستقبل | G36: الخطاطبة | H36: 46905/8 | I36: س ل ب 5917 | J36: ياسر احمد | K36: علاء علام | L36: 11700 | M36: 7100 | O36: 200 | Q36: 4400 | R36: =IF($B36="","",N($S36)-N($Q36)) | S36: =IF($B36="","",N($L36)+N($N36)+N($P36)) | AF36: =IF($B36="","",SUM($T36:$AE36)) | AG36: =IF($B36="","",N($M36)-N($AF36)) | AH36: =IF($B36="","",N($L36)-N($AF36)) | AI36: =IF($B36="","",IF(N($L36)=0,"",(N($L36)-N($AF36))/N($L36)))
A37: =IF($B37="","",COUNTA($B$4:$B37)) | B37: 46030 | C37: 1581 | D37: مخزن | E37: 1*40 | F37: المستقبل | G37: الخطاطبة | H37: 40490/4 | I37: س ل ا 5468 | J37: حسام الدين محمد | K37: احمد مخزن | L37: 11700 | M37: 7100 | O37: 200 | Q37: 4400 | R37: =IF($B37="","",N($S37)-N($Q37)) | S37: =IF($B37="","",N($L37)+N($N37)+N($P37)) | AF37: =IF($B37="","",SUM($T37:$AE37)) | AG37: =IF($B37="","",N($M37)-N($AF37)) | AH37: =IF($B37="","",N($L37)-N($AF37)) | AI37: =IF($B37="","",IF(N($L37)=0,"",(N($L37)-N($AF37))/N($L37)))
A38: =IF($B38="","",COUNTA($B$4:$B38)) | B38: 46030 | C38: 1582 | D38: عتريس مخيمر خ | E38: 1*40 | F38: المستقبل | G38: الخطاطبة | H38: 4273392/6 | I38: ب ص ا 2574 | J38: محمد البحيرى | K38: البحيري | L38: 11700 | M38: 7100 | O38: 200 | Q38: 4400 | R38: =IF($B38="","",N($S38)-N($Q38)) | S38: =IF($B38="","",N($L38)+N($N38)+N($P38)) | AF38: =IF($B38="","",SUM($T38:$AE38)) | AG38: =IF($B38="","",N($M38)-N($AF38)) | AH38: =IF($B38="","",N($L38)-N($AF38)) | AI38: =IF($B38="","",IF(N($L38)=0,"",(N($L38)-N($AF38))/N($L38)))
A39: =IF($B39="","",COUNTA($B$4:$B39)) | B39: 46030 | C39: 1583 | D39: المكتب | E39: 1*40 | F39: المستقبل | G39: الخطاطبة | H39: 605262/2 | I39: س ع م 8737 | J39: محمود بكر | K39: المكتب | L39: 11700 | M39: 5000 | Q39: 6700 | R39: =IF($B39="","",N($S39)-N($Q39)) | S39: =IF($B39="","",N($L39)+N($N39)+N($P39)) | T39: 1400 | U39: 550 | V39: 300 | W39: 150 | X39: 65 | Y39: 120 | AE39: 2200 | AF39: =IF($B39="","",SUM($T39:$AE39)) | AG39: =IF($B39="","",N($M39)-N($AF39)) | AH39: =IF($B39="","",N($L39)-N($AF39)) | AI39: =IF($B39="","",IF(N($L39)=0,"",(N($L39)-N($AF39))/N($L39)))
A40: =IF($B40="","",COUNTA($B$4:$B40)) | B40: 46031 | C40: 1586 | D40: حاتم البحر ق | E40: 1*40 | G40: كفر الدوار | H40: 564861/6 | I40: س م ب 3925 | J40: عادل محمد علام | K40: الزوقزوق | L40: 9000 | M40: 5100 | O40: 200 | Q40: 3700 | R40: =IF($B40="","",N($S40)-N($Q40)) | S40: =IF($B40="","",N($L40)+N($N40)+N($P40)) | AF40: =IF($B40="","",SUM($T40:$AE40)) | AG40: =IF($B40="","",N($M40)-N($AF40)) | AH40: =IF($B40="","",N($L40)-N($AF40)) | AI40: =IF($B40="","",IF(N($L40)=0,"",(N($L40)-N($AF40))/N($L40)))
...

Sheet التخليص
A1: شركة المتوكل — التخليص
A2: سجل شهادات وأعمال التخليص الجمركي
A3: م | B3: التاريخ | C3: اسم الشهادة | D3: رقم الشهادة | E3: الأتعاب | F3: المصروفات | G3: إجمالي الكشف | H3: الدفعات | I3: المتبقي
A4: =IF($B4="","",COUNTA($B$4:$B4)) | G4: =IF($B4="","",N($E4)+N($F4)) | I4: =IF($B4="","",N($G4)-N($H4))
A5: =IF($B5="","",COUNTA($B$4:$B5)) | G5: =IF($B5="","",N($E5)+N($F5)) | I5: =IF($B5="","",N($G5)-N($H5))
A6: =IF($B6="","",COUNTA($B$4:$B6)) | G6: =IF($B6="","",N($E6)+N($F6)) | I6: =IF($B6="","",N($G6)-N($H6))
A7: =IF($B7="","",COUNTA($B$4:$B7)) | G7: =IF($B7="","",N($E7)+N($F7)) | I7: =IF($B7="","",N($G7)-N($H7))
A8: =IF($B8="","",COUNTA($B$4:$B8)) | G8: =IF($B8="","",N($E8)+N($F8)) | I8: =IF($B8="","",N($G8)-N($H8))
A9: =IF($B9="","",COUNTA($B$4:$B9)) | G9: =IF($B9="","",N($E9)+N($F9)) | I9: =IF($B9="","",N($G9)-N($H9))
A10: =IF($B10="","",COUNTA($B$4:$B10)) | G10: =IF($B10="","",N($E10)+N($F10)) | I10: =IF($B10="","",N($G10)-N($H10))
A11: =IF($B11="","",COUNTA($B$4:$B11)) | G11: =IF($B11="","",N($E11)+N($F11)) | I11: =IF($B11="","",N($G11)-N($H11))
A12: =IF($B12="","",COUNTA($B$4:$B12)) | G12: =IF($B12="","",N($E12)+N($F12)) | I12: =IF($B12="","",N($G12)-N($H12))
A13: =IF($B13="","",COUNTA($B$4:$B13)) | G13: =IF($B13="","",N($E13)+N($F13)) | I13: =IF($B13="","",N($G13)-N($H13))
A14: =IF($B14="","",COUNTA($B$4:$B14)) | G14: =IF($B14="","",N($E14)+N($F14)) | I14: =IF($B14="","",N($G14)-N($H14))
A15: =IF($B15="","",COUNTA($B$4:$B15)) | G15: =IF($B15="","",N($E15)+N($F15)) | I15: =IF($B15="","",N($G15)-N($H15))
... A2203: =IF($B2203="","",COUNTA($B$4:$B2203)) | G2203: =IF($B2203="","",N($E2203)+N($F2203)) | I2203: =IF($B2203="","",N($G2203)-N($H2203))
B2204: الإجماليات | E2204: =SUM($E$4:$E$2203) | F2204: =SUM($F$4:$F$2203) | G2204: =SUM($G$4:$G$2203) | H2204: =SUM($H$4:$H$2203) | I2204: =SUM($I$4:$I$2203)

Sheet مولدات ايجي كول
A1: شركة المتوكل — مولدات ايجي كول
A2: سجل نقل مولدات شركة ايجي كول
A3: م | B3: التاريخ | C3: اسم الشركة | D3: العنوان | E3: رقم الإذن | F3: عدد المولدات | G3: النولون | H3: الدفعات | I3: المتبقي
A4: =IF($B4="","",COUNTA($B$4:$B4)) | B4: 46030 | C4: المسعد | D4: البرج | E4: 871257 | F4: 2 | G4: 5500 | I4: =IF($B4="","",N($G4)-N($H4))
A5: =IF($B5="","",COUNTA($B$4:$B5)) | B5: 46033 | C5: ماى فارم | D5: جمصة | E5: 75127 | F5: 1 | G5: 2750 | I5: =IF($B5="","",N($G5)-N($H5))
A6: =IF($B6="","",COUNTA($B$4:$B6)) | B6: 46037 | C6: الفرسان | D6: اكتوبر | E6: 873056 | F6: 4 | G6: 11000 | I6: =IF($B6="","",N($G6)-N($H6))
A7: =IF($B7="","",COUNTA($B$4:$B7)) | B7: 46039 | C7: الفرسان | D7: اكتوبر | E7: 873078 | F7: 1 | G7: 2750 | I7: =IF($B7="","",N($G7)-N($H7))
A8: =IF($B8="","",COUNTA($B$4:$B8)) | B8: 46044 | C8: المجد | D8: النوبارية | E8: 3034 | F8: 2 | G8: 5500 | I8: =IF($B8="","",N($G8)-N($H8))
A9: =IF($B9="","",COUNTA($B$4:$B9)) | B9: 46046 | C9: ماى فارم | D9: جمصة | E9: 37584 | F9: 1 | G9: 2750 | I9: =IF($B9="","",N($G9)-N($H9))
A10: =IF($B10="","",COUNTA($B$4:$B10)) | B10: 46047 | C10: الصعيد | D10: بنى سويف | E10: 276995 | F10: 4 | G10: 11000 | I10: =IF($B10="","",N($G10)-N($H10))
A11: =IF($B11="","",COUNTA($B$4:$B11)) | B11: 46047 | C11: الصعيد | D11: بنى سويف | E11: 277114 | F11: 1 | G11: 2750 | I11: =IF($B11="","",N($G11)-N($H11))
A12: =IF($B12="","",COUNTA($B$4:$B12)) | B12: 46047 | C12: ماى فارم | D12: الجيزة | E12: 873146 | F12: 1 | G12: 2750 | I12: =IF($B12="","",N($G12)-N($H12))
A13: =IF($B13="","",COUNTA($B$4:$B13)) | B13: 46051 | C13: المجد | D13: النوبارية | E13: 1515 | F13: 2 | G13: 5500 | I13: =IF($B13="","",N($G13)-N($H13))
A14: =IF($B14="","",COUNTA($B$4:$B14)) | B14: 46051 | C14: المجد | D14: التوفيقية | E14: 1520 | F14: 3 | G14: 8250 | I14: =IF($B14="","",N($G14)-N($H14))
A15: =IF($B15="","",COUNTA($B$4:$B15)) | B15: 46055 | C15: بيك اجرى | D15: النوبارية | E15: 878856 | F15: 1 | G15: 2750 | I15: =IF($B15="","",N($G15)-N($H15))
A16: =IF($B16="","",COUNTA($B$4:$B16)) | B16: 46063 | H16: 50000 | I16: =IF($B16="","",N($G16)-N($H16))
A17: =IF($B17="","",COUNTA($B$4:$B17)) | B17: 46063 | C17: معبد فارم | D17: القناطر | E17: 882981 | F17: 1 | G17: 2750 | I17: =IF($B17="","",N($G17)-N($H17))
A18: =IF($B18="","",COUNTA($B$4:$B18)) | B18: 46068 | C18: انترواكو | D18: القناطر | E18: 884175 | F18: 2 | G18: 5500 | I18: =IF($B18="","",N($G18)-N($H18))
A19: =IF($B19="","",COUNTA($B$4:$B19)) | B19: 46074 | C19: نورميلا | D19: البرج | E19: 57110 | F19: 2 | G19: 5500 | I19: =IF($B19="","",N($G19)-N($H19))
A20: =IF($B20="","",COUNTA($B$4:$B20)) | B20: 46074 | C20: انترواكو | D20: القناطر | E20: 57109 | F20: 2 | G20: 5500 | I20: =IF($B20="","",N($G20)-N($H20))
A21: =IF($B21="","",COUNTA($B$4:$B21)) | B21: 46076 | C21: اورينت | D21: العبور | F21: 1 | G21: 2750 | I21: =IF($B21="","",N($G21)-N($H21))
A22: =IF($B22="","",COUNTA($B$4:$B22)) | B22: 46079 | C22: الفرسان | D22: اكتوبر | E22: 89983 | F22: 1 | G22: 2750 | I22: =IF($B22="","",N($G22)-N($H22))
A23: =IF($B23="","",COUNTA($B$4:$B23)) | B23: 46079 | H23: 30000 | I23: =IF($B23="","",N($G23)-N($H23))
A24: =IF($B24="","",COUNTA($B$4:$B24)) | B24: 46083 | C24: تومكو | D24: المنيا | E24: 279807 | F24: 1 | G24: 3750 | I24: =IF($B24="","",N($G24)-N($H24))
A25: =IF($B25="","",COUNTA($B$4:$B25)) | B25: 46089 | C25: انتراكو | D25: القناطر | E25: 9020621020 | F25: 4 | G25: 11000 | I25: =IF($B25="","",N($G25)-N($H25))
A26: =IF($B26="","",COUNTA($B$4:$B26)) | B26: 46090 | C26: الريعى | D26: الشرقية | E26: 892394 | F26: 1 | G26: 2750 | I26: =IF($B26="","",N($G26)-N($H26))
A27: =IF($B27="","",COUNTA($B$4:$B27)) | B27: 46090 | C27: المجد | D27: بلد | E27: 16111072 | F27: 1 | G27: 2750 | I27: =IF($B27="","",N($G27)-N($H27))
A28: =IF($B28="","",COUNTA($B$4:$B28)) | B28: 46093 | C28: انتراكو | D28: السادات | E28: 894052 | I28: =IF($B28="","",N($G28)-N($H28))
A29: =IF($B29="","",COUNTA($B$4:$B29)) | B29: 46093 | C29: انتراكو | D29: بنى سويف | E29: 895171 | F29: 1 | G29: 2750 | I29: =IF($B29="","",N($G29)-N($H29))
A30: =IF($B30="","",COUNTA($B$4:$B30)) | B30: 46095 | C30: الفرسان | D30: اكتوبر | E30: 894811 | F30: 1 | G30: 2750 | I30: =IF($B30="","",N($G30)-N($H30))
A31: =IF($B31="","",COUNTA($B$4:$B31)) | B31: 46097 | C31: انتراكو | D31: السادات | E31: 896107 | F31: 1 | G31: 2750 | I31: =IF($B31="","",N($G31)-N($H31))
A32: =IF($B32="","",COUNTA($B$4:$B32)) | B32: 46098 | C32: جرين لاند | D32: ك الدوار | E32: 886874 | F32: 2 | G32: 5500 | I32: =IF($B32="","",N($G32)-N($H32))
A33: =IF($B33="","",COUNTA($B$4:$B33)) | B33: 46099 | H33: 40000 | I33: =IF($B33="","",N($G33)-N($H33))
A34: =IF($B34="","",COUNTA($B$4:$B34)) | B34: 46111 | C34: انتراكو | D34: السادات | E34: 900217 | F34: 4 | G34: 11000 | I34: =IF($B34="","",N($G34)-N($H34))
A35: =IF($B35="","",COUNTA($B$4:$B35)) | B35: 46121 | C35: انتراكو | D35: السادات | E35: 900788 | F35: 4 | G35: 11000 | I35: =IF($B35="","",N($G35)-N($H35))
A36: =IF($B36="","",COUNTA($B$4:$B36)) | B36: 46121 | C36: الموندو | D36: السادات | E36: 9020717040 | F36: 1 | G36: 2750 | I36: =IF($B36="","",N($G36)-N($H36))
A37: =IF($B37="","",COUNTA($B$4:$B37)) | B37: 46128 | C37: البستانية وارد | D37: السادات | E37: 148538 | F37: 2 | G37: 5500 | I37: =IF($B37="","",N($G37)-N($H37))
A38: =IF($B38="","",COUNTA($B$4:$B38)) | B38: 46133 | H38: 40000 | I38: =IF($B38="","",N($G38)-N($H38))
A39: =IF($B39="","",COUNTA($B$4:$B39)) | B39: 46133 | C39: الفرسان | D39: اكتوبر | E39: 903929 | F39: 1 | G39: 2750 | I39: =IF($B39="","",N($G39)-N($H39))
A40: =IF($B40="","",COUNTA($B$4:$B40)) | B40: 46133 | C40: الفرسان | D40: اكتوبر | E40: 908217 | F40: 1 | G40: 2750 | I40: =IF($B40="","",N($G40)-N($H40))
...

Sheet مولدات الشجيع
A1: شركة المتوكل — مولدات الشجيع
A2: سجل نقل مولدات الشجيع
A3: م | B3: التاريخ | C3: اسم الشركة | D3: العنوان | E3: رقم الإذن | F3: عدد المولدات | G3: النولون | H3: الدفعات | I3: المتبقي
A4: =IF($B4="","",COUNTA($B$4:$B4)) | B4: 46110 | C4: انتراكوا | D4: الاسماعيلية | E4: 900222 | F4: 1 | I4: =IF($B4="","",N($G4)-N($H4))
A5: =IF($B5="","",COUNTA($B$4:$B5)) | B5: 46116 | C5: تومكو | D5: المنيا | E5: 901954 | F5: 2 | I5: =IF($B5="","",N($G5)-N($H5))
A6: =IF($B6="","",COUNTA($B$4:$B6)) | B6: 46118 | I6: =IF($B6="","",N($G6)-N($H6))
A7: =IF($B7="","",COUNTA($B$4:$B7)) | I7: =IF($B7="","",N($G7)-N($H7))
A8: =IF($B8="","",COUNTA($B$4:$B8)) | I8: =IF($B8="","",N($G8)-N($H8))
A9: =IF($B9="","",COUNTA($B$4:$B9)) | I9: =IF($B9="","",N($G9)-N($H9))
A10: =IF($B10="","",COUNTA($B$4:$B10)) | I10: =IF($B10="","",N($G10)-N($H10))
A11: =IF($B11="","",COUNTA($B$4:$B11)) | I11: =IF($B11="","",N($G11)-N($H11))
A12: =IF($B12="","",COUNTA($B$4:$B12)) | I12: =IF($B12="","",N($G12)-N($H12))
A13: =IF($B13="","",COUNTA($B$4:$B13)) | I13: =IF($B13="","",N($G13)-N($H13))
A14: =IF($B14="","",COUNTA($B$4:$B14)) | I14: =IF($B14="","",N($G14)-N($H14))
A15: =IF($B15="","",COUNTA($B$4:$B15)) | I15: =IF($B15="","",N($G15)-N($H15))
A16: =IF($B16="","",COUNTA($B$4:$B16)) | I16: =IF($B16="","",N($G16)-N($H16))
A17: =IF($B17="","",COUNTA($B$4:$B17)) | I17: =IF($B17="","",N($G17)-N($H17))
A18: =IF($B18="","",COUNTA($B$4:$B18)) | I18: =IF($B18="","",N($G18)-N($H18))
... A2203: =IF($B2203="","",COUNTA($B$4:$B2203)) | I2203: =IF($B2203="","",N($G2203)-N($H2203))
B2204: الإجماليات | F2204: =SUM($F$4:$F$2203) | G2204: =SUM($G$4:$G$2203) | H2204: =SUM($H$4:$H$2203) | I2204: =SUM($I$4:$I$2203)

Sheet شامل
A1: شركة المتوكل — شامل
A2: السجل الشامل للفواتير وحسابات العملاء
A3: مسلسل | B3: تاريخ الفاتورة | C3: رقم الكشف | D3: رقم الفاتورة | E3: رقم الإذن | F3: اسم العميل | G3: اسم الشركة | H3: الجهة | I3: عدد الحاويات | J3: النولون | K3: بيانات أو عطالات | L3: قيمة مضافة | M3: خصم أ ت ص | N3: الإيصالات | O3: إجمالي الفاتورة | P3: الدفعات | Q3: إجمالي الحساب | R3: نولون فعلي | S3: كشف وضمان | T3: مصروف | U3: إجمالي ربح | V3: ربح آخر
A4: =IF($B4="","",COUNTA($B$4:$B4)) | L4: =IF($B4="","",ROUND((N($J4)+N($K4))*نسبة_القيمة_المضافة,2)) | O4: =IF($B4="","",N($J4)+N($K4)+N($L4)-N($M4)+N($N4)) | Q4: =IF($B4="","",N($O4)-N($P4)) | U4: =IF($B4="","",N($J4)-N($R4)-N($T4))
A5: =IF($B5="","",COUNTA($B$4:$B5)) | L5: =IF($B5="","",ROUND((N($J5)+N($K5))*نسبة_القيمة_المضافة,2)) | O5: =IF($B5="","",N($J5)+N($K5)+N($L5)-N($M5)+N($N5)) | Q5: =IF($B5="","",N($O5)-N($P5)) | U5: =IF($B5="","",N($J5)-N($R5)-N($T5))
A6: =IF($B6="","",COUNTA($B$4:$B6)) | L6: =IF($B6="","",ROUND((N($J6)+N($K6))*نسبة_القيمة_المضافة,2)) | O6: =IF($B6="","",N($J6)+N($K6)+N($L6)-N($M6)+N($N6)) | Q6: =IF($B6="","",N($O6)-N($P6)) | U6: =IF($B6="","",N($J6)-N($R6)-N($T6))
A7: =IF($B7="","",COUNTA($B$4:$B7)) | L7: =IF($B7="","",ROUND((N($J7)+N($K7))*نسبة_القيمة_المضافة,2)) | O7: =IF($B7="","",N($J7)+N($K7)+N($L7)-N($M7)+N($N7)) | Q7: =IF($B7="","",N($O7)-N($P7)) | U7: =IF($B7="","",N($J7)-N($R7)-N($T7))
A8: =IF($B8="","",COUNTA($B$4:$B8)) | L8: =IF($B8="","",ROUND((N($J8)+N($K8))*نسبة_القيمة_المضافة,2)) | O8: =IF($B8="","",N($J8)+N($K8)+N($L8)-N($M8)+N($N8)) | Q8: =IF($B8="","",N($O8)-N($P8)) | U8: =IF($B8="","",N($J8)-N($R8)-N($T8))
A9: =IF($B9="","",COUNTA($B$4:$B9)) | L9: =IF($B9="","",ROUND((N($J9)+N($K9))*نسبة_القيمة_المضافة,2)) | O9: =IF($B9="","",N($J9)+N($K9)+N($L9)-N($M9)+N($N9)) | Q9: =IF($B9="","",N($O9)-N($P9)) | U9: =IF($B9="","",N($J9)-N($R9)-N($T9))
A10: =IF($B10="","",COUNTA($B$4:$B10)) | L10: =IF($B10="","",ROUND((N($J10)+N($K10))*نسبة_القيمة_المضافة,2)) | O10: =IF($B10="","",N($J10)+N($K10)+N($L10)-N($M10)+N($N10)) | Q10: =IF($B10="","",N($O10)-N($P10)) | U10: =IF($B10="","",N($J10)-N($R10)-N($T10))
A11: =IF($B11="","",COUNTA($B$4:$B11)) | L11: =IF($B11="","",ROUND((N($J11)+N($K11))*نسبة_القيمة_المضافة,2)) | O11: =IF($B11="","",N($J11)+N($K11)+N($L11)-N($M11)+N($N11)) | Q11: =IF($B11="","",N($O11)-N($P11)) | U11: =IF($B11="","",N($J11)-N($R11)-N($T11))
A12: =IF($B12="","",COUNTA($B$4:$B12)) | L12: =IF($B12="","",ROUND((N($J12)+N($K12))*نسبة_القيمة_المضافة,2)) | O12: =IF($B12="","",N($J12)+N($K12)+N($L12)-N($M12)+N($N12)) | Q12: =IF($B12="","",N($O12)-N($P12)) | U12: =IF($B12="","",N($J12)-N($R12)-N($T12))
A13: =IF($B13="","",COUNTA($B$4:$B13)) | L13: =IF($B13="","",ROUND((N($J13)+N($K13))*نسبة_القيمة_المضافة,2)) | O13: =IF($B13="","",N($J13)+N($K13)+N($L13)-N($M13)+N($N13)) | Q13: =IF($B13="","",N($O13)-N($P13)) | U13: =IF($B13="","",N($J13)-N($R13)-N($T13))
A14: =IF($B14="","",COUNTA($B$4:$B14)) | L14: =IF($B14="","",ROUND((N($J14)+N($K14))*نسبة_القيمة_المضافة,2)) | O14: =IF($B14="","",N($J14)+N($K14)+N($L14)-N($M14)+N($N14)) | Q14: =IF($B14="","",N($O14)-N($P14)) | U14: =IF($B14="","",N($J14)-N($R14)-N($T14))
A15: =IF($B15="","",COUNTA($B$4:$B15)) | L15: =IF($B15="","",ROUND((N($J15)+N($K15))*نسبة_القيمة_المضافة,2)) | O15: =IF($B15="","",N($J15)+N($K15)+N($L15)-N($M15)+N($N15)) | Q15: =IF($B15="","",N($O15)-N($P15)) | U15: =IF($B15="","",N($J15)-N($R15)-N($T15))
... A2203: =IF($B2203="","",COUNTA($B$4:$B2203)) | L2203: =IF($B2203="","",ROUND((N($J2203)+N($K2203))*نسبة_القيمة_المضافة,2)) | O2203: =IF($B2203="","",N($J2203)+N($K2203)+N($L2203)-N($M2203)+N($N2203)) | Q2203: =IF($B2203="","",N($O2203)-N($P2203)) | U2203: =IF($B2203="","",N($J2203)-N($R2203)-N($T2203))
B2204: الإجماليات | I2204: =SUM($I$4:$I$2203) | J2204: =SUM($J$4:$J$2203) | K2204: =SUM($K$4:$K$2203) | L2204: =SUM($L$4:$L$2203) | M2204: =SUM($M$4:$M$2203) | N2204: =SUM($N$4:$N$2203) | O2204: =SUM($O$4:$O$2203) | P2204: =SUM($P$4:$P$2203) | Q2204: =SUM($Q$4:$Q$2203) | R2204: =SUM($R$4:$R$2203) | S2204: =SUM($S$4:$S$2203) | T2204: =SUM($T$4:$T$2203) | U2204: =SUM($U$4:$U$2203) | V2204: =SUM($V$4:$V$2203)

Sheet أرصدة العملاء والموردين
A1: شركة المتوكل — أرصدة العملاء والموردين
A2: كشف حساب العملاء والموردين — المنقول من النظام القديم
B3: العميل | C3: الرصيد (له) | E3: المورد | F3: الرصيد (عليه)
B4: فاطمة | E4: طارق | F4: 500000
B5: عرب اوشن | E5: احمد عليمي | F5: 20000
B6: سيجل | E6: احمد ظريف | F6: 10000
B7: صلاح | E7: احمد عادل | F7: 15000
B8: علاء جمعة | E8: مكتب | F8: 54000
B9: فيرتكس | E9: بوالص | F9: 3469000
B10: احمد سنبل | E10: vito
B11: الفؤاد | E11: مولدات
B12: احمد عبدالله
B13: الشيخ حسن
B14: وورلد
B15: نيو ترند
B16: اسلام
B17: اوفرسيز.
B18: kz
B19: البغدادية
B20: اسماء خليفة
B21: يونايتد
B22: كومباكت
B23: اكما
... B50: بيردس
B204: إجمالي أرصدة العملاء | C204: =SUM(C4:C203) | E204: إجمالي أرصدة الموردين | F204: =SUM(F4:F203)
E205: الفرق (له − عليه) | F205: =C204-F204

Sheet التقارير
A1: شركة المتوكل — التقارير المالية والإدارية
A2: تقارير جاهزة للطباعة — تُحدَّث تلقائياً
B3: الملخص المالي العام
B4: إجمالي الإيرادات | C4: =SUM('البوالص'!$L$4:$L$2203)+SUM('شامل'!$O$4:$O$2203)+SUM('التخليص'!$G$4:$G$2203)+SUM('مولدات ايجي كول'!$G$4:$G$2203)+SUM('مولدات الشجيع'!$G$4:$G$2203) | E4: إجمالي المتحصّلات | F4: =SUM('البوالص'!$Q$4:$Q$2203)+SUM('شامل'!$P$4:$P$2203)+SUM('التخليص'!$H$4:$H$2203)+SUM('مولدات ايجي كول'!$H$4:$H$2203)+SUM('مولدات الشجيع'!$H$4:$H$2203)
B5: إجمالي المصروفات | C5: =SUM('البوالص'!$AF$4:$AF$2203)+SUM('شامل'!$T$4:$T$2203)+SUM('التخليص'!$F$4:$F$2203) | E5: المتبقي على العملاء | F5: =SUM('البوالص'!$R$4:$R$2203)+SUM('شامل'!$Q$4:$Q$2203)+SUM('التخليص'!$I$4:$I$2203)+SUM('مولدات ايجي كول'!$I$4:$I$2203)+SUM('مولدات الشجيع'!$I$4:$I$2203)
B6: صافي الأرباح | C6: =SUM('شامل'!$U$4:$U$2203)+SUM('شامل'!$V$4:$V$2203)+SUM('البوالص'!$AH$4:$AH$2203) | E6: إجمالي النولون | F6: =SUM('البوالص'!$L$4:$L$2203)+SUM('شامل'!$J$4:$J$2203)+SUM('مولدات ايجي كول'!$G$4:$G$2203)+SUM('مولدات الشجيع'!$G$4:$G$2203)
E7: هامش الربح % | F7: =IF((SUM('البوالص'!$L$4:$L$2203)+SUM('شامل'!$O$4:$O$2203)+SUM('التخليص'!$G$4:$G$2203)+SUM('مولدات ايجي كول'!$G$4:$G$2203)+SUM('مولدات الشجيع'!$G$4:$G$2203))=0,"",(SUM('شامل'!$U$4:$U$2203)+SUM('شامل'!$V$4:$V$2203)+SUM('البوالص'!$AH$4:$AH$2203))/(SUM('البوالص'!$L$4:$L$2203)+SUM('شامل'!$O$4:$O$2203)+SUM('التخليص'!$G$4:$G$2203)+SUM('مولدات ايجي كول'!$G$4:$G$2203)+SUM('مولدات الشجيع'!$G$4:$G$2203)))
B9: الأداء الشهري | H9: الربح حسب الشركة
B10: الشهر | C10: الإيرادات | D10: المصروفات | E10: صافي الربح | F10: المتحصّلات | H10: الشركة | I10: النولون | J10: صافي الربح
B11: ='بيانات_التقارير'!B4 | C11: ='بيانات_التقارير'!C4 | D11: ='بيانات_التقارير'!D4 | E11: ='بيانات_التقارير'!E4 | F11: ='بيانات_التقارير'!F4 | H11: ='بيانات_التقارير'!H4 | I11: ='بيانات_التقارير'!I4 | J11: ='بيانات_التقارير'!J4
B12: ='بيانات_التقارير'!B5 | C12: ='بيانات_التقارير'!C5 | D12: ='بيانات_التقارير'!D5 | E12: ='بيانات_التقارير'!E5 | F12: ='بيانات_التقارير'!F5 | H12: ='بيانات_التقارير'!H5 | I12: ='بيانات_التقارير'!I5 | J12: ='بيانات_التقارير'!J5
B13: ='بيانات_التقارير'!B6 | C13: ='بيانات_التقارير'!C6 | D13: ='بيانات_التقارير'!D6 | E13: ='بيانات_التقارير'!E6 | F13: ='بيانات_التقارير'!F6 | H13: ='بيانات_التقارير'!H6 | I13: ='بيانات_التقارير'!I6 | J13: ='بيانات_التقارير'!J6
B14: ='بيانات_التقارير'!B7 | C14: ='بيانات_التقارير'!C7 | D14: ='بيانات_التقارير'!D7 | E14: ='بيانات_التقارير'!E7 | F14: ='بيانات_التقارير'!F7 | H14: ='بيانات_التقارير'!H7 | I14: ='بيانات_التقارير'!I7 | J14: ='بيانات_التقارير'!J7
B15: ='بيانات_التقارير'!B8 | C15: ='بيانات_التقارير'!C8 | D15: ='بيانات_التقارير'!D8 | E15: ='بيانات_التقارير'!E8 | F15: ='بيانات_التقارير'!F8 | H15: ='بيانات_التقارير'!H8 | I15: ='بيانات_التقارير'!I8 | J15: ='بيانات_التقارير'!J8
B16: ='بيانات_التقارير'!B9 | C16: ='بيانات_التقارير'!C9 | D16: ='بيانات_التقارير'!D9 | E16: ='بيانات_التقارير'!E9 | F16: ='بيانات_التقارير'!F9 | H16: ='بيانات_التقارير'!H9 | I16: ='بيانات_التقارير'!I9 | J16: ='بيانات_التقارير'!J9
B17: ='بيانات_التقارير'!B10 | C17: ='بيانات_التقارير'!C10 | D17: ='بيانات_التقارير'!D10 | E17: ='بيانات_التقارير'!E10 | F17: ='بيانات_التقارير'!F10 | H17: ='بيانات_التقارير'!H10 | I17: ='بيانات_التقارير'!I10 | J17: ='بيانات_التقارير'!J10
B18: ='بيانات_التقارير'!B11 | C18: ='بيانات_التقارير'!C11 | D18: ='بيانات_التقارير'!D11 | E18: ='بيانات_التقارير'!E11 | F18: ='بيانات_التقارير'!F11 | H18: ='بيانات_التقارير'!H11 | I18: ='بيانات_التقارير'!I11 | J18: ='بيانات_التقارير'!J11
B19: ='بيانات_التقارير'!B12 | C19: ='بيانات_التقارير'!C12 | D19: ='بيانات_التقارير'!D12 | E19: ='بيانات_التقارير'!E12 | F19: ='بيانات_التقارير'!F12 | H19: ='بيانات_التقارير'!H12 | I19: ='بيانات_التقارير'!I12 | J19: ='بيانات_التقارير'!J12
B20: ='بيانات_التقارير'!B13 | C20: ='بيانات_التقارير'!C13 | D20: ='بيانات_التقارير'!D13 | E20: ='بيانات_التقارير'!E13 | F20: ='بيانات_التقارير'!F13 | H20: ='بيانات_التقارير'!H13 | I20: ='بيانات_التقارير'!I13 | J20: ='بيانات_التقارير'!J13
B21: ='بيانات_التقارير'!B14 | C21: ='بيانات_التقارير'!C14 | D21: ='بيانات_التقارير'!D14 | E21: ='بيانات_التقارير'!E14 | F21: ='بيانات_التقارير'!F14 | H21: ='بيانات_التقارير'!H14 | I21: ='بيانات_التقارير'!I14 | J21: ='بيانات_التقارير'!J14
B22: ='بيانات_التقارير'!B15 | C22: ='بيانات_التقارير'!C15 | D22: ='بيانات_التقارير'!D15 | E22: ='بيانات_التقارير'!E15 | F22: ='بيانات_التقارير'!F15 | H22: ='بيانات_التقارير'!H15 | I22: ='بيانات_التقارير'!I15 | J22: ='بيانات_التقارير'!J15
B23: الإجمالي السنوي | C23: =SUM('بيانات_التقارير'!C4:C15) | D23: =SUM('بيانات_التقارير'!D4:D15) | E23: =SUM('بيانات_التقارير'!E4:E15) | F23: =SUM('بيانات_التقارير'!F4:F15) | H23: ='بيانات_التقارير'!H16 | I23: ='بيانات_التقارير'!I16 | J23: ='بيانات_التقارير'!J16
H24: ='بيانات_التقارير'!H17 | I24: ='بيانات_التقارير'!I17 | J24: ='بيانات_التقارير'!J17
H25: ='بيانات_التقارير'!H18 | I25: ='بيانات_التقارير'!I18 | J25: ='بيانات_التقارير'!J18
B26: مديونية العملاء (المتأخرات)
B27: العميل | C27: إجمالي الفواتير | D27: المتبقي عليه
B28: ='بيانات_التقارير'!L4 | C28: ='بيانات_التقارير'!M4 | D28: ='بيانات_التقارير'!N4
B29: ='بيانات_التقارير'!L5 | C29: ='بيانات_التقارير'!M5 | D29: ='بيانات_التقارير'!N5
B30: ='بيانات_التقارير'!L6 | C30: ='بيانات_التقارير'!M6 | D30: ='بيانات_التقارير'!N6
B31: ='بيانات_التقارير'!L7 | C31: ='بيانات_التقارير'!M7 | D31: ='بيانات_التقارير'!N7
B32: ='بيانات_التقارير'!L8 | C32: ='بيانات_التقارير'!M8 | D32: ='بيانات_التقارير'!N8
B33: ='بيانات_التقارير'!L9 | C33: ='بيانات_التقارير'!M9 | D33: ='بيانات_التقارير'!N9
B34: ='بيانات_التقارير'!L10 | C34: ='بيانات_التقارير'!M10 | D34: ='بيانات_التقارير'!N10
B35: ='بيانات_التقارير'!L11 | C35: ='بيانات_التقارير'!M11 | D35: ='بيانات_التقارير'!N11
B36: ='بيانات_التقارير'!L12 | C36: ='بيانات_التقارير'!M12 | D36: ='بيانات_التقارير'!N12
B37: ='بيانات_التقارير'!L13 | C37: ='بيانات_التقارير'!M13 | D37: ='بيانات_التقارير'!N13
B38: ='بيانات_التقارير'!L14 | C38: ='بيانات_التقارير'!M14 | D38: ='بيانات_التقارير'!N14
B39: ='بيانات_التقارير'!L15 | C39: ='بيانات_التقارير'!M15 | D39: ='بيانات_التقارير'!N15
... B42: ='بيانات_التقارير'!L18 | C42: ='بيانات_التقارير'!M18 | D42: ='بيانات_التقارير'!N18

Sheet بيانات_التقارير
A1: شركة المتوكل — بيانات التقارير (تُحدَّث تلقائياً)
A2: لا تُعدّل هذه الصفحة يدوياً — تُغذّي لوحة التحكم والرسوم
A3: تاريخ | B3: الشهر | C3: الإيرادات | D3: المصروفات | E3: صافي الربح | F3: المتحصّلات | H3: الشركة | I3: النولون | J3: صافي الربح | L3: العميل | M3: إجمالي الفواتير | N3: المتبقي عليه | P3: بند المصروف | Q3: الإجمالي | S3: جهة المولدات | T3: إجمالي النولون | V3: المورد | W3: الرصيد
A4: =DATE(سنة_التقارير,1,1) | B4: يناير | C4: =SUMIFS('البوالص'!$L$4:$L$2203,'البوالص'!$B$4:$B$2203,">="&$A4,'البوالص'!$B$4:$B$2203,"<"&EDATE($A4,1))+SUMIFS('شامل'!$O$4:$O$2203,'شامل'!$B$4:$B$2203,">="&$A4,'شامل'!$B$4:$B$2203,"<"&EDATE($A4,1))+SUMIFS('التخليص'!$G$4:$G$2203,'التخليص'!$B$4:$B$2203,">="&$A4,'التخليص'!$B$4:$B$2203,"<"&EDATE($A4,1))+SUMIFS('مولدات ايجي كول'!$G$4:$G$2203,'مولدات ايجي كول'!$B$4:$B$2203,">="&$A4,'مولدات ايجي كول'!$B$4:$B$2203,"<"&EDATE($A4,1))+SUMIFS('مولدات الشجيع'!$G$4:$G$2203,'مولدات الشجيع'!$B$4:$B$2203,">="&$A4,'مولدات الشجيع'!$B$4:$B$2203,"<"&EDATE($A4,1)) | D4: =SUMIFS('البوالص'!$AF$4:$AF$2203,'البوالص'!$B$4:$B$2203,">="&$A4,'البوالص'!$B$4:$B$2203,"<"&EDATE($A4,1))+SUMIFS('شامل'!$T$4:$T$2203,'شامل'!$B$4:$B$2203,">="&$A4,'شامل'!$B$4:$B$2203,"<"&EDATE($A4,1))+SUMIFS('التخليص'!$F$4:$F$2203,'التخليص'!$B$4:$B$2203,">="&$A4,'التخليص'!$B$4:$B$2203,"<"&EDATE($A4,1)) | E4: =SUMIFS('شامل'!$U$4:$U$2203,'شامل'!$B$4:$B$2203,">="&$A4,'شامل'!$B$4:$B$2203,"<"&EDATE($A4,1))+SUMIFS('شامل'!$V$4:$V$2203,'شامل'!$B$4:$B$2203,">="&$A4,'شامل'!$B$4:$B$2203,"<"&EDATE($A4,1))+SUMIFS('البوالص'!$AH$4:$AH$2203,'البوالص'!$B$4:$B$2203,">="&$A4,'البوالص'!$B$4:$B$2203,"<"&EDATE($A4,1)) | F4: =SUMIFS('البوالص'!$Q$4:$Q$2203,'البوالص'!$B$4:$B$2203,">="&$A4,'البوالص'!$B$4:$B$2203,"<"&EDATE($A4,1))+SUMIFS('شامل'!$P$4:$P$2203,'شامل'!$B$4:$B$2203,">="&$A4,'شامل'!$B$4:$B$2203,"<"&EDATE($A4,1))+SUMIFS('التخليص'!$H$4:$H$2203,'التخليص'!$B$4:$B$2203,">="&$A4,'التخليص'!$B$4:$B$2203,"<"&EDATE($A4,1))+SUMIFS('مولدات ايجي كول'!$H$4:$H$2203,'مولدات ايجي كول'!$B$4:$B$2203,">="&$A4,'مولدات ايجي كول'!$B$4:$B$2203,"<"&EDATE($A4,1))+SUMIFS('مولدات الشجيع'!$H$4:$H$2203,'مولدات الشجيع'!$B$4:$B$2203,">="&$A4,'مولدات الشجيع'!$B$4:$B$2203,"<"&EDATE($A4,1)) | H4: =IF(الإعدادات!$E4="","",الإعدادات!$E4) | I4: =SUMIF('البوالص'!$F$4:$F$2203,الإعدادات!$E4,'البوالص'!$L$4:$L$2203)+SUMIF('شامل'!$G$4:$G$2203,الإعدادات!$E4,'شامل'!$J$4:$J$2203) | J4: =SUMIF('البوالص'!$F$4:$F$2203,الإعدادات!$E4,'البوالص'!$AH$4:$AH$2203)+SUMIF('شامل'!$G$4:$G$2203,الإعدادات!$E4,'شامل'!$U$4:$U$2203) | L4: =IF(الإعدادات!$I4="","",الإعدادات!$I4) | M4: =SUMIF('شامل'!$F$4:$F$2203,الإعدادات!$I4,'شامل'!$O$4:$O$2203) | N4: =SUMIF('شامل'!$F$4:$F$2203,الإعدادات!$I4,'شامل'!$Q$4:$Q$2203) | P4: دور سواق | Q4: =SUM('البوالص'!$T$4:$T$2203) | S4: ايجي كول | T4: =SUM('مولدات ايجي كول'!$G$4:$G$2203) | V4: =IF('أرصدة العملاء والموردين'!E4="","",'أرصدة العملاء والموردين'!E4) | W4: ='أرصدة العملاء والموردين'!F4
A5: =DATE(سنة_التقارير,2,1) | B5: فبراير | C5: =SUMIFS('البوالص'!$L$4:$L$2203,'البوالص'!$B$4:$B$2203,">="&$A5,'البوالص'!$B$4:$B$2203,"<"&EDATE($A5,1))+SUMIFS('شامل'!$O$4:$O$2203,'شامل'!$B$4:$B$2203,">="&$A5,'شامل'!$B$4:$B$2203,"<"&EDATE($A5,1))+SUMIFS('التخليص'!$G$4:$G$2203,'التخليص'!$B$4:$B$2203,">="&$A5,'التخليص'!$B$4:$B$2203,"<"&EDATE($A5,1))+SUMIFS('مولدات ايجي كول'!$G$4:$G$2203,'مولدات ايجي كول'!$B$4:$B$2203,">="&$A5,'مولدات ايجي كول'!$B$4:$B$2203,"<"&EDATE($A5,1))+SUMIFS('مولدات الشجيع'!$G$4:$G$2203,'مولدات الشجيع'!$B$4:$B$2203,">="&$A5,'مولدات الشجيع'!$B$4:$B$2203,"<"&EDATE($A5,1)) | D5: =SUMIFS('البوالص'!$AF$4:$AF$2203,'البوالص'!$B$4:$B$2203,">="&$A5,'البوالص'!$B$4:$B$2203,"<"&EDATE($A5,1))+SUMIFS('شامل'!$T$4:$T$2203,'شامل'!$B$4:$B$2203,">="&$A5,'شامل'!$B$4:$B$2203,"<"&EDATE($A5,1))+SUMIFS('التخليص'!$F$4:$F$2203,'التخليص'!$B$4:$B$2203,">="&$A5,'التخليص'!$B$4:$B$2203,"<"&EDATE($A5,1)) | E5: =SUMIFS('شامل'!$U$4:$U$2203,'شامل'!$B$4:$B$2203,">="&$A5,'شامل'!$B$4:$B$2203,"<"&EDATE($A5,1))+SUMIFS('شامل'!$V$4:$V$2203,'شامل'!$B$4:$B$2203,">="&$A5,'شامل'!$B$4:$B$2203,"<"&EDATE($A5,1))+SUMIFS('البوالص'!$AH$4:$AH$2203,'البوالص'!$B$4:$B$2203,">="&$A5,'البوالص'!$B$4:$B$2203,"<"&EDATE($A5,1)) | F5: =SUMIFS('البوالص'!$Q$4:$Q$2203,'البوالص'!$B$4:$B$2203,">="&$A5,'البوالص'!$B$4:$B$2203,"<"&EDATE($A5,1))+SUMIFS('شامل'!$P$4:$P$2203,'شامل'!$B$4:$B$2203,">="&$A5,'شامل'!$B$4:$B$2203,"<"&EDATE($A5,1))+SUMIFS('التخليص'!$H$4:$H$2203,'التخليص'!$B$4:$B$2203,">="&$A5,'التخليص'!$B$4:$B$2203,"<"&EDATE($A5,1))+SUMIFS('مولدات ايجي كول'!$H$4:$H$2203,'مولدات ايجي كول'!$B$4:$B$2203,">="&$A5,'مولدات ايجي كول'!$B$4:$B$2203,"<"&EDATE($A5,1))+SUMIFS('مولدات الشجيع'!$H$4:$H$2203,'مولدات الشجيع'!$B$4:$B$2203,">="&$A5,'مولدات الشجيع'!$B$4:$B$2203,"<"&EDATE($A5,1)) | H5: =IF(الإعدادات!$E5="","",الإعدادات!$E5) | I5: =SUMIF('البوالص'!$F$4:$F$2203,الإعدادات!$E5,'البوالص'!$L$4:$L$2203)+SUMIF('شامل'!$G$4:$G$2203,الإعدادات!$E5,'شامل'!$J$4:$J$2203) | J5: =SUMIF('البوالص'!$F$4:$F$2203,الإعدادات!$E5,'البوالص'!$AH$4:$AH$2203)+SUMIF('شامل'!$G$4:$G$2203,الإعدادات!$E5,'شامل'!$U$4:$U$2203) | L5: =IF(الإعدادات!$I5="","",الإعدادات!$I5) | M5: =SUMIF('شامل'!$F$4:$F$2203,الإعدادات!$I5,'شامل'!$O$4:$O$2203) | N5: =SUMIF('شامل'!$F$4:$F$2203,الإعدادات!$I5,'شامل'!$Q$4:$Q$2203) | P5: دور تبّاع | Q5: =SUM('البوالص'!$U$4:$U$2203) | S5: الشجيع | T5: =SUM('مولدات الشجيع'!$G$4:$G$2203) | V5: =IF('أرصدة العملاء والموردين'!E5="","",'أرصدة العملاء والموردين'!E5) | W5: ='أرصدة العملاء والموردين'!F5
A6: =DATE(سنة_التقارير,3,1) | B6: مارس | C6: =SUMIFS('البوالص'!$L$4:$L$2203,'البوالص'!$B$4:$B$2203,">="&$A6,'البوالص'!$B$4:$B$2203,"<"&EDATE($A6,1))+SUMIFS('شامل'!$O$4:$O$2203,'شامل'!$B$4:$B$2203,">="&$A6,'شامل'!$B$4:$B$2203,"<"&EDATE($A6,1))+SUMIFS('التخليص'!$G$4:$G$2203,'التخليص'!$B$4:$B$2203,">="&$A6,'التخليص'!$B$4:$B$2203,"<"&EDATE($A6,1))+SUMIFS('مولدات ايجي كول'!$G$4:$G$2203,'مولدات ايجي كول'!$B$4:$B$2203,">="&$A6,'مولدات ايجي كول'!$B$4:$B$2203,"<"&EDATE($A6,1))+SUMIFS('مولدات الشجيع'!$G$4:$G$2203,'مولدات الشجيع'!$B$4:$B$2203,">="&$A6,'مولدات الشجيع'!$B$4:$B$2203,"<"&EDATE($A6,1)) | D6: =SUMIFS('البوالص'!$AF$4:$AF$2203,'البوالص'!$B$4:$B$2203,">="&$A6,'البوالص'!$B$4:$B$2203,"<"&EDATE($A6,1))+SUMIFS('شامل'!$T$4:$T$2203,'شامل'!$B$4:$B$2203,">="&$A6,'شامل'!$B$4:$B$2203,"<"&EDATE($A6,1))+SUMIFS('التخليص'!$F$4:$F$2203,'التخليص'!$B$4:$B$2203,">="&$A6,'التخليص'!$B$4:$B$2203,"<"&EDATE($A6,1)) | E6: =SUMIFS('شامل'!$U$4:$U$2203,'شامل'!$B$4:$B$2203,">="&$A6,'شامل'!$B$4:$B$2203,"<"&EDATE($A6,1))+SUMIFS('شامل'!$V$4:$V$2203,'شامل'!$B$4:$B$2203,">="&$A6,'شامل'!$B$4:$B$2203,"<"&EDATE($A6,1))+SUMIFS('البوالص'!$AH$4:$AH$2203,'البوالص'!$B$4:$B$2203,">="&$A6,'البوالص'!$B$4:$B$2203,"<"&EDATE($A6,1)) | F6: =SUMIFS('البوالص'!$Q$4:$Q$2203,'البوالص'!$B$4:$B$2203,">="&$A6,'البوالص'!$B$4:$B$2203,"<"&EDATE($A6,1))+SUMIFS('شامل'!$P$4:$P$2203,'شامل'!$B$4:$B$2203,">="&$A6,'شامل'!$B$4:$B$2203,"<"&EDATE($A6,1))+SUMIFS('التخليص'!$H$4:$H$2203,'التخليص'!$B$4:$B$2203,">="&$A6,'التخليص'!$B$4:$B$2203,"<"&EDATE($A6,1))+SUMIFS('مولدات ايجي كول'!$H$4:$H$2203,'مولدات ايجي كول'!$B$4:$B$2203,">="&$A6,'مولدات ايجي كول'!$B$4:$B$2203,"<"&EDATE($A6,1))+SUMIFS('مولدات الشجيع'!$H$4:$H$2203,'مولدات الشجيع'!$B$4:$B$2203,">="&$A6,'مولدات الشجيع'!$B$4:$B$2203,"<"&EDATE($A6,1)) | H6: =IF(الإعدادات!$E6="","",الإعدادات!$E6) | I6: =SUMIF('البوالص'!$F$4:$F$2203,الإعدادات!$E6,'البوالص'!$L$4:$L$2203)+SUMIF('شامل'!$G$4:$G$2203,الإعدادات!$E6,'شامل'!$J$4:$J$2203) | J6: =SUMIF('البوالص'!$F$4:$F$2203,الإعدادات!$E6,'البوالص'!$AH$4:$AH$2203)+SUMIF('شامل'!$G$4:$G$2203,الإعدادات!$E6,'شامل'!$U$4:$U$2203) | L6: =IF(الإعدادات!$I6="","",الإعدادات!$I6) | M6: =SUMIF('شامل'!$F$4:$F$2203,الإعدادات!$I6,'شامل'!$O$4:$O$2203) | N6: =SUMIF('شامل'!$F$4:$F$2203,الإعدادات!$I6,'شامل'!$Q$4:$Q$2203) | P6: بياتة (مصروف) | Q6: =SUM('البوالص'!$V$4:$V$2203) | V6: =IF('أرصدة العملاء والموردين'!E6="","",'أرصدة العملاء والموردين'!E6) | W6: ='أرصدة العملاء والموردين'!F6
A7: =DATE(سنة_التقارير,4,1) | B7: أبريل | C7: =SUMIFS('البوالص'!$L$4:$L$2203,'البوالص'!$B$4:$B$2203,">="&$A7,'البوالص'!$B$4:$B$2203,"<"&EDATE($A7,1))+SUMIFS('شامل'!$O$4:$O$2203,'شامل'!$B$4:$B$2203,">="&$A7,'شامل'!$B$4:$B$2203,"<"&EDATE($A7,1))+SUMIFS('التخليص'!$G$4:$G$2203,'التخليص'!$B$4:$B$2203,">="&$A7,'التخليص'!$B$4:$B$2203,"<"&EDATE($A7,1))+SUMIFS('مولدات ايجي كول'!$G$4:$G$2203,'مولدات ايجي كول'!$B$4:$B$2203,">="&$A7,'مولدات ايجي كول'!$B$4:$B$2203,"<"&EDATE($A7,1))+SUMIFS('مولدات الشجيع'!$G$4:$G$2203,'مولدات الشجيع'!$B$4:$B$2203,">="&$A7,'مولدات الشجيع'!$B$4:$B$2203,"<"&EDATE($A7,1)) | D7: =SUMIFS('البوالص'!$AF$4:$AF$2203,'البوالص'!$B$4:$B$2203,">="&$A7,'البوالص'!$B$4:$B$2203,"<"&EDATE($A7,1))+SUMIFS('شامل'!$T$4:$T$2203,'شامل'!$B$4:$B$2203,">="&$A7,'شامل'!$B$4:$B$2203,"<"&EDATE($A7,1))+SUMIFS('التخليص'!$F$4:$F$2203,'التخليص'!$B$4:$B$2203,">="&$A7,'التخليص'!$B$4:$B$2203,"<"&EDATE($A7,1)) | E7: =SUMIFS('شامل'!$U$4:$U$2203,'شامل'!$B$4:$B$2203,">="&$A7,'شامل'!$B$4:$B$2203,"<"&EDATE($A7,1))+SUMIFS('شامل'!$V$4:$V$2203,'شامل'!$B$4:$B$2203,">="&$A7,'شامل'!$B$4:$B$2203,"<"&EDATE($A7,1))+SUMIFS('البوالص'!$AH$4:$AH$2203,'البوالص'!$B$4:$B$2203,">="&$A7,'البوالص'!$B$4:$B$2203,"<"&EDATE($A7,1)) | F7: =SUMIFS('البوالص'!$Q$4:$Q$2203,'البوالص'!$B$4:$B$2203,">="&$A7,'البوالص'!$B$4:$B$2203,"<"&EDATE($A7,1))+SUMIFS('شامل'!$P$4:$P$2203,'شامل'!$B$4:$B$2203,">="&$A7,'شامل'!$B$4:$B$2203,"<"&EDATE($A7,1))+SUMIFS('التخليص'!$H$4:$H$2203,'التخليص'!$B$4:$B$2203,">="&$A7,'التخليص'!$B$4:$B$2203,"<"&EDATE($A7,1))+SUMIFS('مولدات ايجي كول'!$H$4:$H$2203,'مولدات ايجي كول'!$B$4:$B$2203,">="&$A7,'مولدات ايجي كول'!$B$4:$B$2203,"<"&EDATE($A7,1))+SUMIFS('مولدات الشجيع'!$H$4:$H$2203,'مولدات الشجيع'!$B$4:$B$2203,">="&$A7,'مولدات الشجيع'!$B$4:$B$2203,"<"&EDATE($A7,1)) | H7: =IF(الإعدادات!$E7="","",الإعدادات!$E7) | I7: =SUMIF('البوالص'!$F$4:$F$2203,الإعدادات!$E7,'البوالص'!$L$4:$L$2203)+SUMIF('شامل'!$G$4:$G$2203,الإعدادات!$E7,'شامل'!$J$4:$J$2203) | J7: =SUMIF('البوالص'!$F$4:$F$2203,الإعدادات!$E7,'البوالص'!$AH$4:$AH$2203)+SUMIF('شامل'!$G$4:$G$2203,الإعدادات!$E7,'شامل'!$U$4:$U$2203) | L7: =IF(الإعدادات!$I7="","",الإعدادات!$I7) | M7: =SUMIF('شامل'!$F$4:$F$2203,الإعدادات!$I7,'شامل'!$O$4:$O$2203) | N7: =SUMIF('شامل'!$F$4:$F$2203,الإعدادات!$I7,'شامل'!$Q$4:$Q$2203) | P7: مصروف | Q7: =SUM('البوالص'!$W$4:$W$2203) | V7: =IF('أرصدة العملاء والموردين'!E7="","",'أرصدة العملاء والموردين'!E7) | W7: ='أرصدة العملاء والموردين'!F7
A8: =DATE(سنة_التقارير,5,1) | B8: مايو | C8: =SUMIFS('البوالص'!$L$4:$L$2203,'البوالص'!$B$4:$B$2203,">="&$A8,'البوالص'!$B$4:$B$2203,"<"&EDATE($A8,1))+SUMIFS('شامل'!$O$4:$O$2203,'شامل'!$B$4:$B$2203,">="&$A8,'شامل'!$B$4:$B$2203,"<"&EDATE($A8,1))+SUMIFS('التخليص'!$G$4:$G$2203,'التخليص'!$B$4:$B$2203,">="&$A8,'التخليص'!$B$4:$B$2203,"<"&EDATE($A8,1))+SUMIFS('مولدات ايجي كول'!$G$4:$G$2203,'مولدات ايجي كول'!$B$4:$B$2203,">="&$A8,'مولدات ايجي كول'!$B$4:$B$2203,"<"&EDATE($A8,1))+SUMIFS('مولدات الشجيع'!$G$4:$G$2203,'مولدات الشجيع'!$B$4:$B$2203,">="&$A8,'مولدات الشجيع'!$B$4:$B$2203,"<"&EDATE($A8,1)) | D8: =SUMIFS('البوالص'!$AF$4:$AF$2203,'البوالص'!$B$4:$B$2203,">="&$A8,'البوالص'!$B$4:$B$2203,"<"&EDATE($A8,1))+SUMIFS('شامل'!$T$4:$T$2203,'شامل'!$B$4:$B$2203,">="&$A8,'شامل'!$B$4:$B$2203,"<"&EDATE($A8,1))+SUMIFS('التخليص'!$F$4:$F$2203,'التخليص'!$B$4:$B$2203,">="&$A8,'التخليص'!$B$4:$B$2203,"<"&EDATE($A8,1)) | E8: =SUMIFS('شامل'!$U$4:$U$2203,'شامل'!$B$4:$B$2203,">="&$A8,'شامل'!$B$4:$B$2203,"<"&EDATE($A8,1))+SUMIFS('شامل'!$V$4:$V$2203,'شامل'!$B$4:$B$2203,">="&$A8,'شامل'!$B$4:$B$2203,"<"&EDATE($A8,1))+SUMIFS('البوالص'!$AH$4:$AH$2203,'البوالص'!$B$4:$B$2203,">="&$A8,'البوالص'!$B$4:$B$2203,"<"&EDATE($A8,1)) | F8: =SUMIFS('البوالص'!$Q$4:$Q$2203,'البوالص'!$B$4:$B$2203,">="&$A8,'البوالص'!$B$4:$B$2203,"<"&EDATE($A8,1))+SUMIFS('شامل'!$P$4:$P$2203,'شامل'!$B$4:$B$2203,">="&$A8,'شامل'!$B$4:$B$2203,"<"&EDATE($A8,1))+SUMIFS('التخليص'!$H$4:$H$2203,'التخليص'!$B$4:$B$2203,">="&$A8,'التخليص'!$B$4:$B$2203,"<"&EDATE($A8,1))+SUMIFS('مولدات ايجي كول'!$H$4:$H$2203,'مولدات ايجي كول'!$B$4:$B$2203,">="&$A8,'مولدات ايجي كول'!$B$4:$B$2203,"<"&EDATE($A8,1))+SUMIFS('مولدات الشجيع'!$H$4:$H$2203,'مولدات الشجيع'!$B$4:$B$2203,">="&$A8,'مولدات الشجيع'!$B$4:$B$2203,"<"&EDATE($A8,1)) | H8: =IF(الإعدادات!$E8="","",الإعدادات!$E8) | I8: =SUMIF('البوالص'!$F$4:$F$2203,الإعدادات!$E8,'البوالص'!$L$4:$L$2203)+SUMIF('شامل'!$G$4:$G$2203,الإعدادات!$E8,'شامل'!$J$4:$J$2203) | J8: =SUMIF('البوالص'!$F$4:$F$2203,الإعدادات!$E8,'البوالص'!$AH$4:$AH$2203)+SUMIF('شامل'!$G$4:$G$2203,الإعدادات!$E8,'شامل'!$U$4:$U$2203) | L8: =IF(الإعدادات!$I8="","",الإعدادات!$I8) | M8: =SUMIF('شامل'!$F$4:$F$2203,الإعدادات!$I8,'شامل'!$O$4:$O$2203) | N8: =SUMIF('شامل'!$F$4:$F$2203,الإعدادات!$I8,'شامل'!$Q$4:$Q$2203) | P8: كرتات | Q8: =SUM('البوالص'!$X$4:$X$2203) | V8: =IF('أرصدة العملاء والموردين'!E8="","",'أرصدة العملاء والموردين'!E8) | W8: ='أرصدة العملاء والموردين'!F8
A9: =DATE(سنة_التقارير,6,1) | B9: يونيو | C9: =SUMIFS('البوالص'!$L$4:$L$2203,'البوالص'!$B$4:$B$2203,">="&$A9,'البوالص'!$B$4:$B$2203,"<"&EDATE($A9,1))+SUMIFS('شامل'!$O$4:$O$2203,'شامل'!$B$4:$B$2203,">="&$A9,'شامل'!$B$4:$B$2203,"<"&EDATE($A9,1))+SUMIFS('التخليص'!$G$4:$G$2203,'التخليص'!$B$4:$B$2203,">="&$A9,'التخليص'!$B$4:$B$2203,"<"&EDATE($A9,1))+SUMIFS('مولدات ايجي كول'!$G$4:$G$2203,'مولدات ايجي كول'!$B$4:$B$2203,">="&$A9,'مولدات ايجي كول'!$B$4:$B$2203,"<"&EDATE($A9,1))+SUMIFS('مولدات الشجيع'!$G$4:$G$2203,'مولدات الشجيع'!$B$4:$B$2203,">="&$A9,'مولدات الشجيع'!$B$4:$B$2203,"<"&EDATE($A9,1)) | D9: =SUMIFS('البوالص'!$AF$4:$AF$2203,'البوالص'!$B$4:$B$2203,">="&$A9,'البوالص'!$B$4:$B$2203,"<"&EDATE($A9,1))+SUMIFS('شامل'!$T$4:$T$2203,'شامل'!$B$4:$B$2203,">="&$A9,'شامل'!$B$4:$B$2203,"<"&EDATE($A9,1))+SUMIFS('التخليص'!$F$4:$F$2203,'التخليص'!$B$4:$B$2203,">="&$A9,'التخليص'!$B$4:$B$2203,"<"&EDATE($A9,1)) | E9: =SUMIFS('شامل'!$U$4:$U$2203,'شامل'!$B$4:$B$2203,">="&$A9,'شامل'!$B$4:$B$2203,"<"&EDATE($A9,1))+SUMIFS('شامل'!$V$4:$V$2203,'شامل'!$B$4:$B$2203,">="&$A9,'شامل'!$B$4:$B$2203,"<"&EDATE($A9,1))+SUMIFS('البوالص'!$AH$4:$AH$2203,'البوالص'!$B$4:$B$2203,">="&$A9,'البوالص'!$B$4:$B$2203,"<"&EDATE($A9,1)) | F9: =SUMIFS('البوالص'!$Q$4:$Q$2203,'البوالص'!$B$4:$B$2203,">="&$A9,'البوالص'!$B$4:$B$2203,"<"&EDATE($A9,1))+SUMIFS('شامل'!$P$4:$P$2203,'شامل'!$B$4:$B$2203,">="&$A9,'شامل'!$B$4:$B$2203,"<"&EDATE($A9,1))+SUMIFS('التخليص'!$H$4:$H$2203,'التخليص'!$B$4:$B$2203,">="&$A9,'التخليص'!$B$4:$B$2203,"<"&EDATE($A9,1))+SUMIFS('مولدات ايجي كول'!$H$4:$H$2203,'مولدات ايجي كول'!$B$4:$B$2203,">="&$A9,'مولدات ايجي كول'!$B$4:$B$2203,"<"&EDATE($A9,1))+SUMIFS('مولدات الشجيع'!$H$4:$H$2203,'مولدات الشجيع'!$B$4:$B$2203,">="&$A9,'مولدات الشجيع'!$B$4:$B$2203,"<"&EDATE($A9,1)) | H9: =IF(الإعدادات!$E9="","",الإعدادات!$E9) | I9: =SUMIF('البوالص'!$F$4:$F$2203,الإعدادات!$E9,'البوالص'!$L$4:$L$2203)+SUMIF('شامل'!$G$4:$G$2203,الإعدادات!$E9,'شامل'!$J$4:$J$2203) | J9: =SUMIF('البوالص'!$F$4:$F$2203,الإعدادات!$E9,'البوالص'!$AH$4:$AH$2203)+SUMIF('شامل'!$G$4:$G$2203,الإعدادات!$E9,'شامل'!$U$4:$U$2203) | L9: =IF(الإعدادات!$I9="","",الإعدادات!$I9) | M9: =SUMIF('شامل'!$F$4:$F$2203,الإعدادات!$I9,'شامل'!$O$4:$O$2203) | N9: =SUMIF('شامل'!$F$4:$F$2203,الإعدادات!$I9,'شامل'!$Q$4:$Q$2203) | P9: تحيا مصر | Q9: =SUM('البوالص'!$Y$4:$Y$2203) | V9: =IF('أرصدة العملاء والموردين'!E9="","",'أرصدة العملاء والموردين'!E9) | W9: ='أرصدة العملاء والموردين'!F9
A10: =DATE(سنة_التقارير,7,1) | B10: يوليو | C10: =SUMIFS('البوالص'!$L$4:$L$2203,'البوالص'!$B$4:$B$2203,">="&$A10,'البوالص'!$B$4:$B$2203,"<"&EDATE($A10,1))+SUMIFS('شامل'!$O$4:$O$2203,'شامل'!$B$4:$B$2203,">="&$A10,'شامل'!$B$4:$B$2203,"<"&EDATE($A10,1))+SUMIFS('التخليص'!$G$4:$G$2203,'التخليص'!$B$4:$B$2203,">="&$A10,'التخليص'!$B$4:$B$2203,"<"&EDATE($A10,1))+SUMIFS('مولدات ايجي كول'!$G$4:$G$2203,'مولدات ايجي كول'!$B$4:$B$2203,">="&$A10,'مولدات ايجي كول'!$B$4:$B$2203,"<"&EDATE($A10,1))+SUMIFS('مولدات الشجيع'!$G$4:$G$2203,'مولدات الشجيع'!$B$4:$B$2203,">="&$A10,'مولدات الشجيع'!$B$4:$B$2203,"<"&EDATE($A10,1)) | D10: =SUMIFS('البوالص'!$AF$4:$AF$2203,'البوالص'!$B$4:$B$2203,">="&$A10,'البوالص'!$B$4:$B$2203,"<"&EDATE($A10,1))+SUMIFS('شامل'!$T$4:$T$2203,'شامل'!$B$4:$B$2203,">="&$A10,'شامل'!$B$4:$B$2203,"<"&EDATE($A10,1))+SUMIFS('التخليص'!$F$4:$F$2203,'التخليص'!$B$4:$B$2203,">="&$A10,'التخليص'!$B$4:$B$2203,"<"&EDATE($A10,1)) | E10: =SUMIFS('شامل'!$U$4:$U$2203,'شامل'!$B$4:$B$2203,">="&$A10,'شامل'!$B$4:$B$2203,"<"&EDATE($A10,1))+SUMIFS('شامل'!$V$4:$V$2203,'شامل'!$B$4:$B$2203,">="&$A10,'شامل'!$B$4:$B$2203,"<"&EDATE($A10,1))+SUMIFS('البوالص'!$AH$4:$AH$2203,'البوالص'!$B$4:$B$2203,">="&$A10,'البوالص'!$B$4:$B$2203,"<"&EDATE($A10,1)) | F10: =SUMIFS('البوالص'!$Q$4:$Q$2203,'البوالص'!$B$4:$B$2203,">="&$A10,'البوالص'!$B$4:$B$2203,"<"&EDATE($A10,1))+SUMIFS('شامل'!$P$4:$P$2203,'شامل'!$B$4:$B$2203,">="&$A10,'شامل'!$B$4:$B$2203,"<"&EDATE($A10,1))+SUMIFS('التخليص'!$H$4:$H$2203,'التخليص'!$B$4:$B$2203,">="&$A10,'التخليص'!$B$4:$B$2203,"<"&EDATE($A10,1))+SUMIFS('مولدات ايجي كول'!$H$4:$H$2203,'مولدات ايجي كول'!$B$4:$B$2203,">="&$A10,'مولدات ايجي كول'!$B$4:$B$2203,"<"&EDATE($A10,1))+SUMIFS('مولدات الشجيع'!$H$4:$H$2203,'مولدات الشجيع'!$B$4:$B$2203,">="&$A10,'مولدات الشجيع'!$B$4:$B$2203,"<"&EDATE($A10,1)) | H10: =IF(الإعدادات!$E10="","",الإعدادات!$E10) | I10: =SUMIF('البوالص'!$F$4:$F$2203,الإعدادات!$E10,'البوالص'!$L$4:$L$2203)+SUMIF('شامل'!$G$4:$G$2203,الإعدادات!$E10,'شامل'!$J$4:$J$2203) | J10: =SUMIF('البوالص'!$F$4:$F$2203,الإعدادات!$E10,'البوالص'!$AH$4:$AH$2203)+SUMIF('شامل'!$G$4:$G$2203,الإعدادات!$E10,'شامل'!$U$4:$U$2203) | L10: =IF(الإعدادات!$I10="","",الإعدادات!$I10) | M10: =SUMIF('شامل'!$F$4:$F$2203,الإعدادات!$I10,'شامل'!$O$4:$O$2203) | N10: =SUMIF('شامل'!$F$4:$F$2203,الإعدادات!$I10,'شامل'!$Q$4:$Q$2203) | P10: ثبتان | Q10: =SUM('البوالص'!$Z$4:$Z$2203) | V10: =IF('أرصدة العملاء والموردين'!E10="","",'أرصدة العملاء والموردين'!E10) | W10: ='أرصدة العملاء والموردين'!F10
