Workbook

Sheet اكما
A1: فاتورة | B1: م | C1: التاريخ | D1: رقم الاذن | E1: عدد الحاويات | F1: النولون | G1: قيمة مضافة | H1: الايصالات | I1: اجمالي الفاتوره | J1: الدفعات | K1: اجمالي الحساب | L1: Column1 | M1: Column2
I2: =Table11819202310303132353839[[#This Row],[النولون]]+Table11819202310303132353839[[#This Row],[الايصالات]]+Table11819202310303132353839[[#This Row],[قيمة مضافة]] -> 0 | K2: 0
A3: 1225 | B3: 1 | C3: 14/1/2026 | D3: 871542 | E3: 2*20 | F3: 26800 | H3: =100+365.21+1100+420+50+1482+300+342 -> 4159.21 | I3: =Table11819202310303132353839[[#This Row],[النولون]]+Table11819202310303132353839[[#This Row],[الايصالات]]+Table11819202310303132353839[[#This Row],[قيمة مضافة]] -> 30959.21 | K3: =K2+Table11819202310303132353839[[#This Row],[اجمالي الفاتوره]]-Table11819202310303132353839[[#This Row],[الدفعات]] -> 30959.21
A4: 1244 | B4: 2 | C4: 22/1/2026 | D4: 1260082 | E4: 22*40 | F4: =18500*22 -> 407000 | H4: =12*350+26*100+120*2+483.63+483.63+483.63+480.8+480.8+480.8+480.8+480.8+829.66+829.66+365.21+365.21+365.21+365.21+365.21+365.21+648.88+869.38+909.09+789.94+869.38+581.31+800+7700+22000+6*1150+9*1140+1350+1135*2+800+1050+1100*2 -> 74743.45 | I4: =Table11819202310303132353839[[#This Row],[النولون]]+Table11819202310303132353839[[#This Row],[الايصالات]]+Table11819202310303132353839[[#This Row],[قيمة مضافة]] -> 481743.45 | K4: =K3+Table11819202310303132353839[[#This Row],[اجمالي الفاتوره]]-Table11819202310303132353839[[#This Row],[الدفعات]] -> 512702.66
C5: 17/2/2026 | I5: =Table11819202310303132353839[[#This Row],[النولون]]+Table11819202310303132353839[[#This Row],[الايصالات]]+Table11819202310303132353839[[#This Row],[قيمة مضافة]] -> 0 | J5: 512703 | K5: =K4+Table11819202310303132353839[[#This Row],[اجمالي الفاتوره]]-Table11819202310303132353839[[#This Row],[الدفعات]] -> -0.34
A6: 1245 | B6: 3 | C6: 22/1/2026 | D6: 20179 | E6: بالتة | F6: 6000 | G6: =0.14*Table11819202310303132353839[[#This Row],[النولون]] -> 840 | H6: =255+88.61 -> 343.61 | I6: =Table11819202310303132353839[[#This Row],[النولون]]+Table11819202310303132353839[[#This Row],[الايصالات]]+Table11819202310303132353839[[#This Row],[قيمة مضافة]] -> 7183.61 | K6: =K5+Table11819202310303132353839[[#This Row],[اجمالي الفاتوره]]-Table11819202310303132353839[[#This Row],[الدفعات]] -> 7183.27
C7: 18/2/2026 | J7: 7183.61 | K7: =K6+Table11819202310303132353839[[#This Row],[اجمالي الفاتوره]]-Table11819202310303132353839[[#This Row],[الدفعات]] -> -0.34
A8: 1272 | B8: 4 | C8: 7/2/2026 | D8: 1260107 | E8: 22*40 | F8: =18500*22 -> 407000 | H8: =25*100+600+7700+22000+1100+1000+3*1140+1140+1100+15*1150+392.75+790.15+477.98+862.19+916.37+829.66+477.98+869.38+909.28+483.63*5+4*480.8+365.21*4+45.15*2+20*350 -> 77228.23 | I8: =Table11819202310303132353839[[#This Row],[النولون]]+Table11819202310303132353839[[#This Row],[الايصالات]]+Table11819202310303132353839[[#This Row],[قيمة مضافة]] -> 484228.23 | K8: =K7+Table11819202310303132353839[[#This Row],[اجمالي الفاتوره]]-Table11819202310303132353839[[#This Row],[الدفعات]] -> 484227.89
C9: 12/3/2026 | F9: 0 | H9: 0 | I9: 0 | J9: 484228 | K9: =K8+Table11819202310303132353839[[#This Row],[اجمالي الفاتوره]]-Table11819202310303132353839[[#This Row],[الدفعات]] -> -0.11
A10: 1283 | B10: 5 | C10: 11/2/2026 | D10: 1470800 | E10: 2*20 | F10: 24000 | H10: =100*2+1350+1256.52+490+1435+1071.83+50.2 -> 5853.55 | I10: =Table11819202310303132353839[[#This Row],[النولون]]+Table11819202310303132353839[[#This Row],[الايصالات]]+Table11819202310303132353839[[#This Row],[قيمة مضافة]] -> 29853.55 | K10: =K9+Table11819202310303132353839[[#This Row],[اجمالي الفاتوره]]-Table11819202310303132353839[[#This Row],[الدفعات]] -> 29853.44
A11: 1284 | B11: 6 | C11: 11/2/2026 | D11: 871744 | E11: 10*20 | F11: =24000*5 -> 120000 | H11: =100*4+50*3+850+378.98+385.86+365.21*3+105.79*3+68.08*2+45.15+560*3+490*2+1245*2+1350*3+1500+1710+250.8 -> 16419.95 | I11: =Table11819202310303132353839[[#This Row],[النولون]]+Table11819202310303132353839[[#This Row],[الايصالات]]+Table11819202310303132353839[[#This Row],[قيمة مضافة]] -> 136419.95 | K11: =K10+Table11819202310303132353839[[#This Row],[اجمالي الفاتوره]]-Table11819202310303132353839[[#This Row],[الدفعات]] -> 166273.39
A12: 1299 | B12: 7 | C12: 21/2/2026 | D12: 883888 | E12: 8*20 | F12: =24000*4 -> 96000 | H12: =4*100+409.96+1150+392.75+1150+392.75+1350+365.21+1150+490*4+6680.4+1200+1368 -> 17969.07 | I12: =Table11819202310303132353839[[#This Row],[النولون]]+Table11819202310303132353839[[#This Row],[الايصالات]]+Table11819202310303132353839[[#This Row],[قيمة مضافة]] -> 113969.07 | K12: =K11+Table11819202310303132353839[[#This Row],[اجمالي الفاتوره]]-Table11819202310303132353839[[#This Row],[الدفعات]] -> 280242.46
A13: 1300 | B13: 8 | C13: 21/2/2026 | D13: 2319607560 | E13: 14*20 | F13: =24000*7 -> 168000 | H13: =850+7*100+365.21*6+603.72+490*7+11012.4+1350*5+1150*2+684 -> 28521.38 | I13: =Table11819202310303132353839[[#This Row],[النولون]]+Table11819202310303132353839[[#This Row],[الايصالات]]+Table11819202310303132353839[[#This Row],[قيمة مضافة]] -> 196521.38 | K13: =K12+Table11819202310303132353839[[#This Row],[اجمالي الفاتوره]]-Table11819202310303132353839[[#This Row],[الدفعات]] -> 476763.84
A14: 1301 | B14: 9 | C14: 21/2/2026 | D14: 15748539 | E14: 3*20 | F14: =18500+24000 -> 42500 | H14: =100+60+220.89+700+365.21+1350+1000+490+1485 -> 5771.1 | I14: =Table11819202310303132353839[[#This Row],[النولون]]+Table11819202310303132353839[[#This Row],[الايصالات]]+Table11819202310303132353839[[#This Row],[قيمة مضافة]] -> 48271.1 | K14: =K13+Table11819202310303132353839[[#This Row],[اجمالي الفاتوره]]-Table11819202310303132353839[[#This Row],[الدفعات]] -> 525034.94
A15: 1307 | B15: 10 | C15: 22/2/2026 | D15: 265402165 | E15: 8*20 | F15: =24000*4 -> 96000 | H15: =4*100+810+365.21*4+1350*4+490*4+1977+11491.2+24021 -> 47520.04 | I15: =Table11819202310303132353839[[#This Row],[النولون]]+Table11819202310303132353839[[#This Row],[الايصالات]]+Table11819202310303132353839[[#This Row],[قيمة مضافة]] -> 143520.04 | K15: =K14+Table11819202310303132353839[[#This Row],[اجمالي الفاتوره]]-Table11819202310303132353839[[#This Row],[الدفعات]] -> 668554.98
C16: 31/3/2026 | J16: 668554 | K16: =K15+Table11819202310303132353839[[#This Row],[اجمالي الفاتوره]]-Table11819202310303132353839[[#This Row],[الدفعات]] -> 0.98
A17: 1326 | B17: 11 | C17: 7/3/2026 | D17: 75808 | E17: 2*20 | F17: 24000 | H17: =100+375.54+490+1436.4+456+114+1350 -> 4321.94 | I17: =Table11819202310303132353839[[#This Row],[النولون]]+Table11819202310303132353839[[#This Row],[الايصالات]]+Table11819202310303132353839[[#This Row],[قيمة مضافة]] -> 28321.94 | K17: =K16+Table11819202310303132353839[[#This Row],[اجمالي الفاتوره]]-Table11819202310303132353839[[#This Row],[الدفعات]] -> 28322.92
A18: 1327 | B18: 12 | C18: 7/3/2026 | D18: 2320876560 | E18: 2*20 | F18: 24000 | H18: =100+365.21+490+1573.2+1350 -> 3878.41 | I18: =Table11819202310303132353839[[#This Row],[النولون]]+Table11819202310303132353839[[#This Row],[الايصالات]]+Table11819202310303132353839[[#This Row],[قيمة مضافة]] -> 27878.41 | K18: =K17+Table11819202310303132353839[[#This Row],[اجمالي الفاتوره]]-Table11819202310303132353839[[#This Row],[الدفعات]] -> 56201.33 | L18: =SUM(I:I)-SUM(J:J)+K2 -> 2221981.4 | M18: =SUM(Table11819202310303132353839[قيمة مضافة]) -> 16184
C19: 9/4/2026 | J19: 56200 | K19: =K18+Table11819202310303132353839[[#This Row],[اجمالي الفاتوره]]-Table11819202310303132353839[[#This Row],[الدفعات]] -> 1.33
A20: 1329 | B20: 13 | C20: 28/3/2026 | D20: 2260190 | E20: 2*40 | F20: =2*21300 -> 42600 | H20: =100*2+810+1140+1150+883.84+493.96+700+350*2+2000 -> 8077.8 | I20: =Table11819202310303132353839[[#This Row],[النولون]]+Table11819202310303132353839[[#This Row],[الايصالات]]+Table11819202310303132353839[[#This Row],[قيمة مضافة]] -> 50677.8 | K20: =K19+Table11819202310303132353839[[#This Row],[اجمالي الفاتوره]]-Table11819202310303132353839[[#This Row],[الدفعات]] -> 50679.13
A21: 1330 | B21: 14 | C21: 28/3/2026 | D21: 891559 | E21: 10*20 | F21: =27600*5 -> 138000 | H21: =5*100+850+810+365.21*4+406.52+45.15+105.79+105.79+68.08+105.79+490*4+560+1350*5+250.8+1500+1710 -> 17188.76 | I21: =Table11819202310303132353839[[#This Row],[النولون]]+Table11819202310303132353839[[#This Row],[الايصالات]]+Table11819202310303132353839[[#This Row],[قيمة مضافة]] -> 155188.76 | K21: =K20+Table11819202310303132353839[[#This Row],[اجمالي الفاتوره]]-Table11819202310303132353839[[#This Row],[الدفعات]] -> 205867.89
A22: 1131 | B22: 15 | C22: 28/3/2026 | D22: 884426 | E22: 10*20 | F22: =5*27600 -> 138000 | H22: =5*100+850+447.83+451.28+406.52+403.08+368.65+5*490+250+13110+1500+1710+1350*4+1100 -> 28947.36 | I22: =Table11819202310303132353839[[#This Row],[النولون]]+Table11819202310303132353839[[#This Row],[الايصالات]]+Table11819202310303132353839[[#This Row],[قيمة مضافة]] -> 166947.36 | K22: =K21+Table11819202310303132353839[[#This Row],[اجمالي الفاتوره]]-Table11819202310303132353839[[#This Row],[الدفعات]] -> 372815.25
A23: 1344 | B23: 16 | C23: 30/3/2026 | D23: 2321317690 | E23: 8*20 | F23: =27600*4 -> 110400 | H23: =100*6+850*2+365.21*4+560+490*3+1350*4+7113.6+342 -> 18646.44 | I23: =Table11819202310303132353839[[#This Row],[النولون]]+Table11819202310303132353839[[#This Row],[الايصالات]]+Table11819202310303132353839[[#This Row],[قيمة مضافة]] -> 129046.44 | K23: =K22+Table11819202310303132353839[[#This Row],[اجمالي الفاتوره]]-Table11819202310303132353839[[#This Row],[الدفعات]] -> 501861.69
A24: 1345 | B24: 17 | C24: 30/3/2026 | D24: 266986048 | E24: 2*20 | F24: 27600 | H24: =100+365.21+490+1350+497+2872.8+6224 -> 11899.01 | I24: =Table11819202310303132353839[[#This Row],[النولون]]+Table11819202310303132353839[[#This Row],[الايصالات]]+Table11819202310303132353839[[#This Row],[قيمة مضافة]] -> 39499.01 | K24: =K23+Table11819202310303132353839[[#This Row],[اجمالي الفاتوره]]-Table11819202310303132353839[[#This Row],[الدفعات]] -> 541360.7
C25: 46135 | I25: =Table11819202310303132353839[[#This Row],[النولون]]+Table11819202310303132353839[[#This Row],[الايصالات]]+Table11819202310303132353839[[#This Row],[قيمة مضافة]] -> 0 | J25: 541359 | K25: =K24+Table11819202310303132353839[[#This Row],[اجمالي الفاتوره]]-Table11819202310303132353839[[#This Row],[الدفعات]] -> 1.7
A26: 1416 | B26: 18 | C26: 46138 | D26: 178343 | E26: 2*40 | F26: =20500*2 -> 41000 | G26: =0.14*Table11819202310303132353839[[#This Row],[النولون]] -> 5740 | H26: =100*2+1135*2+377.5+739.95+350*2+1282.5*2+228+719+16758+20089.31 -> 44646.76 | I26: =Table11819202310303132353839[[#This Row],[النولون]]+Table11819202310303132353839[[#This Row],[الايصالات]]+Table11819202310303132353839[[#This Row],[قيمة مضافة]] -> 91386.76 | K26: =K25+Table11819202310303132353839[[#This Row],[اجمالي الفاتوره]]-Table11819202310303132353839[[#This Row],[الدفعات]] -> 91388.46
C27: 46176 | J27: 91388.46 | K27: =K26+Table11819202310303132353839[[#This Row],[اجمالي الفاتوره]]-Table11819202310303132353839[[#This Row],[الدفعات]] -> 0
A28: 1471 | B28: 19 | C28: 46159 | D28: 197530 | E28: 2*20 | F28: 27600 | G28: =0.14*Table11819202310303132353839[[#This Row],[النولون]] -> 3864 | H28: =100+5010+100+1150+1284.87+560+1596+100+399+4446+10401.25 -> 25147.12 | I28: =Table11819202310303132353839[[#This Row],[النولون]]+Table11819202310303132353839[[#This Row],[الايصالات]]+Table11819202310303132353839[[#This Row],[قيمة مضافة]] -> 56611.12 | K28: =K27+Table11819202310303132353839[[#This Row],[اجمالي الفاتوره]]-Table11819202310303132353839[[#This Row],[الدفعات]] -> 56611.12
A29: 1472 | B29: 20 | C29: 46159 | D29: 911142 | E29: 8*20 | F29: =27600*4 -> 110400 | H29: =100*4+850+45.15+68.08+45.15+45.15+365.21+365.21+365.21+365.21+490*4+1200+1368+319.2+1350*4 -> 13161.57 | I29: =Table11819202310303132353839[[#This Row],[النولون]]+Table11819202310303132353839[[#This Row],[الايصالات]]+Table11819202310303132353839[[#This Row],[قيمة مضافة]] -> 123561.57 | K29: =K28+Table11819202310303132353839[[#This Row],[اجمالي الفاتوره]]-Table11819202310303132353839[[#This Row],[الدفعات]] -> 180172.69
A30: 1473 | B30: 21 | C30: 46159 | D30: 904038 | E30: 10*20 | F30: =5*27600+2*2000+1000 -> 143000 | H30: =6*100+850+810+105.79+68.08+68.08+45.15+365.21*4+368.65+560*5+1250*4+1245+5000+1500+1710+399 -> 22030.59 | I30: =Table11819202310303132353839[[#This Row],[النولون]]+Table11819202310303132353839[[#This Row],[الايصالات]]+Table11819202310303132353839[[#This Row],[قيمة مضافة]] -> 165030.59 | K30: =K29+Table11819202310303132353839[[#This Row],[اجمالي الفاتوره]]-Table11819202310303132353839[[#This Row],[الدفعات]] -> 345203.28
A31: 1474 | B31: 22 | C31: 46159 | D31: 2326365110 | E31: 10*20 | F31: =5*27600+3000 -> 141000 | H31: =5*100+365.21*5+490*5+1150*4+1350+10602 -> 21328.05 | I31: =Table11819202310303132353839[[#This Row],[النولون]]+Table11819202310303132353839[[#This Row],[الايصالات]]+Table11819202310303132353839[[#This Row],[قيمة مضافة]] -> 162328.05 | K31: =K30+Table11819202310303132353839[[#This Row],[اجمالي الفاتوره]]-Table11819202310303132353839[[#This Row],[الدفعات]] -> 507531.33
C32: 46198 | J32: 451020 | K32: =K31+Table11819202310303132353839[[#This Row],[اجمالي الفاتوره]]-Table11819202310303132353839[[#This Row],[الدفعات]] -> 56511.33
A33: 1475 | B33: 23 | C33: 46159 | D33: 5260305 | E33: 7*40 | F33: =20500*7 -> 143500 | H33: =7*100+120+810+1350+1245+1250+1245+1245+1150+480.8*4+365.21*3+1610+2450+7000+4*350+6840+1100 -> 32533.83 | I33: =Table11819202310303132353839[[#This Row],[النولون]]+Table11819202310303132353839[[#This Row],[الايصالات]]+Table11819202310303132353839[[#This Row],[قيمة مضافة]] -> 176033.83 | K33: =K32+Table11819202310303132353839[[#This Row],[اجمالي الفاتوره]]-Table11819202310303132353839[[#This Row],[الدفعات]] -> 232545.16
C34: 46211 | J34: 232544.95 | K34: =K33+Table11819202310303132353839[[#This Row],[اجمالي الفاتوره]]-Table11819202310303132353839[[#This Row],[الدفعات]] -> 0.21
A35: 1486 | B35: 24 | C35: 46174 | D35: 209408 | E35: 2*40 | F35: =20500*2 -> 41000 | G35: =Table11819202310303132353839[[#This Row],[النولون]]*0.14 -> 5740 | H35: =100+1105+1105+344.34+386.5+350+1852.5+1282.5+200+719+20531.17+16758 -> 44734.01 | I35: =Table11819202310303132353839[[#This Row],[النولون]]+Table11819202310303132353839[[#This Row],[الايصالات]]+Table11819202310303132353839[[#This Row],[قيمة مضافة]] -> 91474.01 | K35: =K34+Table11819202310303132353839[[#This Row],[اجمالي الفاتوره]]-Table11819202310303132353839[[#This Row],[الدفعات]] -> 91474.22
A36: 1487 | B36: 25 | C36: 46174 | D36: 2328038790 | E36: 10*20 | F36: =27600*5 -> 138000 | H36: =100*5+365.21*4+409.96+5*560+8892+1350*5 -> 20812.8 | I36: =Table11819202310303132353839[[#This Row],[النولون]]+Table11819202310303132353839[[#This Row],[الايصالات]]+Table11819202310303132353839[[#This Row],[قيمة مضافة]] -> 158812.8 | K36: =K35+Table11819202310303132353839[[#This Row],[اجمالي الفاتوره]]-Table11819202310303132353839[[#This Row],[الدفعات]] -> 250287.02
A37: 1488 | B37: 26 | C37: 46174 | D37: 2326783040 | E37: 6*20 | F37: =27600*3 -> 82800 | H37: =3*100+365.21*3+1350*3+560*3+6361.2 -> 13486.83 | I37: =Table11819202310303132353839[[#This Row],[النولون]]+Table11819202310303132353839[[#This Row],[الايصالات]]+Table11819202310303132353839[[#This Row],[قيمة مضافة]] -> 96286.83 | K37: =K36+Table11819202310303132353839[[#This Row],[اجمالي الفاتوره]]-Table11819202310303132353839[[#This Row],[الدفعات]] -> 346573.85
A38: 1507 | B38: 27 | C38: 46180 | D38: 920218 | E38: 10*20 | F38: =27600*5 -> 138000 | H38: =114+100*5+120+368.65+600.75+365.21*3+105.79+45.15+560*3+1350*4+1315+1500+1710+399 -> 14953.97 | I38: =Table11819202310303132353839[[#This Row],[النولون]]+Table11819202310303132353839[[#This Row],[الايصالات]]+Table11819202310303132353839[[#This Row],[قيمة مضافة]] -> 152953.97 | K38: =K37+Table11819202310303132353839[[#This Row],[اجمالي الفاتوره]]-Table11819202310303132353839[[#This Row],[الدفعات]] -> 499527.82
A39: 1548 | B39: 28 | C39: 46187 | D39: 2327908940 | E39: 10*20 | F39: =27600*5 -> 138000 | H39: =100*5+5*365.21+490*4+8892+5*1350 -> 19928.05 | I39: =Table11819202310303132353839[[#This Row],[النولون]]+Table11819202310303132353839[[#This Row],[الايصالات]]+Table11819202310303132353839[[#This Row],[قيمة مضافة]] -> 157928.05 | K39: =K38+Table11819202310303132353839[[#This Row],[اجمالي الفاتوره]]-Table11819202310303132353839[[#This Row],[الدفعات]] -> 657455.87
A40: 1549 | B40: 29 | C40: 46187 | D40: 2327908590 | E40: 4*20 | F40: =2*27600 -> 55200 | H40: =100*2+365.21*2+490*2+3556.8+1350+1350 -> 8167.22 | I40: =Table11819202310303132353839[[#This Row],[النولون]]+Table11819202310303132353839[[#This Row],[الايصالات]]+Table11819202310303132353839[[#This Row],[قيمة مضافة]] -> 63367.22 | K40: =K39+Table11819202310303132353839[[#This Row],[اجمالي الفاتوره]]-Table11819202310303132353839[[#This Row],[الدفعات]] -> 720823.09
...

Sheet mfb
A1: فاتورة | B1: م | C1: التاريخ | D1: اسم الشركه | E1: العنوان | F1: رقم الاذن | G1: عدد الحاويات | H1: النولون | I1: قيمة مضافة | J1: الايصالات | K1: اجمالي الفاتوره | L1: الدفعات | M1: اجمالي الحساب | N1: Column1 | O1: Column2
A2: 1261 | C2: 31/1/2026 | D2: لوجيا | E2: الصف | F2: 874984 | G2: 24*20 | H2: =12*26800 -> 321600 | J2: =24*120+100+11*560+365.21*8+382.42*2+399.64+420.29+3*1215+3*1250+6*1350+850*2+3192+3762+2736+1200+17784+3600+4104 -> 67219.45 | K2: =Table1181920231030313235383940[[#This Row],[النولون]]+Table1181920231030313235383940[[#This Row],[الايصالات]]+Table1181920231030313235383940[[#This Row],[قيمة مضافة]] -> 388819.45 | M2: =Table1181920231030313235383940[[#This Row],[اجمالي الفاتوره]] -> 388819.45
B3: 1 | C3: 31/1/2026 | D3: لوجيا | H3: 2500 | J3: =23*200+2410+35+574.7+3405+600 -> 11624.7 | K3: =Table1181920231030313235383940[[#This Row],[النولون]]+Table1181920231030313235383940[[#This Row],[الايصالات]]+Table1181920231030313235383940[[#This Row],[قيمة مضافة]] -> 14124.7 | M3: =M2+Table1181920231030313235383940[[#This Row],[اجمالي الفاتوره]]-Table1181920231030313235383940[[#This Row],[الدفعات]] -> 402944.15
B4: 2 | C4: 31/1/2026 | D4: زونج | E4: صور ضوئية | J4: 1010 | K4: =Table1181920231030313235383940[[#This Row],[النولون]]+Table1181920231030313235383940[[#This Row],[الايصالات]]+Table1181920231030313235383940[[#This Row],[قيمة مضافة]] -> 1010 | M4: =M3+Table1181920231030313235383940[[#This Row],[اجمالي الفاتوره]]-Table1181920231030313235383940[[#This Row],[الدفعات]] -> 403954.15
A5: 1270 | C5: 4/2/2026 | D5: لوجيا | E5: الصف | F5: 1346 | G5: 12*20 | H5: =26800*6 -> 160800 | J5: =12*120+1350+1772.87+1250+1315*4+5*365.21+180+600+560*6+2017.8+6726 -> 25782.72 | K5: =Table1181920231030313235383940[[#This Row],[النولون]]+Table1181920231030313235383940[[#This Row],[الايصالات]]+Table1181920231030313235383940[[#This Row],[قيمة مضافة]] -> 186582.72 | M5: =M4+Table1181920231030313235383940[[#This Row],[اجمالي الفاتوره]]-Table1181920231030313235383940[[#This Row],[الدفعات]] -> 590536.87
B6: 3 | C6: 4/2/2026 | D6: لوجيا | E6: الصف | H6: 2500 | J6: =11*200+1210+35+574.7 -> 4019.7 | K6: =Table1181920231030313235383940[[#This Row],[النولون]]+Table1181920231030313235383940[[#This Row],[الايصالات]]+Table1181920231030313235383940[[#This Row],[قيمة مضافة]] -> 6519.7 | M6: =M5+Table1181920231030313235383940[[#This Row],[اجمالي الفاتوره]]-Table1181920231030313235383940[[#This Row],[الدفعات]] -> 597056.57
A7: 1271 | C7: 4/2/2026 | D7: لوجيا | E7: الصف | F7: 878005 | G7: 22*20 | H7: =11*26800 -> 294800 | J7: =850+24*120+365.21*11+1350+1250+1315*9+420+560*8+16302+1368+3300+3762 -> 51814.31 | K7: =Table1181920231030313235383940[[#This Row],[النولون]]+Table1181920231030313235383940[[#This Row],[الايصالات]]+Table1181920231030313235383940[[#This Row],[قيمة مضافة]] -> 346614.31 | M7: =M6+Table1181920231030313235383940[[#This Row],[اجمالي الفاتوره]]-Table1181920231030313235383940[[#This Row],[الدفعات]] -> 943670.88
B8: 4 | C8: 4/2/2026 | D8: لوجيا | E8: الصف | H8: 2500 | J8: =21*200+2210+35+574.7 -> 7019.7 | K8: =Table1181920231030313235383940[[#This Row],[النولون]]+Table1181920231030313235383940[[#This Row],[الايصالات]]+Table1181920231030313235383940[[#This Row],[قيمة مضافة]] -> 9519.7 | M8: =M7+Table1181920231030313235383940[[#This Row],[اجمالي الفاتوره]]-Table1181920231030313235383940[[#This Row],[الدفعات]] -> 953190.58
C9: 8/2/2026 | K9: =Table1181920231030313235383940[[#This Row],[النولون]]+Table1181920231030313235383940[[#This Row],[الايصالات]]+Table1181920231030313235383940[[#This Row],[قيمة مضافة]] -> 0 | L9: 589956.57 | M9: =M8+Table1181920231030313235383940[[#This Row],[اجمالي الفاتوره]]-Table1181920231030313235383940[[#This Row],[الدفعات]] -> 363234.01 | N9: =SUM(K:K)-SUM(L:L) -> 0 | O9: =SUM(I:I) -> 0
K10: =Table1181920231030313235383940[[#This Row],[النولون]]+Table1181920231030313235383940[[#This Row],[الايصالات]]+Table1181920231030313235383940[[#This Row],[قيمة مضافة]] -> 0 | L10: 356134.01 | M10: =M9+Table1181920231030313235383940[[#This Row],[اجمالي الفاتوره]]-Table1181920231030313235383940[[#This Row],[الدفعات]] -> 7100
A11: 1288 | C11: 14/2/2026 | D11: لوجيا | E11: الصف | F11: 878872 | G11: 18*20 | H11: =26800*9 -> 241200 | J11: =850+560*9+614.9+1065+389.31+1115+389.31+1115+365.21*6+1115*3+1065+1150*2+45.15*2+105.79*7+18*120+2700+3078+451.45 -> 28700.06 | K11: =Table1181920231030313235383940[[#This Row],[النولون]]+Table1181920231030313235383940[[#This Row],[الايصالات]]+Table1181920231030313235383940[[#This Row],[قيمة مضافة]] -> 269900.06 | M11: =M10+Table1181920231030313235383940[[#This Row],[اجمالي الفاتوره]]-Table1181920231030313235383940[[#This Row],[الدفعات]] -> 277000.06
B12: 5 | C12: 14/2/2026 | D12: لوجيا | E12: الصف | H12: 2500 | J12: =574.7+17*200 -> 3974.7 | K12: =Table1181920231030313235383940[[#This Row],[النولون]]+Table1181920231030313235383940[[#This Row],[الايصالات]]+Table1181920231030313235383940[[#This Row],[قيمة مضافة]] -> 6474.7 | M12: =M11+Table1181920231030313235383940[[#This Row],[اجمالي الفاتوره]]-Table1181920231030313235383940[[#This Row],[الدفعات]] -> 283474.76
C13: 4/3/2026 | K13: =Table1181920231030313235383940[[#This Row],[النولون]]+Table1181920231030313235383940[[#This Row],[الايصالات]]+Table1181920231030313235383940[[#This Row],[قيمة مضافة]] -> 0 | L13: 283474.76 | M13: =M12+Table1181920231030313235383940[[#This Row],[اجمالي الفاتوره]]-Table1181920231030313235383940[[#This Row],[الدفعات]] -> 0
A14: 1388 | C14: 46130 | D14: لوجيا | E14: الصف | F14: 4965 | G14: 18*20 | H14: =9*28000 -> 252000 | J14: =1368+13748.4+1080+1350*4+1115*2+1315*3+365.21*2+375.54+372.09+372.09+836.05+389.31+385.86+372.09+850+560*8+16*120 -> 38854.85 | K14: =Table1181920231030313235383940[[#This Row],[النولون]]+Table1181920231030313235383940[[#This Row],[الايصالات]]+Table1181920231030313235383940[[#This Row],[قيمة مضافة]] -> 290854.85 | M14: =M13+Table1181920231030313235383940[[#This Row],[اجمالي الفاتوره]]-Table1181920231030313235383940[[#This Row],[الدفعات]] -> 290854.85
B15: 6 | C15: 46130 | D15: لوجيا | E15: الصف | H15: 2500 | J15: =35+574.7+200*17 -> 4009.7 | K15: =Table1181920231030313235383940[[#This Row],[النولون]]+Table1181920231030313235383940[[#This Row],[الايصالات]]+Table1181920231030313235383940[[#This Row],[قيمة مضافة]] -> 6509.7 | M15: =M14+Table1181920231030313235383940[[#This Row],[اجمالي الفاتوره]]-Table1181920231030313235383940[[#This Row],[الدفعات]] -> 297364.55
A16: 1389 | C16: 46130 | D16: لوجيا | E16: الصف | F16: 4973 | G16: 18*20 | H16: =9*28000 -> 252000 | J16: =850*2+1080+21*120+9*560+2394+13748.4+9*1315+6*365.21+399.64+600.75+396.19 -> 41905.24 | K16: =Table1181920231030313235383940[[#This Row],[النولون]]+Table1181920231030313235383940[[#This Row],[الايصالات]]+Table1181920231030313235383940[[#This Row],[قيمة مضافة]] -> 293905.24 | M16: =M15+Table1181920231030313235383940[[#This Row],[اجمالي الفاتوره]]-Table1181920231030313235383940[[#This Row],[الدفعات]] -> 591269.79
B17: 7 | C17: 46130 | D17: لوجيا | E17: الصف | H17: 2500 | J17: =35+574.7+200*17 -> 4009.7 | K17: =Table1181920231030313235383940[[#This Row],[النولون]]+Table1181920231030313235383940[[#This Row],[الايصالات]]+Table1181920231030313235383940[[#This Row],[قيمة مضافة]] -> 6509.7 | M17: =M16+Table1181920231030313235383940[[#This Row],[اجمالي الفاتوره]]-Table1181920231030313235383940[[#This Row],[الدفعات]] -> 597779.49
C18: 46139 | K18: =Table1181920231030313235383940[[#This Row],[النولون]]+Table1181920231030313235383940[[#This Row],[الايصالات]]+Table1181920231030313235383940[[#This Row],[قيمة مضافة]] -> 0 | L18: 597779.49 | M18: =M17+Table1181920231030313235383940[[#This Row],[اجمالي الفاتوره]]-Table1181920231030313235383940[[#This Row],[الدفعات]] -> 0
B19: 8 | C19: 46159 | D19: صن رايز | E19: عرب مساعد | F19: 913136 | G19: 10*20 | H19: =26000*5 -> 130000 | J19: =114+13*120+2100+389.31+375.54+1100+45.15+1150+365.21+365.21+1150+2150+365.21+45.15+45.15+5*560+4963.56+399+1500+1710 -> 22692.49 | K19: =Table1181920231030313235383940[[#This Row],[النولون]]+Table1181920231030313235383940[[#This Row],[الايصالات]]+Table1181920231030313235383940[[#This Row],[قيمة مضافة]] -> 152692.49 | M19: =M18+Table1181920231030313235383940[[#This Row],[اجمالي الفاتوره]]-Table1181920231030313235383940[[#This Row],[الدفعات]] -> 152692.49
A20: 1476 | C20: 46159 | D20: لوجيا | E20: الصف | F20: 919283 | G20: 24*20 | H20: =28000*12 -> 336000 | J20: =27*120+850+11*560+350+22230+6840+1200+3*570+3600+4104+7*365.21+396.19*2+372.09+389.31+413.41+1350*7+1200*2+1250+1315*2 -> 70537.66 | K20: =Table1181920231030313235383940[[#This Row],[النولون]]+Table1181920231030313235383940[[#This Row],[الايصالات]]+Table1181920231030313235383940[[#This Row],[قيمة مضافة]] -> 406537.66 | M20: =M19+Table1181920231030313235383940[[#This Row],[اجمالي الفاتوره]]-Table1181920231030313235383940[[#This Row],[الدفعات]] -> 559230.15
B21: 9 | C21: 46159 | D21: لوجيا | E21: الصف | H21: 2500 | J21: =2410+35+642+23*200 -> 7687 | K21: =Table1181920231030313235383940[[#This Row],[النولون]]+Table1181920231030313235383940[[#This Row],[الايصالات]]+Table1181920231030313235383940[[#This Row],[قيمة مضافة]] -> 10187 | M21: =M20+Table1181920231030313235383940[[#This Row],[اجمالي الفاتوره]]-Table1181920231030313235383940[[#This Row],[الدفعات]] -> 569417.15
C22: 46177 | K22: =Table1181920231030313235383940[[#This Row],[النولون]]+Table1181920231030313235383940[[#This Row],[الايصالات]]+Table1181920231030313235383940[[#This Row],[قيمة مضافة]] -> 0 | L22: 569417.15 | M22: =M21+Table1181920231030313235383940[[#This Row],[اجمالي الفاتوره]]-Table1181920231030313235383940[[#This Row],[الدفعات]] -> 0
A23: 1508 | C23: 46180 | D23: لوجيا | E23: الصف | F23: 925680 | G23: 22*20 | H23: =28000*11 -> 308000 | J23: =120*23+6*560+850+171.2+105.79*4+68.08+68.08+105.79+365.21*11+1250*2+1215*8+1250+5000+3300+3762+877.8 -> 38233.42 | K23: =Table1181920231030313235383940[[#This Row],[النولون]]+Table1181920231030313235383940[[#This Row],[الايصالات]]+Table1181920231030313235383940[[#This Row],[قيمة مضافة]] -> 346233.42 | M23: =M22+Table1181920231030313235383940[[#This Row],[اجمالي الفاتوره]]-Table1181920231030313235383940[[#This Row],[الدفعات]] -> 346233.42
B24: 10 | C24: 46180 | D24: لوجيا | E24: الصف | H24: 2500 | J24: =21*200+574.7+35+1010 -> 5819.7 | K24: =Table1181920231030313235383940[[#This Row],[النولون]]+Table1181920231030313235383940[[#This Row],[الايصالات]]+Table1181920231030313235383940[[#This Row],[قيمة مضافة]] -> 8319.7 | L24: 10 | M24: =M23+Table1181920231030313235383940[[#This Row],[اجمالي الفاتوره]]-Table1181920231030313235383940[[#This Row],[الدفعات]] -> 354543.12
C25: 46190 | K25: =Table1181920231030313235383940[[#This Row],[النولون]]+Table1181920231030313235383940[[#This Row],[الايصالات]]+Table1181920231030313235383940[[#This Row],[قيمة مضافة]] -> 0 | L25: 354543.12 | M25: =M24+Table1181920231030313235383940[[#This Row],[اجمالي الفاتوره]]-Table1181920231030313235383940[[#This Row],[الدفعات]] -> 0
K26: =Table1181920231030313235383940[[#This Row],[النولون]]+Table1181920231030313235383940[[#This Row],[الايصالات]]+Table1181920231030313235383940[[#This Row],[قيمة مضافة]] -> 0 | M26: =M25+Table1181920231030313235383940[[#This Row],[اجمالي الفاتوره]]-Table1181920231030313235383940[[#This Row],[الدفعات]] -> 0
K27: =Table1181920231030313235383940[[#This Row],[النولون]]+Table1181920231030313235383940[[#This Row],[الايصالات]]+Table1181920231030313235383940[[#This Row],[قيمة مضافة]] -> 0 | M27: =M26+Table1181920231030313235383940[[#This Row],[اجمالي الفاتوره]]-Table1181920231030313235383940[[#This Row],[الدفعات]] -> 0
K28: =Table1181920231030313235383940[[#This Row],[النولون]]+Table1181920231030313235383940[[#This Row],[الايصالات]]+Table1181920231030313235383940[[#This Row],[قيمة مضافة]] -> 0 | M28: =M27+Table1181920231030313235383940[[#This Row],[اجمالي الفاتوره]]-Table1181920231030313235383940[[#This Row],[الدفعات]] -> 0
K29: =Table1181920231030313235383940[[#This Row],[النولون]]+Table1181920231030313235383940[[#This Row],[الايصالات]]+Table1181920231030313235383940[[#This Row],[قيمة مضافة]] -> 0 | M29: =M28+Table1181920231030313235383940[[#This Row],[اجمالي الفاتوره]]-Table1181920231030313235383940[[#This Row],[الدفعات]] -> 0
K30: =Table1181920231030313235383940[[#This Row],[النولون]]+Table1181920231030313235383940[[#This Row],[الايصالات]]+Table1181920231030313235383940[[#This Row],[قيمة مضافة]] -> 0 | M30: =M29+Table1181920231030313235383940[[#This Row],[اجمالي الفاتوره]]-Table1181920231030313235383940[[#This Row],[الدفعات]] -> 0
K31: =Table1181920231030313235383940[[#This Row],[النولون]]+Table1181920231030313235383940[[#This Row],[الايصالات]]+Table1181920231030313235383940[[#This Row],[قيمة مضافة]] -> 0 | M31: =M30+Table1181920231030313235383940[[#This Row],[اجمالي الفاتوره]]-Table1181920231030313235383940[[#This Row],[الدفعات]] -> 0
K32: =Table1181920231030313235383940[[#This Row],[النولون]]+Table1181920231030313235383940[[#This Row],[الايصالات]]+Table1181920231030313235383940[[#This Row],[قيمة مضافة]] -> 0 | M32: =M31+Table1181920231030313235383940[[#This Row],[اجمالي الفاتوره]]-Table1181920231030313235383940[[#This Row],[الدفعات]] -> 0
K33: =Table1181920231030313235383940[[#This Row],[النولون]]+Table1181920231030313235383940[[#This Row],[الايصالات]]+Table1181920231030313235383940[[#This Row],[قيمة مضافة]] -> 0 | M33: =M32+Table1181920231030313235383940[[#This Row],[اجمالي الفاتوره]]-Table1181920231030313235383940[[#This Row],[الدفعات]] -> 0
K34: =Table1181920231030313235383940[[#This Row],[النولون]]+Table1181920231030313235383940[[#This Row],[الايصالات]]+Table1181920231030313235383940[[#This Row],[قيمة مضافة]] -> 0 | M34: =M33+Table1181920231030313235383940[[#This Row],[اجمالي الفاتوره]]-Table1181920231030313235383940[[#This Row],[الدفعات]] -> 0
K35: =Table1181920231030313235383940[[#This Row],[النولون]]+Table1181920231030313235383940[[#This Row],[الايصالات]]+Table1181920231030313235383940[[#This Row],[قيمة مضافة]] -> 0 | M35: =M34+Table1181920231030313235383940[[#This Row],[اجمالي الفاتوره]]-Table1181920231030313235383940[[#This Row],[الدفعات]] -> 0
K36: =Table1181920231030313235383940[[#This Row],[النولون]]+Table1181920231030313235383940[[#This Row],[الايصالات]]+Table1181920231030313235383940[[#This Row],[قيمة مضافة]] -> 0 | M36: =M35+Table1181920231030313235383940[[#This Row],[اجمالي الفاتوره]]-Table1181920231030313235383940[[#This Row],[الدفعات]] -> 0
K37: =Table1181920231030313235383940[[#This Row],[النولون]]+Table1181920231030313235383940[[#This Row],[الايصالات]]+Table1181920231030313235383940[[#This Row],[قيمة مضافة]] -> 0 | M37: =M36+Table1181920231030313235383940[[#This Row],[اجمالي الفاتوره]]-Table1181920231030313235383940[[#This Row],[الدفعات]] -> 0
... K347: =Table1181920231030313235383940[[#This Row],[النولون]]+Table1181920231030313235383940[[#This Row],[الايصالات]]+Table1181920231030313235383940[[#This Row],[قيمة مضافة]] -> 0 | M347: =M346+Table1181920231030313235383940[[#This Row],[اجمالي الفاتوره]]-Table1181920231030313235383940[[#This Row],[الدفعات]] -> 0

Sheet ريجينا
A1: فاتورة | B1: م | C1: التاريخ | D1: رقم الاذن | E1: توكيل | F1: عدد الحاويات | G1: النولون | H1: قيمة مضافة | I1: الايصالات | J1: اجمالي الفاتوره | K1: الدفعات | L1: اجمالي الحساب | M1: Column1 | N1: Column2
J2: =Table118192023103031323538394041481115182028[[#This Row],[النولون]]+Table118192023103031323538394041481115182028[[#This Row],[الايصالات]]+Table118192023103031323538394041481115182028[[#This Row],[قيمة مضافة]] -> 0 | L2: 0
A3: 1212 | B3: 1 | C3: 3/1/2026 | D3: 31804 | E3: ESL | F3: 10*20 | G3: =5*17500 -> 87500 | I3: =850+5*60+365.21*5+5*1130+7410+1500 -> 17536.05 | J3: =Table118192023103031323538394041481115182028[[#This Row],[النولون]]+Table118192023103031323538394041481115182028[[#This Row],[الايصالات]]+Table118192023103031323538394041481115182028[[#This Row],[قيمة مضافة]] -> 105036.05 | L3: =L2+Table118192023103031323538394041481115182028[[#This Row],[اجمالي الفاتوره]]-Table118192023103031323538394041481115182028[[#This Row],[الدفعات]] -> 105036.05
A4: 1213 | B4: 2 | C4: 3/1/2026 | D4: 263510355 | E4: ميرسك | F4: 5*40 | G4: =13000*5 -> 65000 | I4: =5*60+3*100+4*1130+1150+591.35+446.88+487.65+441.22+469.5+11736.3+2487+21291 -> 44220.9 | J4: =Table118192023103031323538394041481115182028[[#This Row],[النولون]]+Table118192023103031323538394041481115182028[[#This Row],[الايصالات]]+Table118192023103031323538394041481115182028[[#This Row],[قيمة مضافة]] -> 109220.9 | L4: =L3+Table118192023103031323538394041481115182028[[#This Row],[اجمالي الفاتوره]]-Table118192023103031323538394041481115182028[[#This Row],[الدفعات]] -> 214256.95
A5: 1214 | B5: 3 | C5: 3/1/2026 | D5: 263510215 | E5: ميرسك | F5: 2*40 | G5: =2*13000 -> 26000 | I5: =100+1130+1100+710.5+461.01+60*2+4393.56+997+8517 -> 17529.07 | J5: =Table118192023103031323538394041481115182028[[#This Row],[النولون]]+Table118192023103031323538394041481115182028[[#This Row],[الايصالات]]+Table118192023103031323538394041481115182028[[#This Row],[قيمة مضافة]] -> 43529.07 | L5: =L4+Table118192023103031323538394041481115182028[[#This Row],[اجمالي الفاتوره]]-Table118192023103031323538394041481115182028[[#This Row],[الدفعات]] -> 257786.02
A6: 1215 | B6: 4 | C6: 3/1/2026 | D6: 31766 | E6: ESL | F6: 2*40 | G6: =2*13000 -> 26000 | I6: =1130*2+452.53+461.01+60*2+2280+500 -> 6073.54 | J6: =Table118192023103031323538394041481115182028[[#This Row],[النولون]]+Table118192023103031323538394041481115182028[[#This Row],[الايصالات]]+Table118192023103031323538394041481115182028[[#This Row],[قيمة مضافة]] -> 32073.54 | L6: =L5+Table118192023103031323538394041481115182028[[#This Row],[اجمالي الفاتوره]]-Table118192023103031323538394041481115182028[[#This Row],[الدفعات]] -> 289859.56
C7: 4/3/2026 | D7: من مبلغ | E7: 400524.28 | I7: 0 | J7: =Table118192023103031323538394041481115182028[[#This Row],[النولون]]+Table118192023103031323538394041481115182028[[#This Row],[الايصالات]]+Table118192023103031323538394041481115182028[[#This Row],[قيمة مضافة]] -> 0 | K7: 75602.61 | L7: =L6+Table118192023103031323538394041481115182028[[#This Row],[اجمالي الفاتوره]]-Table118192023103031323538394041481115182028[[#This Row],[الدفعات]] -> 214256.95
A8: 1247 | B8: 5 | C8: 22/1/2026 | D8: 874062 | E8: CMA | F8: 1*20 ثق | G8: 13000 | I8: =850+100+60+75.47+527.54+550+25.1+150+171 -> 2509.11 | J8: =Table118192023103031323538394041481115182028[[#This Row],[النولون]]+Table118192023103031323538394041481115182028[[#This Row],[الايصالات]]+Table118192023103031323538394041481115182028[[#This Row],[قيمة مضافة]] -> 15509.11 | L8: =L7+Table118192023103031323538394041481115182028[[#This Row],[اجمالي الفاتوره]]-Table118192023103031323538394041481115182028[[#This Row],[الدفعات]] -> 229766.06
A9: 1248 | B9: 6 | C9: 22/1/2026 | D9: 6442485680 | E9: COSCO | F9: 1*40 | G9: 13000 | I9: =100+1130+710.5+60+2006.4+342 -> 4348.9 | J9: =Table118192023103031323538394041481115182028[[#This Row],[النولون]]+Table118192023103031323538394041481115182028[[#This Row],[الايصالات]]+Table118192023103031323538394041481115182028[[#This Row],[قيمة مضافة]] -> 17348.9 | L9: =L8+Table118192023103031323538394041481115182028[[#This Row],[اجمالي الفاتوره]]-Table118192023103031323538394041481115182028[[#This Row],[الدفعات]] -> 247114.96
A10: 1249 | B10: 7 | C10: 22/1/2026 | D10: 6442492950 | E10: COSCO | F10: 1*40 | G10: 13000 | I10: =60+1130+710.5+228+342 -> 2470.5 | J10: =Table118192023103031323538394041481115182028[[#This Row],[النولون]]+Table118192023103031323538394041481115182028[[#This Row],[الايصالات]]+Table118192023103031323538394041481115182028[[#This Row],[قيمة مضافة]] -> 15470.5 | L10: =L9+Table118192023103031323538394041481115182028[[#This Row],[اجمالي الفاتوره]]-Table118192023103031323538394041481115182028[[#This Row],[الدفعات]] -> 262585.46
A11: 1269 | B11: 8 | C11: 3/2/2026 | D11: 26109546 | E11: دي بي | F11: 10*20 | G11: =17500*5 -> 87500 | I11: =810*2+850*2+150+100*5+60*5+268.42+365.21*4+1130*4+1150+10000+456+500+10716+1824 -> 35165.26 | J11: =Table118192023103031323538394041481115182028[[#This Row],[النولون]]+Table118192023103031323538394041481115182028[[#This Row],[الايصالات]]+Table118192023103031323538394041481115182028[[#This Row],[قيمة مضافة]] -> 122665.26 | L11: =L10+Table118192023103031323538394041481115182028[[#This Row],[اجمالي الفاتوره]]-Table118192023103031323538394041481115182028[[#This Row],[الدفعات]] -> 385250.72
C12: 6/4/2026 | J12: =Table118192023103031323538394041481115182028[[#This Row],[النولون]]+Table118192023103031323538394041481115182028[[#This Row],[الايصالات]]+Table118192023103031323538394041481115182028[[#This Row],[قيمة مضافة]] -> 0 | K12: 350085.46 | L12: =L11+Table118192023103031323538394041481115182028[[#This Row],[اجمالي الفاتوره]]-Table118192023103031323538394041481115182028[[#This Row],[الدفعات]] -> 35165.26
A13: 1286 | B13: 9 | C13: 11/2/2026 | D13: 1964551 | E13: CMA | F13: 3*20 | G13: =17500+13000 -> 30500 | I13: =50+100*2+60*2+372.25+213.5+1130+580+2394+45+513+450 -> 6067.75 | J13: =Table118192023103031323538394041481115182028[[#This Row],[النولون]]+Table118192023103031323538394041481115182028[[#This Row],[الايصالات]]+Table118192023103031323538394041481115182028[[#This Row],[قيمة مضافة]] -> 36567.75 | L13: =L12+Table118192023103031323538394041481115182028[[#This Row],[اجمالي الفاتوره]]-Table118192023103031323538394041481115182028[[#This Row],[الدفعات]] -> 71733.01
A14: 1321 | B14: 10 | C14: 4/3/2026 | D14: 6445256130 | E14: COSCO | F14: 1*40 | G14: 13000 | I14: =850+100+60+1130+480.8+45.15+1072.97+25.1+342 -> 4106.02 | J14: =Table118192023103031323538394041481115182028[[#This Row],[النولون]]+Table118192023103031323538394041481115182028[[#This Row],[الايصالات]]+Table118192023103031323538394041481115182028[[#This Row],[قيمة مضافة]] -> 17106.02 | L14: =L13+Table118192023103031323538394041481115182028[[#This Row],[اجمالي الفاتوره]]-Table118192023103031323538394041481115182028[[#This Row],[الدفعات]] -> 88839.03 | M14: =SUM(J:J)-SUM(K:K)+L2 -> 712185.53 | N14: =SUM(H:H) -> 0
A15: 1322 | B15: 11 | C15: 4/3/2026 | D15: 35462 | E15: ميدكون | F15: 4*40 | G15: =13000*4 -> 52000 | I15: =810*2+850+50+60*4+1130+477.98+365.21*3+1130+1100+1100+263+787+5244+1000+2000*2 -> 20087.61 | J15: =Table118192023103031323538394041481115182028[[#This Row],[النولون]]+Table118192023103031323538394041481115182028[[#This Row],[الايصالات]]+Table118192023103031323538394041481115182028[[#This Row],[قيمة مضافة]] -> 72087.61 | L15: =L14+Table118192023103031323538394041481115182028[[#This Row],[اجمالي الفاتوره]]-Table118192023103031323538394041481115182028[[#This Row],[الدفعات]] -> 160926.64
A16: 1323 | B16: 12 | C16: 4/3/2026 | D16: 497 | E16: ايجيبت | F16: 10*20 | G16: =17500*5 -> 87500 | I16: =850+365.21*4+372.09+60*5+10000+500+10146+2850+1130*4+1150 -> 32148.93 | J16: =Table118192023103031323538394041481115182028[[#This Row],[النولون]]+Table118192023103031323538394041481115182028[[#This Row],[الايصالات]]+Table118192023103031323538394041481115182028[[#This Row],[قيمة مضافة]] -> 119648.93 | L16: =L15+Table118192023103031323538394041481115182028[[#This Row],[اجمالي الفاتوره]]-Table118192023103031323538394041481115182028[[#This Row],[الدفعات]] -> 280575.57
C17: 46147 | J17: =Table118192023103031323538394041481115182028[[#This Row],[النولون]]+Table118192023103031323538394041481115182028[[#This Row],[الايصالات]]+Table118192023103031323538394041481115182028[[#This Row],[قيمة مضافة]] -> 0 | K17: 280575.57 | L17: =L16+Table118192023103031323538394041481115182028[[#This Row],[اجمالي الفاتوره]]-Table118192023103031323538394041481115182028[[#This Row],[الدفعات]] -> 0
A18: 1346 | B18: 13 | C18: 30/3/2026 | D18: 896498 | E18: CMA | F18: 37*20 | G18: =18*19500+14500 -> 365500 | I18: =570+1100*2+1130*16+19*60+3*100+850*2+200+928+5550+6327+105.79*11+45.15*5+82.86+140.22+358.87+667.62*2+786.78+747.18+327.5+327.5+365.21*12+13*3500 -> 92373.11 | J18: =Table118192023103031323538394041481115182028[[#This Row],[النولون]]+Table118192023103031323538394041481115182028[[#This Row],[الايصالات]]+Table118192023103031323538394041481115182028[[#This Row],[قيمة مضافة]] -> 457873.11 | L18: =L17+Table118192023103031323538394041481115182028[[#This Row],[اجمالي الفاتوره]]-Table118192023103031323538394041481115182028[[#This Row],[الدفعات]] -> 457873.11
C19: 46184 | J19: =Table118192023103031323538394041481115182028[[#This Row],[النولون]]+Table118192023103031323538394041481115182028[[#This Row],[الايصالات]]+Table118192023103031323538394041481115182028[[#This Row],[قيمة مضافة]] -> 0 | K19: 365500 | L19: =L18+Table118192023103031323538394041481115182028[[#This Row],[اجمالي الفاتوره]]-Table118192023103031323538394041481115182028[[#This Row],[الدفعات]] -> 92373.11
A20: 1413 | B20: 14 | C20: 46138 | D20: 18908900 | E20: كادمار | F20: 1*40 | G20: 14500 | I20: =1130+466.67+68.08+60+850+1187.2+700+700 -> 5161.95 | J20: =Table118192023103031323538394041481115182028[[#This Row],[النولون]]+Table118192023103031323538394041481115182028[[#This Row],[الايصالات]]+Table118192023103031323538394041481115182028[[#This Row],[قيمة مضافة]] -> 19661.95 | L20: =L19+Table118192023103031323538394041481115182028[[#This Row],[اجمالي الفاتوره]]-Table118192023103031323538394041481115182028[[#This Row],[الدفعات]] -> 112035.06
A21: 1414 | B21: 15 | C21: 46138 | D21: 69571500 | E21: كادمار | F21: 1*40 | G21: 14500 | I21: =1130+909.09+68.08+60+850+1187.2+700*2 -> 5604.37 | J21: =Table118192023103031323538394041481115182028[[#This Row],[النولون]]+Table118192023103031323538394041481115182028[[#This Row],[الايصالات]]+Table118192023103031323538394041481115182028[[#This Row],[قيمة مضافة]] -> 20104.37 | L21: =L20+Table118192023103031323538394041481115182028[[#This Row],[اجمالي الفاتوره]]-Table118192023103031323538394041481115182028[[#This Row],[الدفعات]] -> 132139.43
A22: 1415 | B22: 16 | C22: 46138 | D22: 22579600 | E22: كادمار | F22: 1*40 | G22: 14500 | I22: =1100+458.19+68.08+60+1187.2+700*2+119.7 -> 4393.17 | J22: =Table118192023103031323538394041481115182028[[#This Row],[النولون]]+Table118192023103031323538394041481115182028[[#This Row],[الايصالات]]+Table118192023103031323538394041481115182028[[#This Row],[قيمة مضافة]] -> 18893.17 | L22: =L21+Table118192023103031323538394041481115182028[[#This Row],[اجمالي الفاتوره]]-Table118192023103031323538394041481115182028[[#This Row],[الدفعات]] -> 151032.6
A23: 1446 | B23: 17 | C23: 46151 | D23: 914230 | E23: CMA | F23: 6*20 | G23: =19500*3 -> 58500 | I23: =60*3+810+866.22+365.21+330.94+6881.04+752.4+1100*3+900+1026 -> 15411.81 | J23: =Table118192023103031323538394041481115182028[[#This Row],[النولون]]+Table118192023103031323538394041481115182028[[#This Row],[الايصالات]]+Table118192023103031323538394041481115182028[[#This Row],[قيمة مضافة]] -> 73911.81 | L23: =L22+Table118192023103031323538394041481115182028[[#This Row],[اجمالي الفاتوره]]-Table118192023103031323538394041481115182028[[#This Row],[الدفعات]] -> 224944.41
A24: 1466 | B24: 18 | C24: 46158 | D24: 9166178 | E24: CMA | F24: 7*20 | G24: =3*19500+14500 -> 73000 | I24: =251.21+365.21*3+4*60+200+15333+1130+600+1100*2+1197+1050+2500*3 -> 30796.84 | J24: =Table118192023103031323538394041481115182028[[#This Row],[النولون]]+Table118192023103031323538394041481115182028[[#This Row],[الايصالات]]+Table118192023103031323538394041481115182028[[#This Row],[قيمة مضافة]] -> 103796.84 | L24: =L23+Table118192023103031323538394041481115182028[[#This Row],[اجمالي الفاتوره]]-Table118192023103031323538394041481115182028[[#This Row],[الدفعات]] -> 328741.25
A25: 1494 | B25: 19 | C25: 46174 | D25: 76804 | E25: لات | F25: 1*40 | G25: 14500 | I25: =810+210+1100+105.79+441.22+60+478.8+228+114+150 -> 3697.81 | J25: =Table118192023103031323538394041481115182028[[#This Row],[النولون]]+Table118192023103031323538394041481115182028[[#This Row],[الايصالات]]+Table118192023103031323538394041481115182028[[#This Row],[قيمة مضافة]] -> 18197.81 | L25: =L24+Table118192023103031323538394041481115182028[[#This Row],[اجمالي الفاتوره]]-Table118192023103031323538394041481115182028[[#This Row],[الدفعات]] -> 346939.06
A26: 1495 | B26: 20 | C26: 46174 | D26: 76805 | E26: لات | F26: 1*40 | G26: 14500 | I26: =210+1100+442.45+60+2633.4+228+114+150+2500 -> 7437.85 | J26: =Table118192023103031323538394041481115182028[[#This Row],[النولون]]+Table118192023103031323538394041481115182028[[#This Row],[الايصالات]]+Table118192023103031323538394041481115182028[[#This Row],[قيمة مضافة]] -> 21937.85 | L26: =L25+Table118192023103031323538394041481115182028[[#This Row],[اجمالي الفاتوره]]-Table118192023103031323538394041481115182028[[#This Row],[الدفعات]] -> 368876.91
A27: 1531 | B27: 21 | C27: 46186 | D27: 6503773540 | E27: كوسكو | F27: 1*40 | G27: 14500 | I27: =210+1100+790.06+909.09+60+1909.5+342+150+3000 -> 8470.65 | J27: =Table118192023103031323538394041481115182028[[#This Row],[النولون]]+Table118192023103031323538394041481115182028[[#This Row],[الايصالات]]+Table118192023103031323538394041481115182028[[#This Row],[قيمة مضافة]] -> 22970.65 | L27: =L26+Table118192023103031323538394041481115182028[[#This Row],[اجمالي الفاتوره]]-Table118192023103031323538394041481115182028[[#This Row],[الدفعات]] -> 391847.56
A28: 1532 | B28: 22 | C28: 46186 | D28: 6503773550 | E28: كوسكو | F28: 1*40 | G28: 14500 | I28: =210+1100+909.09+60+1909.5+342+150 -> 4680.59 | J28: =Table118192023103031323538394041481115182028[[#This Row],[النولون]]+Table118192023103031323538394041481115182028[[#This Row],[الايصالات]]+Table118192023103031323538394041481115182028[[#This Row],[قيمة مضافة]] -> 19180.59 | L28: =L27+Table118192023103031323538394041481115182028[[#This Row],[اجمالي الفاتوره]]-Table118192023103031323538394041481115182028[[#This Row],[الدفعات]] -> 411028.15
A29: 1533 | B29: 23 | C29: 46186 | D29: 17222907 | E29: MSC | F29: 1*40 | G29: =14500+5000 -> 19500 | I29: =850+1100+210+60+204+1713.6+2000+2500+1000 -> 9637.6 | J29: =Table118192023103031323538394041481115182028[[#This Row],[النولون]]+Table118192023103031323538394041481115182028[[#This Row],[الايصالات]]+Table118192023103031323538394041481115182028[[#This Row],[قيمة مضافة]] -> 29137.6 | L29: =L28+Table118192023103031323538394041481115182028[[#This Row],[اجمالي الفاتوره]]-Table118192023103031323538394041481115182028[[#This Row],[الدفعات]] -> 440165.75
A30: 1534 | B30: 24 | C30: 46186 | D30: 6238300 | E30: ONE | F30: 1*40 | G30: 14500 | I30: =150+60+1130+750.23+1345+4615+855 -> 8905.23 | J30: =Table118192023103031323538394041481115182028[[#This Row],[النولون]]+Table118192023103031323538394041481115182028[[#This Row],[الايصالات]]+Table118192023103031323538394041481115182028[[#This Row],[قيمة مضافة]] -> 23405.23 | L30: =L29+Table118192023103031323538394041481115182028[[#This Row],[اجمالي الفاتوره]]-Table118192023103031323538394041481115182028[[#This Row],[الدفعات]] -> 463570.98
A31: 1535 | B31: 25 | C31: 46186 | D31: 925261 | E31: CMA | F31: 2*40 | G31: =14500*2 -> 29000 | I31: =1100+1100+464.45+463.84+60+5000+400+570+2500*2 -> 14158.29 | J31: =Table118192023103031323538394041481115182028[[#This Row],[النولون]]+Table118192023103031323538394041481115182028[[#This Row],[الايصالات]]+Table118192023103031323538394041481115182028[[#This Row],[قيمة مضافة]] -> 43158.29 | L31: =L30+Table118192023103031323538394041481115182028[[#This Row],[اجمالي الفاتوره]]-Table118192023103031323538394041481115182028[[#This Row],[الدفعات]] -> 506729.27
A32: 1538 | B32: 26 | C32: 46186 | D32: 77014 | E32: لات | F32: 2*40 | G32: =14500*2 -> 29000 | I32: =850+410+1100+1130+45.15+469.5+710.5+60*2+478.8+200+1500*2+456*2 -> 9425.95 | J32: =Table118192023103031323538394041481115182028[[#This Row],[النولون]]+Table118192023103031323538394041481115182028[[#This Row],[الايصالات]]+Table118192023103031323538394041481115182028[[#This Row],[قيمة مضافة]] -> 38425.95 | L32: =L31+Table118192023103031323538394041481115182028[[#This Row],[اجمالي الفاتوره]]-Table118192023103031323538394041481115182028[[#This Row],[الدفعات]] -> 545155.22
A33: 1537 | B33: 27 | C33: 46186 | D33: 77015 | E33: لات | F33: 3*40 | G33: =14500*3 -> 43500 | I33: =610+1100*2+1150+68.08+68.08+750.23+710.5+710.5+60*3+250+6583.5+1500*3+684*2 -> 19148.89 | J33: =Table118192023103031323538394041481115182028[[#This Row],[النولون]]+Table118192023103031323538394041481115182028[[#This Row],[الايصالات]]+Table118192023103031323538394041481115182028[[#This Row],[قيمة مضافة]] -> 62648.89 | L33: =L32+Table118192023103031323538394041481115182028[[#This Row],[اجمالي الفاتوره]]-Table118192023103031323538394041481115182028[[#This Row],[الدفعات]] -> 607804.11
A34: 1550 | B34: 28 | C34: 46194 | D34: 928762 | E34: CMA | F34: 6*20 | G34: =3*19500 -> 58500 | I34: =3*2500+850+2*60+365.21+413.41+385.86+1130+1100*2+7866+900+1026 -> 22756.48 | J34: =Table118192023103031323538394041481115182028[[#This Row],[النولون]]+Table118192023103031323538394041481115182028[[#This Row],[الايصالات]]+Table118192023103031323538394041481115182028[[#This Row],[قيمة مضافة]] -> 81256.48 | L34: =L33+Table118192023103031323538394041481115182028[[#This Row],[اجمالي الفاتوره]]-Table118192023103031323538394041481115182028[[#This Row],[الدفعات]] -> 689060.59
A35: 1551 | B35: 29 | C35: 46194 | D35: 925317 | E35: CMA | F35: 1*40 | G35: 14500 | I35: =2*2500+60+1150+789.94+1140+200+285 -> 8624.94 | J35: =Table118192023103031323538394041481115182028[[#This Row],[النولون]]+Table118192023103031323538394041481115182028[[#This Row],[الايصالات]]+Table118192023103031323538394041481115182028[[#This Row],[قيمة مضافة]] -> 23124.94 | L35: =L34+Table118192023103031323538394041481115182028[[#This Row],[اجمالي الفاتوره]]-Table118192023103031323538394041481115182028[[#This Row],[الدفعات]] -> 712185.53
J36: =Table118192023103031323538394041481115182028[[#This Row],[النولون]]+Table118192023103031323538394041481115182028[[#This Row],[الايصالات]]+Table118192023103031323538394041481115182028[[#This Row],[قيمة مضافة]] -> 0 | L36: =L35+Table118192023103031323538394041481115182028[[#This Row],[اجمالي الفاتوره]]-Table118192023103031323538394041481115182028[[#This Row],[الدفعات]] -> 712185.53
J37: =Table118192023103031323538394041481115182028[[#This Row],[النولون]]+Table118192023103031323538394041481115182028[[#This Row],[الايصالات]]+Table118192023103031323538394041481115182028[[#This Row],[قيمة مضافة]] -> 0 | L37: =L36+Table118192023103031323538394041481115182028[[#This Row],[اجمالي الفاتوره]]-Table118192023103031323538394041481115182028[[#This Row],[الدفعات]] -> 712185.53
J38: =Table118192023103031323538394041481115182028[[#This Row],[النولون]]+Table118192023103031323538394041481115182028[[#This Row],[الايصالات]]+Table118192023103031323538394041481115182028[[#This Row],[قيمة مضافة]] -> 0 | L38: =L37+Table118192023103031323538394041481115182028[[#This Row],[اجمالي الفاتوره]]-Table118192023103031323538394041481115182028[[#This Row],[الدفعات]] -> 712185.53
J39: =Table118192023103031323538394041481115182028[[#This Row],[النولون]]+Table118192023103031323538394041481115182028[[#This Row],[الايصالات]]+Table118192023103031323538394041481115182028[[#This Row],[قيمة مضافة]] -> 0 | L39: =L38+Table118192023103031323538394041481115182028[[#This Row],[اجمالي الفاتوره]]-Table118192023103031323538394041481115182028[[#This Row],[الدفعات]] -> 712185.53
J40: =Table118192023103031323538394041481115182028[[#This Row],[النولون]]+Table118192023103031323538394041481115182028[[#This Row],[الايصالات]]+Table118192023103031323538394041481115182028[[#This Row],[قيمة مضافة]] -> 0 | L40: =L39+Table118192023103031323538394041481115182028[[#This Row],[اجمالي الفاتوره]]-Table118192023103031323538394041481115182028[[#This Row],[الدفعات]] -> 712185.53
...

Sheet اسمنت مصر
A1: فاتورة | B1: م | C1: التاريخ | D1: اسم الشركه | E1: العنوان | F1: رقم الاذن | G1: عدد الحاويات | H1: النولون | I1: قيمة مضافة | J1: الايصالات | K1: اجمالي الفاتوره | L1: الدفعات | M1: اجمالي الحساب | N1: Column1 | O1: Column2
A2: 1262 | B2: 1 | C2: 31/1/2026 | D2: اسمنت | E2: بني سويف /ابوقير | F2: 1257 | G2: 4*20 | H2: =29500*2 -> 59000 | J2: =100*2+5*50+240+490*2+1100*2+97.5*2+475.5+425.5+8433.36 -> 13399.36 | K2: =Table1181920231030313235383940414811151820284359[[#This Row],[النولون]]+Table1181920231030313235383940414811151820284359[[#This Row],[الايصالات]]+Table1181920231030313235383940414811151820284359[[#This Row],[قيمة مضافة]] -> 72399.36 | M2: =Table1181920231030313235383940414811151820284359[[#This Row],[اجمالي الفاتوره]]-L2 -> 72399.36
C3: 16/3/2026 | K3: =Table1181920231030313235383940414811151820284359[[#This Row],[النولون]]+Table1181920231030313235383940414811151820284359[[#This Row],[الايصالات]]+Table1181920231030313235383940414811151820284359[[#This Row],[قيمة مضافة]] -> 0 | L3: 70629.36 | M3: =M2+Table1181920231030313235383940414811151820284359[[#This Row],[اجمالي الفاتوره]]-Table1181920231030313235383940414811151820284359[[#This Row],[الدفعات]] -> 1770
A4: 1342 | B4: 2 | C4: 30/3/2026 | D4: اسمنت | E4: بني سويف /ابوقير | F4: 3748 | G4: 2*20 | H4: 32500 | J4: =850+100*3+120+1150+443+197.5+2108.34 -> 5168.84 | K4: =Table1181920231030313235383940414811151820284359[[#This Row],[النولون]]+Table1181920231030313235383940414811151820284359[[#This Row],[الايصالات]]+Table1181920231030313235383940414811151820284359[[#This Row],[قيمة مضافة]] -> 37668.84 | M4: =M3+Table1181920231030313235383940414811151820284359[[#This Row],[اجمالي الفاتوره]]-Table1181920231030313235383940414811151820284359[[#This Row],[الدفعات]] -> 39438.84
A5: 1344 | B5: 3 | C5: 30/3/2026 | D5: اسمنت | E5: بني سويف | F5: 2807800 | G5: 12*20 | H5: =28000*6 -> 168000 | J5: =8*100+120+9*50+5*490+365.21*6+12684+8250+1200*6+9496.2 -> 43641.46 | K5: =Table1181920231030313235383940414811151820284359[[#This Row],[النولون]]+Table1181920231030313235383940414811151820284359[[#This Row],[الايصالات]]+Table1181920231030313235383940414811151820284359[[#This Row],[قيمة مضافة]] -> 211641.46 | M5: =M4+Table1181920231030313235383940414811151820284359[[#This Row],[اجمالي الفاتوره]]-Table1181920231030313235383940414811151820284359[[#This Row],[الدفعات]] -> 251080.3
A6: 1365 | B6: 4 | C6: 46119 | D6: اسمنت | E6: بني سويف | F6: 899831 | G6: 2*20 | H6: 28000 | J6: =100*2+850+365.21+105.79+490+1200+798+342+300+79.8 -> 4730.8 | K6: =Table1181920231030313235383940414811151820284359[[#This Row],[النولون]]+Table1181920231030313235383940414811151820284359[[#This Row],[الايصالات]]+Table1181920231030313235383940414811151820284359[[#This Row],[قيمة مضافة]] -> 32730.8 | M6: =M5+Table1181920231030313235383940414811151820284359[[#This Row],[اجمالي الفاتوره]]-Table1181920231030313235383940414811151820284359[[#This Row],[الدفعات]] -> 283811.1
C7: 46158 | K7: =Table1181920231030313235383940414811151820284359[[#This Row],[النولون]]+Table1181920231030313235383940414811151820284359[[#This Row],[الايصالات]]+Table1181920231030313235383940414811151820284359[[#This Row],[قيمة مضافة]] -> 0 | L7: 282040.7 | M7: =M6+Table1181920231030313235383940414811151820284359[[#This Row],[اجمالي الفاتوره]]-Table1181920231030313235383940414811151820284359[[#This Row],[الدفعات]] -> 1770.4
A8: 1439 | B8: 5 | C8: 46145 | D8: اسمنت | E8: بني سويف | F8: 172629 | G8: 4*20 | H8: =28000*2 -> 56000 | I8: =0.14*Table1181920231030313235383940414811151820284359[[#This Row],[النولون]] -> 7840 | J8: =100*3+1130+1150+1440.8+105.79+1150.1+490+2964*2 -> 11694.69 | K8: =Table1181920231030313235383940414811151820284359[[#This Row],[النولون]]+Table1181920231030313235383940414811151820284359[[#This Row],[الايصالات]]+Table1181920231030313235383940414811151820284359[[#This Row],[قيمة مضافة]] -> 75534.69 | M8: =M7+Table1181920231030313235383940414811151820284359[[#This Row],[اجمالي الفاتوره]]-Table1181920231030313235383940414811151820284359[[#This Row],[الدفعات]] -> 77305.09
C9: 46166 | K9: =Table1181920231030313235383940414811151820284359[[#This Row],[النولون]]+Table1181920231030313235383940414811151820284359[[#This Row],[الايصالات]]+Table1181920231030313235383940414811151820284359[[#This Row],[قيمة مضافة]] -> 0 | L9: =63840+11694.69 -> 75534.69 | M9: =M8+Table1181920231030313235383940414811151820284359[[#This Row],[اجمالي الفاتوره]]-Table1181920231030313235383940414811151820284359[[#This Row],[الدفعات]] -> 1770.4
K10: =Table1181920231030313235383940414811151820284359[[#This Row],[النولون]]+Table1181920231030313235383940414811151820284359[[#This Row],[الايصالات]]+Table1181920231030313235383940414811151820284359[[#This Row],[قيمة مضافة]] -> 0 | M10: =M9+Table1181920231030313235383940414811151820284359[[#This Row],[اجمالي الفاتوره]]-Table1181920231030313235383940414811151820284359[[#This Row],[الدفعات]] -> 1770.4
K11: =Table1181920231030313235383940414811151820284359[[#This Row],[النولون]]+Table1181920231030313235383940414811151820284359[[#This Row],[الايصالات]]+Table1181920231030313235383940414811151820284359[[#This Row],[قيمة مضافة]] -> 0 | M11: =M10+Table1181920231030313235383940414811151820284359[[#This Row],[اجمالي الفاتوره]]-Table1181920231030313235383940414811151820284359[[#This Row],[الدفعات]] -> 1770.4
K12: =Table1181920231030313235383940414811151820284359[[#This Row],[النولون]]+Table1181920231030313235383940414811151820284359[[#This Row],[الايصالات]]+Table1181920231030313235383940414811151820284359[[#This Row],[قيمة مضافة]] -> 0 | M12: =M11+Table1181920231030313235383940414811151820284359[[#This Row],[اجمالي الفاتوره]]-Table1181920231030313235383940414811151820284359[[#This Row],[الدفعات]] -> 1770.4
K13: =Table1181920231030313235383940414811151820284359[[#This Row],[النولون]]+Table1181920231030313235383940414811151820284359[[#This Row],[الايصالات]]+Table1181920231030313235383940414811151820284359[[#This Row],[قيمة مضافة]] -> 0 | M13: =M12+Table1181920231030313235383940414811151820284359[[#This Row],[اجمالي الفاتوره]]-Table1181920231030313235383940414811151820284359[[#This Row],[الدفعات]] -> 1770.4 | N13: =SUM(K:K)-SUM(L:L) -> 1770.4 | O13: =SUM(I:I) -> 7840
K14: =Table1181920231030313235383940414811151820284359[[#This Row],[النولون]]+Table1181920231030313235383940414811151820284359[[#This Row],[الايصالات]]+Table1181920231030313235383940414811151820284359[[#This Row],[قيمة مضافة]] -> 0 | M14: =M13+Table1181920231030313235383940414811151820284359[[#This Row],[اجمالي الفاتوره]]-Table1181920231030313235383940414811151820284359[[#This Row],[الدفعات]] -> 1770.4
K15: =Table1181920231030313235383940414811151820284359[[#This Row],[النولون]]+Table1181920231030313235383940414811151820284359[[#This Row],[الايصالات]]+Table1181920231030313235383940414811151820284359[[#This Row],[قيمة مضافة]] -> 0 | M15: =M14+Table1181920231030313235383940414811151820284359[[#This Row],[اجمالي الفاتوره]]-Table1181920231030313235383940414811151820284359[[#This Row],[الدفعات]] -> 1770.4
K16: =Table1181920231030313235383940414811151820284359[[#This Row],[النولون]]+Table1181920231030313235383940414811151820284359[[#This Row],[الايصالات]]+Table1181920231030313235383940414811151820284359[[#This Row],[قيمة مضافة]] -> 0 | M16: =M15+Table1181920231030313235383940414811151820284359[[#This Row],[اجمالي الفاتوره]]-Table1181920231030313235383940414811151820284359[[#This Row],[الدفعات]] -> 1770.4
K17: =Table1181920231030313235383940414811151820284359[[#This Row],[النولون]]+Table1181920231030313235383940414811151820284359[[#This Row],[الايصالات]]+Table1181920231030313235383940414811151820284359[[#This Row],[قيمة مضافة]] -> 0 | M17: =M16+Table1181920231030313235383940414811151820284359[[#This Row],[اجمالي الفاتوره]]-Table1181920231030313235383940414811151820284359[[#This Row],[الدفعات]] -> 1770.4
